Warning: no access to tty (Bad file descriptor).
Thus no job control in this shell.
Thu Nov 16 08:19:59 GMT 2023
/home1/datahome/mdemol/historical_analysis/launch/jlab.py:29: SyntaxWarning: "is not" with a literal. Did you mean "!="?
  elif dashinfo is not "0":
/home1/datahome/mdemol/historical_analysis/launch/jlab.py:32: SyntaxWarning: "is not" with a literal. Did you mean "!="?
  if dashinfo is not "0":
[I 2023-11-16 08:20:17.792 ServerApp] Package jupyterlab took 0.0000s to import
[I 2023-11-16 08:20:18.546 ServerApp] Package jupyter_lsp took 0.7528s to import
[W 2023-11-16 08:20:18.546 ServerApp] A `_jupyter_server_extension_points` function was not found in jupyter_lsp. Instead, a `_jupyter_server_extension_paths` function was found and will be used for now. This function name will be deprecated in future releases of Jupyter Server.
[I 2023-11-16 08:20:18.855 ServerApp] Package jupyter_server_terminals took 0.3090s to import
[I 2023-11-16 08:20:18.856 ServerApp] Package notebook took 0.0000s to import
[I 2023-11-16 08:20:18.858 ServerApp] Package notebook_shim took 0.0000s to import
[W 2023-11-16 08:20:18.858 ServerApp] A `_jupyter_server_extension_points` function was not found in notebook_shim. Instead, a `_jupyter_server_extension_paths` function was found and will be used for now. This function name will be deprecated in future releases of Jupyter Server.
[I 2023-11-16 08:20:32.557 ServerApp] Package panel.io.jupyter_server_extension took 13.6828s to import
[I 2023-11-16 08:20:32.558 ServerApp] jupyter_lsp | extension was successfully linked.
[I 2023-11-16 08:20:32.563 ServerApp] jupyter_server_terminals | extension was successfully linked.
[I 2023-11-16 08:20:32.569 ServerApp] jupyterlab | extension was successfully linked.
[W 2023-11-16 08:20:32.587 JupyterNotebookApp] 'password' has moved from NotebookApp to ServerApp. This config will be passed to ServerApp. Be sure to update your config before our next release.
[W 2023-11-16 08:20:32.590 ServerApp] ServerApp.password config is deprecated in 2.0. Use PasswordIdentityProvider.hashed_password.
[I 2023-11-16 08:20:32.590 ServerApp] notebook | extension was successfully linked.
[I 2023-11-16 08:20:39.074 ServerApp] notebook_shim | extension was successfully linked.
[I 2023-11-16 08:20:39.074 ServerApp] panel.io.jupyter_server_extension | extension was successfully linked.
[I 2023-11-16 08:20:39.559 ServerApp] notebook_shim | extension was successfully loaded.
[I 2023-11-16 08:20:39.561 ServerApp] jupyter_lsp | extension was successfully loaded.
[I 2023-11-16 08:20:39.563 ServerApp] jupyter_server_terminals | extension was successfully loaded.
[I 2023-11-16 08:20:39.686 LabApp] JupyterLab extension loaded from /home1/datahome/mdemol/.miniconda3/envs/histenv2/lib/python3.9/site-packages/jupyterlab
[I 2023-11-16 08:20:39.686 LabApp] JupyterLab application directory is /home1/datahome/mdemol/.miniconda3/envs/histenv2/share/jupyter/lab
[I 2023-11-16 08:20:39.698 LabApp] Extension Manager is 'pypi'.
[I 2023-11-16 08:20:39.702 ServerApp] jupyterlab | extension was successfully loaded.
[I 2023-11-16 08:20:39.705 ServerApp] notebook | extension was successfully loaded.
[I 2023-11-16 08:20:39.706 ServerApp] panel.io.jupyter_server_extension | extension was successfully loaded.
[I 2023-11-16 08:20:39.706 ServerApp] Serving notebooks from local directory: /home1/datahome/mdemol
[I 2023-11-16 08:20:39.706 ServerApp] Jupyter Server 2.9.1 is running at:
[I 2023-11-16 08:20:39.707 ServerApp] http://r1i1n33:8877/lab
[I 2023-11-16 08:20:39.707 ServerApp]     http://127.0.0.1:8877/lab
[I 2023-11-16 08:20:39.707 ServerApp] Use Control-C to stop this server and shut down all kernels (twice to skip confirmation).
[I 2023-11-16 08:20:39.845 ServerApp] Skipped non-installed server(s): bash-language-server, dockerfile-language-server-nodejs, javascript-typescript-langserver, jedi-language-server, julia-language-server, pyright, python-language-server, python-lsp-server, r-languageserver, sql-language-server, texlab, typescript-language-server, unified-language-server, vscode-css-languageserver-bin, vscode-html-languageserver-bin, vscode-json-languageserver-bin, yaml-language-server
[W 2023-11-16 08:21:10.782 ServerApp] 404 GET /api/kernels/486520bc-e5f9-480c-b968-be84b0014b72?1700122870704 (10.148.1.145): Kernel does not exist: 486520bc-e5f9-480c-b968-be84b0014b72
[W 2023-11-16 08:21:10.782 ServerApp] wrote error: 'Kernel does not exist: 486520bc-e5f9-480c-b968-be84b0014b72'
    Traceback (most recent call last):
      File "/home1/datahome/mdemol/.miniconda3/envs/histenv2/lib/python3.9/site-packages/tornado/web.py", line 1786, in _execute
        result = await result
      File "/home1/datahome/mdemol/.miniconda3/envs/histenv2/lib/python3.9/site-packages/jupyter_server/services/kernels/handlers.py", line 75, in get
        model = await ensure_async(km.kernel_model(kernel_id))
      File "/home1/datahome/mdemol/.miniconda3/envs/histenv2/lib/python3.9/site-packages/jupyter_server/services/kernels/kernelmanager.py", line 500, in kernel_model
        self._check_kernel_id(kernel_id)
      File "/home1/datahome/mdemol/.miniconda3/envs/histenv2/lib/python3.9/site-packages/jupyter_server/services/kernels/kernelmanager.py", line 531, in _check_kernel_id
        raise web.HTTPError(404, "Kernel does not exist: %s" % kernel_id)
    tornado.web.HTTPError: HTTP 404: Not Found (Kernel does not exist: 486520bc-e5f9-480c-b968-be84b0014b72)
[W 2023-11-16 08:21:10.826 ServerApp] 404 GET /api/kernels/486520bc-e5f9-480c-b968-be84b0014b72?1700122870704 (fab7e86e3096494a86aeccede238bd42@10.148.1.145) 44.93ms referer=http://localhost:8877/lab/tree/historical_analysis/job_distributed.py
[W 2023-11-16 08:21:11.847 ServerApp] 404 GET /api/kernels/486520bc-e5f9-480c-b968-be84b0014b72/channels?session_id=a865eac5-b8fe-42c2-bef5-3bad6d3f99f5 (10.148.1.145): Kernel does not exist: 486520bc-e5f9-480c-b968-be84b0014b72
[W 2023-11-16 08:21:11.974 ServerApp] 404 GET /api/kernels/486520bc-e5f9-480c-b968-be84b0014b72/channels?session_id=a865eac5-b8fe-42c2-bef5-3bad6d3f99f5 (fab7e86e3096494a86aeccede238bd42@10.148.1.145) 127.06ms referer=None
[W 2023-11-16 08:21:12.163 ServerApp] 404 GET /api/kernels/fe5f49cb-2b45-425f-92dc-5d3ce83d3c3e?1700122872129 (10.148.1.145): Kernel does not exist: fe5f49cb-2b45-425f-92dc-5d3ce83d3c3e
[W 2023-11-16 08:21:12.164 ServerApp] wrote error: 'Kernel does not exist: fe5f49cb-2b45-425f-92dc-5d3ce83d3c3e'
    Traceback (most recent call last):
      File "/home1/datahome/mdemol/.miniconda3/envs/histenv2/lib/python3.9/site-packages/tornado/web.py", line 1786, in _execute
        result = await result
      File "/home1/datahome/mdemol/.miniconda3/envs/histenv2/lib/python3.9/site-packages/jupyter_server/services/kernels/handlers.py", line 75, in get
        model = await ensure_async(km.kernel_model(kernel_id))
      File "/home1/datahome/mdemol/.miniconda3/envs/histenv2/lib/python3.9/site-packages/jupyter_server/services/kernels/kernelmanager.py", line 500, in kernel_model
        self._check_kernel_id(kernel_id)
      File "/home1/datahome/mdemol/.miniconda3/envs/histenv2/lib/python3.9/site-packages/jupyter_server/services/kernels/kernelmanager.py", line 531, in _check_kernel_id
        raise web.HTTPError(404, "Kernel does not exist: %s" % kernel_id)
    tornado.web.HTTPError: HTTP 404: Not Found (Kernel does not exist: fe5f49cb-2b45-425f-92dc-5d3ce83d3c3e)
[W 2023-11-16 08:21:12.164 ServerApp] 404 GET /api/kernels/fe5f49cb-2b45-425f-92dc-5d3ce83d3c3e?1700122872129 (fab7e86e3096494a86aeccede238bd42@10.148.1.145) 1.06ms referer=http://localhost:8877/lab/tree/historical_analysis/job_distributed.py
[W 2023-11-16 08:21:12.257 ServerApp] 404 GET /api/kernels/486520bc-e5f9-480c-b968-be84b0014b72?1700122872132 (10.148.1.145): Kernel does not exist: 486520bc-e5f9-480c-b968-be84b0014b72
[W 2023-11-16 08:21:12.258 ServerApp] wrote error: 'Kernel does not exist: 486520bc-e5f9-480c-b968-be84b0014b72'
    Traceback (most recent call last):
      File "/home1/datahome/mdemol/.miniconda3/envs/histenv2/lib/python3.9/site-packages/tornado/web.py", line 1786, in _execute
        result = await result
      File "/home1/datahome/mdemol/.miniconda3/envs/histenv2/lib/python3.9/site-packages/jupyter_server/services/kernels/handlers.py", line 75, in get
        model = await ensure_async(km.kernel_model(kernel_id))
      File "/home1/datahome/mdemol/.miniconda3/envs/histenv2/lib/python3.9/site-packages/jupyter_server/services/kernels/kernelmanager.py", line 500, in kernel_model
        self._check_kernel_id(kernel_id)
      File "/home1/datahome/mdemol/.miniconda3/envs/histenv2/lib/python3.9/site-packages/jupyter_server/services/kernels/kernelmanager.py", line 531, in _check_kernel_id
        raise web.HTTPError(404, "Kernel does not exist: %s" % kernel_id)
    tornado.web.HTTPError: HTTP 404: Not Found (Kernel does not exist: 486520bc-e5f9-480c-b968-be84b0014b72)
[W 2023-11-16 08:21:12.258 ServerApp] 404 GET /api/kernels/486520bc-e5f9-480c-b968-be84b0014b72?1700122872132 (fab7e86e3096494a86aeccede238bd42@10.148.1.145) 0.86ms referer=http://localhost:8877/lab/tree/historical_analysis/job_distributed.py
[W 2023-11-16 08:21:12.918 ServerApp] 404 GET /api/kernels/fe5f49cb-2b45-425f-92dc-5d3ce83d3c3e/channels?session_id=efa5ff91-4120-43da-8249-f63045309a82 (10.148.1.145): Kernel does not exist: fe5f49cb-2b45-425f-92dc-5d3ce83d3c3e
[W 2023-11-16 08:21:12.918 ServerApp] 404 GET /api/kernels/fe5f49cb-2b45-425f-92dc-5d3ce83d3c3e/channels?session_id=efa5ff91-4120-43da-8249-f63045309a82 (fab7e86e3096494a86aeccede238bd42@10.148.1.145) 0.95ms referer=None
[W 2023-11-16 08:21:13.067 ServerApp] 404 GET /api/kernels/fe5f49cb-2b45-425f-92dc-5d3ce83d3c3e?1700122873032 (10.148.1.145): Kernel does not exist: fe5f49cb-2b45-425f-92dc-5d3ce83d3c3e
[W 2023-11-16 08:21:13.068 ServerApp] wrote error: 'Kernel does not exist: fe5f49cb-2b45-425f-92dc-5d3ce83d3c3e'
    Traceback (most recent call last):
      File "/home1/datahome/mdemol/.miniconda3/envs/histenv2/lib/python3.9/site-packages/tornado/web.py", line 1786, in _execute
        result = await result
      File "/home1/datahome/mdemol/.miniconda3/envs/histenv2/lib/python3.9/site-packages/jupyter_server/services/kernels/handlers.py", line 75, in get
        model = await ensure_async(km.kernel_model(kernel_id))
      File "/home1/datahome/mdemol/.miniconda3/envs/histenv2/lib/python3.9/site-packages/jupyter_server/services/kernels/kernelmanager.py", line 500, in kernel_model
        self._check_kernel_id(kernel_id)
      File "/home1/datahome/mdemol/.miniconda3/envs/histenv2/lib/python3.9/site-packages/jupyter_server/services/kernels/kernelmanager.py", line 531, in _check_kernel_id
        raise web.HTTPError(404, "Kernel does not exist: %s" % kernel_id)
    tornado.web.HTTPError: HTTP 404: Not Found (Kernel does not exist: fe5f49cb-2b45-425f-92dc-5d3ce83d3c3e)
[W 2023-11-16 08:21:13.068 ServerApp] 404 GET /api/kernels/fe5f49cb-2b45-425f-92dc-5d3ce83d3c3e?1700122873032 (fab7e86e3096494a86aeccede238bd42@10.148.1.145) 0.87ms referer=http://localhost:8877/lab/tree/historical_analysis/job_distributed.py
[W 2023-11-16 08:21:13.443 ServerApp] 404 GET /api/kernels/fe5f49cb-2b45-425f-92dc-5d3ce83d3c3e/channels?session_id=efa5ff91-4120-43da-8249-f63045309a82 (10.148.1.145): Kernel does not exist: fe5f49cb-2b45-425f-92dc-5d3ce83d3c3e
[W 2023-11-16 08:21:13.444 ServerApp] 404 GET /api/kernels/fe5f49cb-2b45-425f-92dc-5d3ce83d3c3e/channels?session_id=efa5ff91-4120-43da-8249-f63045309a82 (fab7e86e3096494a86aeccede238bd42@10.148.1.145) 0.95ms referer=None
[W 2023-11-16 08:21:13.597 ServerApp] 404 GET /api/kernels/fe5f49cb-2b45-425f-92dc-5d3ce83d3c3e?1700122873563 (10.148.1.145): Kernel does not exist: fe5f49cb-2b45-425f-92dc-5d3ce83d3c3e
[W 2023-11-16 08:21:13.597 ServerApp] wrote error: 'Kernel does not exist: fe5f49cb-2b45-425f-92dc-5d3ce83d3c3e'
    Traceback (most recent call last):
      File "/home1/datahome/mdemol/.miniconda3/envs/histenv2/lib/python3.9/site-packages/tornado/web.py", line 1786, in _execute
        result = await result
      File "/home1/datahome/mdemol/.miniconda3/envs/histenv2/lib/python3.9/site-packages/jupyter_server/services/kernels/handlers.py", line 75, in get
        model = await ensure_async(km.kernel_model(kernel_id))
      File "/home1/datahome/mdemol/.miniconda3/envs/histenv2/lib/python3.9/site-packages/jupyter_server/services/kernels/kernelmanager.py", line 500, in kernel_model
        self._check_kernel_id(kernel_id)
      File "/home1/datahome/mdemol/.miniconda3/envs/histenv2/lib/python3.9/site-packages/jupyter_server/services/kernels/kernelmanager.py", line 531, in _check_kernel_id
        raise web.HTTPError(404, "Kernel does not exist: %s" % kernel_id)
    tornado.web.HTTPError: HTTP 404: Not Found (Kernel does not exist: fe5f49cb-2b45-425f-92dc-5d3ce83d3c3e)
[W 2023-11-16 08:21:13.598 ServerApp] 404 GET /api/kernels/fe5f49cb-2b45-425f-92dc-5d3ce83d3c3e?1700122873563 (fab7e86e3096494a86aeccede238bd42@10.148.1.145) 0.86ms referer=http://localhost:8877/lab/tree/historical_analysis/job_distributed.py
[W 2023-11-16 08:21:14.297 ServerApp] 404 GET /api/kernels/fe5f49cb-2b45-425f-92dc-5d3ce83d3c3e/channels?session_id=efa5ff91-4120-43da-8249-f63045309a82 (10.148.1.145): Kernel does not exist: fe5f49cb-2b45-425f-92dc-5d3ce83d3c3e
[W 2023-11-16 08:21:14.298 ServerApp] 404 GET /api/kernels/fe5f49cb-2b45-425f-92dc-5d3ce83d3c3e/channels?session_id=efa5ff91-4120-43da-8249-f63045309a82 (fab7e86e3096494a86aeccede238bd42@10.148.1.145) 0.94ms referer=None
[W 2023-11-16 08:21:14.478 ServerApp] 404 GET /api/kernels/fe5f49cb-2b45-425f-92dc-5d3ce83d3c3e?1700122874438 (10.148.1.145): Kernel does not exist: fe5f49cb-2b45-425f-92dc-5d3ce83d3c3e
[W 2023-11-16 08:21:14.478 ServerApp] wrote error: 'Kernel does not exist: fe5f49cb-2b45-425f-92dc-5d3ce83d3c3e'
    Traceback (most recent call last):
      File "/home1/datahome/mdemol/.miniconda3/envs/histenv2/lib/python3.9/site-packages/tornado/web.py", line 1786, in _execute
        result = await result
      File "/home1/datahome/mdemol/.miniconda3/envs/histenv2/lib/python3.9/site-packages/jupyter_server/services/kernels/handlers.py", line 75, in get
        model = await ensure_async(km.kernel_model(kernel_id))
      File "/home1/datahome/mdemol/.miniconda3/envs/histenv2/lib/python3.9/site-packages/jupyter_server/services/kernels/kernelmanager.py", line 500, in kernel_model
        self._check_kernel_id(kernel_id)
      File "/home1/datahome/mdemol/.miniconda3/envs/histenv2/lib/python3.9/site-packages/jupyter_server/services/kernels/kernelmanager.py", line 531, in _check_kernel_id
        raise web.HTTPError(404, "Kernel does not exist: %s" % kernel_id)
    tornado.web.HTTPError: HTTP 404: Not Found (Kernel does not exist: fe5f49cb-2b45-425f-92dc-5d3ce83d3c3e)
[W 2023-11-16 08:21:14.478 ServerApp] 404 GET /api/kernels/fe5f49cb-2b45-425f-92dc-5d3ce83d3c3e?1700122874438 (fab7e86e3096494a86aeccede238bd42@10.148.1.145) 0.85ms referer=http://localhost:8877/lab/tree/historical_analysis/job_distributed.py
[W 2023-11-16 08:21:15.018 ServerApp] 404 GET /api/kernels/486520bc-e5f9-480c-b968-be84b0014b72/channels?session_id=a865eac5-b8fe-42c2-bef5-3bad6d3f99f5 (10.148.1.145): Kernel does not exist: 486520bc-e5f9-480c-b968-be84b0014b72
[W 2023-11-16 08:21:15.018 ServerApp] 404 GET /api/kernels/486520bc-e5f9-480c-b968-be84b0014b72/channels?session_id=a865eac5-b8fe-42c2-bef5-3bad6d3f99f5 (fab7e86e3096494a86aeccede238bd42@10.148.1.145) 0.94ms referer=None
[W 2023-11-16 08:21:15.201 ServerApp] 404 GET /api/kernels/486520bc-e5f9-480c-b968-be84b0014b72?1700122875166 (10.148.1.145): Kernel does not exist: 486520bc-e5f9-480c-b968-be84b0014b72
[W 2023-11-16 08:21:15.201 ServerApp] wrote error: 'Kernel does not exist: 486520bc-e5f9-480c-b968-be84b0014b72'
    Traceback (most recent call last):
      File "/home1/datahome/mdemol/.miniconda3/envs/histenv2/lib/python3.9/site-packages/tornado/web.py", line 1786, in _execute
        result = await result
      File "/home1/datahome/mdemol/.miniconda3/envs/histenv2/lib/python3.9/site-packages/jupyter_server/services/kernels/handlers.py", line 75, in get
        model = await ensure_async(km.kernel_model(kernel_id))
      File "/home1/datahome/mdemol/.miniconda3/envs/histenv2/lib/python3.9/site-packages/jupyter_server/services/kernels/kernelmanager.py", line 500, in kernel_model
        self._check_kernel_id(kernel_id)
      File "/home1/datahome/mdemol/.miniconda3/envs/histenv2/lib/python3.9/site-packages/jupyter_server/services/kernels/kernelmanager.py", line 531, in _check_kernel_id
        raise web.HTTPError(404, "Kernel does not exist: %s" % kernel_id)
    tornado.web.HTTPError: HTTP 404: Not Found (Kernel does not exist: 486520bc-e5f9-480c-b968-be84b0014b72)
[W 2023-11-16 08:21:15.202 ServerApp] 404 GET /api/kernels/486520bc-e5f9-480c-b968-be84b0014b72?1700122875166 (fab7e86e3096494a86aeccede238bd42@10.148.1.145) 0.86ms referer=http://localhost:8877/lab/tree/historical_analysis/job_distributed.py
[W 2023-11-16 08:21:18.302 ServerApp] 404 GET /api/kernels/fe5f49cb-2b45-425f-92dc-5d3ce83d3c3e/channels?session_id=efa5ff91-4120-43da-8249-f63045309a82 (10.148.1.145): Kernel does not exist: fe5f49cb-2b45-425f-92dc-5d3ce83d3c3e
[W 2023-11-16 08:21:18.303 ServerApp] 404 GET /api/kernels/fe5f49cb-2b45-425f-92dc-5d3ce83d3c3e/channels?session_id=efa5ff91-4120-43da-8249-f63045309a82 (fab7e86e3096494a86aeccede238bd42@10.148.1.145) 1.37ms referer=None
[W 2023-11-16 08:21:18.507 ServerApp] 404 GET /api/kernels/fe5f49cb-2b45-425f-92dc-5d3ce83d3c3e?1700122878471 (10.148.1.145): Kernel does not exist: fe5f49cb-2b45-425f-92dc-5d3ce83d3c3e
[W 2023-11-16 08:21:18.508 ServerApp] wrote error: 'Kernel does not exist: fe5f49cb-2b45-425f-92dc-5d3ce83d3c3e'
    Traceback (most recent call last):
      File "/home1/datahome/mdemol/.miniconda3/envs/histenv2/lib/python3.9/site-packages/tornado/web.py", line 1786, in _execute
        result = await result
      File "/home1/datahome/mdemol/.miniconda3/envs/histenv2/lib/python3.9/site-packages/jupyter_server/services/kernels/handlers.py", line 75, in get
        model = await ensure_async(km.kernel_model(kernel_id))
      File "/home1/datahome/mdemol/.miniconda3/envs/histenv2/lib/python3.9/site-packages/jupyter_server/services/kernels/kernelmanager.py", line 500, in kernel_model
        self._check_kernel_id(kernel_id)
      File "/home1/datahome/mdemol/.miniconda3/envs/histenv2/lib/python3.9/site-packages/jupyter_server/services/kernels/kernelmanager.py", line 531, in _check_kernel_id
        raise web.HTTPError(404, "Kernel does not exist: %s" % kernel_id)
    tornado.web.HTTPError: HTTP 404: Not Found (Kernel does not exist: fe5f49cb-2b45-425f-92dc-5d3ce83d3c3e)
[W 2023-11-16 08:21:18.508 ServerApp] 404 GET /api/kernels/fe5f49cb-2b45-425f-92dc-5d3ce83d3c3e?1700122878471 (fab7e86e3096494a86aeccede238bd42@10.148.1.145) 0.99ms referer=http://localhost:8877/lab/tree/historical_analysis/job_distributed.py
[W 2023-11-16 08:21:19.578 ServerApp] 404 GET /api/kernels/486520bc-e5f9-480c-b968-be84b0014b72/channels?session_id=a865eac5-b8fe-42c2-bef5-3bad6d3f99f5 (10.148.1.145): Kernel does not exist: 486520bc-e5f9-480c-b968-be84b0014b72
[W 2023-11-16 08:21:19.578 ServerApp] 404 GET /api/kernels/486520bc-e5f9-480c-b968-be84b0014b72/channels?session_id=a865eac5-b8fe-42c2-bef5-3bad6d3f99f5 (fab7e86e3096494a86aeccede238bd42@10.148.1.145) 1.00ms referer=None
[W 2023-11-16 08:21:19.767 ServerApp] 404 GET /api/kernels/486520bc-e5f9-480c-b968-be84b0014b72?1700122879730 (10.148.1.145): Kernel does not exist: 486520bc-e5f9-480c-b968-be84b0014b72
[W 2023-11-16 08:21:19.767 ServerApp] wrote error: 'Kernel does not exist: 486520bc-e5f9-480c-b968-be84b0014b72'
    Traceback (most recent call last):
      File "/home1/datahome/mdemol/.miniconda3/envs/histenv2/lib/python3.9/site-packages/tornado/web.py", line 1786, in _execute
        result = await result
      File "/home1/datahome/mdemol/.miniconda3/envs/histenv2/lib/python3.9/site-packages/jupyter_server/services/kernels/handlers.py", line 75, in get
        model = await ensure_async(km.kernel_model(kernel_id))
      File "/home1/datahome/mdemol/.miniconda3/envs/histenv2/lib/python3.9/site-packages/jupyter_server/services/kernels/kernelmanager.py", line 500, in kernel_model
        self._check_kernel_id(kernel_id)
      File "/home1/datahome/mdemol/.miniconda3/envs/histenv2/lib/python3.9/site-packages/jupyter_server/services/kernels/kernelmanager.py", line 531, in _check_kernel_id
        raise web.HTTPError(404, "Kernel does not exist: %s" % kernel_id)
    tornado.web.HTTPError: HTTP 404: Not Found (Kernel does not exist: 486520bc-e5f9-480c-b968-be84b0014b72)
[W 2023-11-16 08:21:19.768 ServerApp] 404 GET /api/kernels/486520bc-e5f9-480c-b968-be84b0014b72?1700122879730 (fab7e86e3096494a86aeccede238bd42@10.148.1.145) 0.87ms referer=http://localhost:8877/lab/tree/historical_analysis/job_distributed.py
[W 2023-11-16 08:21:25.251 ServerApp] 404 GET /api/kernels/486520bc-e5f9-480c-b968-be84b0014b72/channels?session_id=a865eac5-b8fe-42c2-bef5-3bad6d3f99f5 (10.148.1.145): Kernel does not exist: 486520bc-e5f9-480c-b968-be84b0014b72
[W 2023-11-16 08:21:25.252 ServerApp] 404 GET /api/kernels/486520bc-e5f9-480c-b968-be84b0014b72/channels?session_id=a865eac5-b8fe-42c2-bef5-3bad6d3f99f5 (fab7e86e3096494a86aeccede238bd42@10.148.1.145) 0.96ms referer=None
[W 2023-11-16 08:21:25.449 ServerApp] 404 GET /api/kernels/486520bc-e5f9-480c-b968-be84b0014b72?1700122885412 (10.148.1.145): Kernel does not exist: 486520bc-e5f9-480c-b968-be84b0014b72
[W 2023-11-16 08:21:25.449 ServerApp] wrote error: 'Kernel does not exist: 486520bc-e5f9-480c-b968-be84b0014b72'
    Traceback (most recent call last):
      File "/home1/datahome/mdemol/.miniconda3/envs/histenv2/lib/python3.9/site-packages/tornado/web.py", line 1786, in _execute
        result = await result
      File "/home1/datahome/mdemol/.miniconda3/envs/histenv2/lib/python3.9/site-packages/jupyter_server/services/kernels/handlers.py", line 75, in get
        model = await ensure_async(km.kernel_model(kernel_id))
      File "/home1/datahome/mdemol/.miniconda3/envs/histenv2/lib/python3.9/site-packages/jupyter_server/services/kernels/kernelmanager.py", line 500, in kernel_model
        self._check_kernel_id(kernel_id)
      File "/home1/datahome/mdemol/.miniconda3/envs/histenv2/lib/python3.9/site-packages/jupyter_server/services/kernels/kernelmanager.py", line 531, in _check_kernel_id
        raise web.HTTPError(404, "Kernel does not exist: %s" % kernel_id)
    tornado.web.HTTPError: HTTP 404: Not Found (Kernel does not exist: 486520bc-e5f9-480c-b968-be84b0014b72)
[W 2023-11-16 08:21:25.450 ServerApp] 404 GET /api/kernels/486520bc-e5f9-480c-b968-be84b0014b72?1700122885412 (fab7e86e3096494a86aeccede238bd42@10.148.1.145) 0.86ms referer=http://localhost:8877/lab/tree/historical_analysis/job_distributed.py
[W 2023-11-16 08:21:35.269 ServerApp] 404 GET /api/kernels/fe5f49cb-2b45-425f-92dc-5d3ce83d3c3e/channels?session_id=efa5ff91-4120-43da-8249-f63045309a82 (10.148.1.145): Kernel does not exist: fe5f49cb-2b45-425f-92dc-5d3ce83d3c3e
[W 2023-11-16 08:21:35.270 ServerApp] 404 GET /api/kernels/fe5f49cb-2b45-425f-92dc-5d3ce83d3c3e/channels?session_id=efa5ff91-4120-43da-8249-f63045309a82 (fab7e86e3096494a86aeccede238bd42@10.148.1.145) 1.49ms referer=None
[W 2023-11-16 08:21:35.381 ServerApp] 404 GET /api/kernels/fe5f49cb-2b45-425f-92dc-5d3ce83d3c3e?1700122895348 (10.148.1.145): Kernel does not exist: fe5f49cb-2b45-425f-92dc-5d3ce83d3c3e
[W 2023-11-16 08:21:35.382 ServerApp] wrote error: 'Kernel does not exist: fe5f49cb-2b45-425f-92dc-5d3ce83d3c3e'
    Traceback (most recent call last):
      File "/home1/datahome/mdemol/.miniconda3/envs/histenv2/lib/python3.9/site-packages/tornado/web.py", line 1786, in _execute
        result = await result
      File "/home1/datahome/mdemol/.miniconda3/envs/histenv2/lib/python3.9/site-packages/jupyter_server/services/kernels/handlers.py", line 75, in get
        model = await ensure_async(km.kernel_model(kernel_id))
      File "/home1/datahome/mdemol/.miniconda3/envs/histenv2/lib/python3.9/site-packages/jupyter_server/services/kernels/kernelmanager.py", line 500, in kernel_model
        self._check_kernel_id(kernel_id)
      File "/home1/datahome/mdemol/.miniconda3/envs/histenv2/lib/python3.9/site-packages/jupyter_server/services/kernels/kernelmanager.py", line 531, in _check_kernel_id
        raise web.HTTPError(404, "Kernel does not exist: %s" % kernel_id)
    tornado.web.HTTPError: HTTP 404: Not Found (Kernel does not exist: fe5f49cb-2b45-425f-92dc-5d3ce83d3c3e)
[W 2023-11-16 08:21:35.382 ServerApp] 404 GET /api/kernels/fe5f49cb-2b45-425f-92dc-5d3ce83d3c3e?1700122895348 (fab7e86e3096494a86aeccede238bd42@10.148.1.145) 0.88ms referer=http://localhost:8877/lab/tree/historical_analysis/job_distributed.py
[E 2023-11-16 08:22:07.789 ServerApp] Uncaught exception GET /lab/api/settings?1700122923856 (10.148.1.145)
    HTTPServerRequest(protocol='http', host='localhost:8877', method='GET', uri='/lab/api/settings?1700122923856', version='HTTP/1.1', remote_ip='10.148.1.145')
    Traceback (most recent call last):
      File "/home1/datahome/mdemol/.miniconda3/envs/histenv2/lib/python3.9/site-packages/tornado/web.py", line 1786, in _execute
        result = await result
    tornado.iostream.StreamClosedError: Stream is closed
[W 2023-11-16 08:22:10.072 LabApp] Could not determine jupyterlab build status without nodejs
[I 2023-11-16 08:24:32.295 ServerApp] Saving file at /historical_analysis/job_distributed.py
[W 2023-11-16 08:24:46.234 ServerApp] delete /historical_analysis/job_distributed.py.o7424982
[I 2023-11-16 08:40:12.817 ServerApp] Saving file at /historical_analysis/job_distributed.py
[I 2023-11-16 08:43:02.127 ServerApp] Kernel started: bc183fb1-6411-48bf-9091-a5a5991392a5
readline: /etc/inputrc: line 19: term: unknown variable name
[I 2023-11-16 08:43:03.346 ServerApp] Connecting to kernel bc183fb1-6411-48bf-9091-a5a5991392a5.
[I 2023-11-16 08:43:03.348 ServerApp] Connecting to kernel bc183fb1-6411-48bf-9091-a5a5991392a5.
[I 2023-11-16 08:43:03.350 ServerApp] Connecting to kernel bc183fb1-6411-48bf-9091-a5a5991392a5.
[I 2023-11-16 08:45:02.429 ServerApp] Saving file at /historical_analysis/21_zarr_aviso.ipynb
[I 2023-11-16 08:47:07.293 ServerApp] Saving file at /historical_analysis/21_zarr_aviso.ipynb
[I 2023-11-16 08:51:11.598 ServerApp] Saving file at /historical_analysis/21_zarr_aviso.ipynb
[I 2023-11-16 10:00:52.422 ServerApp] Saving file at /historical_analysis/21_zarr_aviso.ipynb
[I 2023-11-16 10:32:00.606 ServerApp] Saving file at /historical_analysis/21_zarr_aviso.ipynb
[I 2023-11-16 10:32:03.829 ServerApp] Saving file at /historical_analysis/job_distributed.pbs.o7441597
[I 2023-11-16 10:32:05.158 ServerApp] Saving file at /historical_analysis/job_distributed.py
[I 2023-11-16 10:32:09.592 ServerApp] Saving file at /historical_analysis/histlib/cstes.py
[I 2023-11-16 10:32:11.216 ServerApp] Saving file at /historical_analysis/21_zarr_aviso.ipynb
[I 2023-11-16 11:01:02.959 ServerApp] Starting buffering for bc183fb1-6411-48bf-9091-a5a5991392a5:7fdbde0b-2624-414c-8985-9495352078f3
[W 2023-11-16 11:27:09.912 LabApp] Could not determine jupyterlab build status without nodejs
[I 2023-11-16 11:27:10.027 ServerApp] Connecting to kernel bc183fb1-6411-48bf-9091-a5a5991392a5.
[I 2023-11-16 11:27:10.154 ServerApp] Starting buffering for bc183fb1-6411-48bf-9091-a5a5991392a5:1827c3bc-b74a-4ddb-a3d3-f9e46dcd357d
[I 2023-11-16 11:27:12.155 ServerApp] Kernel started: 478b67fc-a84e-4ed9-a3c2-b79f3c5835ea
[I 2023-11-16 11:27:12.241 ServerApp] Connecting to kernel bc183fb1-6411-48bf-9091-a5a5991392a5.
readline: /etc/inputrc: line 19: term: unknown variable name
[I 2023-11-16 11:27:13.110 ServerApp] Connecting to kernel 478b67fc-a84e-4ed9-a3c2-b79f3c5835ea.
[W 2023-11-16 11:32:43.112 ServerApp] WebSocket ping timeout after 119779 ms.
[I 2023-11-16 11:32:48.114 ServerApp] Starting buffering for 478b67fc-a84e-4ed9-a3c2-b79f3c5835ea:4d7e2e2b-ec70-428f-828f-21b2d4192eeb
[I 2023-11-16 11:33:02.635 ServerApp] Connecting to kernel 478b67fc-a84e-4ed9-a3c2-b79f3c5835ea.
[I 2023-11-16 11:33:02.635 ServerApp] Restoring connection for 478b67fc-a84e-4ed9-a3c2-b79f3c5835ea:4d7e2e2b-ec70-428f-828f-21b2d4192eeb
[I 2023-11-16 11:33:05.614 ServerApp] Saving file at /historical_analysis/job_distributed.py
[W 2023-11-16 11:33:05.804 ServerApp] /home1/datahome/mdemol/historical_analysis/.~job_distributed.py doesn't exist
[I 2023-11-16 11:33:41.635 ServerApp] Saving file at /historical_analysis/job_distributed.py
[I 2023-11-16 11:33:41.640 ServerApp] Saving file at /historical_analysis/job_distributed.pbs.o7445161
[I 2023-11-16 11:34:17.167 ServerApp] Saving file at /historical_analysis/histlib/erastar.py
[I 2023-11-16 11:34:22.459 ServerApp] Saving file at /historical_analysis/distributed.log
[W 2023-11-16 11:34:32.636 ServerApp] WebSocket ping timeout after 90001 ms.
[I 2023-11-16 11:34:37.638 ServerApp] Starting buffering for 478b67fc-a84e-4ed9-a3c2-b79f3c5835ea:4d7e2e2b-ec70-428f-828f-21b2d4192eeb
[W 2023-11-16 11:34:42.242 ServerApp] WebSocket ping timeout after 100920 ms.
[I 2023-11-16 11:34:47.243 ServerApp] Starting buffering for bc183fb1-6411-48bf-9091-a5a5991392a5:c26e0ff2-0276-4e49-a753-5c5b3fa1abc2
[I 2023-11-16 11:35:27.762 ServerApp] Saving file at /historical_analysis/histlib/cstes.py
[I 2023-11-16 11:35:29.075 ServerApp] Saving file at /historical_analysis/job_distributed.py
[I 2023-11-16 11:36:01.481 ServerApp] Saving file at /historical_analysis/Untitled.ipynb
[I 2023-11-16 11:36:11.540 ServerApp] Connecting to kernel bc183fb1-6411-48bf-9091-a5a5991392a5.
[I 2023-11-16 11:36:11.540 ServerApp] Restoring connection for bc183fb1-6411-48bf-9091-a5a5991392a5:c26e0ff2-0276-4e49-a753-5c5b3fa1abc2
[I 2023-11-16 11:36:11.547 ServerApp] Connecting to kernel 478b67fc-a84e-4ed9-a3c2-b79f3c5835ea.
[I 2023-11-16 11:36:11.547 ServerApp] Restoring connection for 478b67fc-a84e-4ed9-a3c2-b79f3c5835ea:4d7e2e2b-ec70-428f-828f-21b2d4192eeb
[I 2023-11-16 11:37:14.916 ServerApp] Saving file at /historical_analysis/21_zarr_aviso.ipynb
[I 2023-11-16 11:41:16.000 ServerApp] Starting buffering for bc183fb1-6411-48bf-9091-a5a5991392a5:c26e0ff2-0276-4e49-a753-5c5b3fa1abc2
[I 2023-11-16 11:41:16.001 ServerApp] Starting buffering for 478b67fc-a84e-4ed9-a3c2-b79f3c5835ea:4d7e2e2b-ec70-428f-828f-21b2d4192eeb
[C 2023-11-16 22:10:38.474 ServerApp] received signal 15, stopping
Terminated
[I 2023-11-16 22:10:38.643 ServerApp] Shutting down 6 extensions
[I 2023-11-16 22:10:38.644 ServerApp] Shutting down 2 kernels
[I 2023-11-16 22:10:38.645 ServerApp] Kernel shutdown: 478b67fc-a84e-4ed9-a3c2-b79f3c5835ea
[I 2023-11-16 22:10:38.645 ServerApp] Kernel shutdown: bc183fb1-6411-48bf-9091-a5a5991392a5
