Warning: no access to tty (Bad file descriptor).
Thus no job control in this shell.
Thu Nov  2 15:48:23 GMT 2023
/home1/datahome/mdemol/historical_analysis/launch/jlab.py:29: SyntaxWarning: "is not" with a literal. Did you mean "!="?
  elif dashinfo is not "0":
/home1/datahome/mdemol/historical_analysis/launch/jlab.py:32: SyntaxWarning: "is not" with a literal. Did you mean "!="?
  if dashinfo is not "0":
[I 2023-11-02 15:48:24.710 ServerApp] Package jupyterlab took 0.0000s to import
[I 2023-11-02 15:48:24.731 ServerApp] Package jupyter_lsp took 0.0211s to import
[W 2023-11-02 15:48:24.731 ServerApp] A `_jupyter_server_extension_points` function was not found in jupyter_lsp. Instead, a `_jupyter_server_extension_paths` function was found and will be used for now. This function name will be deprecated in future releases of Jupyter Server.
[I 2023-11-02 15:48:24.740 ServerApp] Package jupyter_server_terminals took 0.0083s to import
[I 2023-11-02 15:48:24.740 ServerApp] Package notebook took 0.0000s to import
[I 2023-11-02 15:48:24.743 ServerApp] Package notebook_shim took 0.0000s to import
[W 2023-11-02 15:48:24.743 ServerApp] A `_jupyter_server_extension_points` function was not found in notebook_shim. Instead, a `_jupyter_server_extension_paths` function was found and will be used for now. This function name will be deprecated in future releases of Jupyter Server.
[I 2023-11-02 15:48:26.268 ServerApp] Package panel.io.jupyter_server_extension took 1.5244s to import
[I 2023-11-02 15:48:26.268 ServerApp] jupyter_lsp | extension was successfully linked.
[I 2023-11-02 15:48:26.273 ServerApp] jupyter_server_terminals | extension was successfully linked.
[I 2023-11-02 15:48:26.278 ServerApp] jupyterlab | extension was successfully linked.
[W 2023-11-02 15:48:26.280 JupyterNotebookApp] 'password' has moved from NotebookApp to ServerApp. This config will be passed to ServerApp. Be sure to update your config before our next release.
[W 2023-11-02 15:48:26.283 ServerApp] ServerApp.password config is deprecated in 2.0. Use PasswordIdentityProvider.hashed_password.
[I 2023-11-02 15:48:26.283 ServerApp] notebook | extension was successfully linked.
[I 2023-11-02 15:48:26.625 ServerApp] notebook_shim | extension was successfully linked.
[I 2023-11-02 15:48:26.625 ServerApp] panel.io.jupyter_server_extension | extension was successfully linked.
[I 2023-11-02 15:48:26.662 ServerApp] notebook_shim | extension was successfully loaded.
[I 2023-11-02 15:48:26.664 ServerApp] jupyter_lsp | extension was successfully loaded.
[I 2023-11-02 15:48:26.666 ServerApp] jupyter_server_terminals | extension was successfully loaded.
[I 2023-11-02 15:48:26.669 LabApp] JupyterLab extension loaded from /home1/datahome/mdemol/.miniconda3/envs/histenv2/lib/python3.9/site-packages/jupyterlab
[I 2023-11-02 15:48:26.669 LabApp] JupyterLab application directory is /home1/datahome/mdemol/.miniconda3/envs/histenv2/share/jupyter/lab
[I 2023-11-02 15:48:26.670 LabApp] Extension Manager is 'pypi'.
[I 2023-11-02 15:48:26.673 ServerApp] jupyterlab | extension was successfully loaded.
[I 2023-11-02 15:48:26.677 ServerApp] notebook | extension was successfully loaded.
[I 2023-11-02 15:48:26.677 ServerApp] panel.io.jupyter_server_extension | extension was successfully loaded.
[I 2023-11-02 15:48:26.678 ServerApp] Serving notebooks from local directory: /home1/datahome/mdemol
[I 2023-11-02 15:48:26.678 ServerApp] Jupyter Server 2.9.1 is running at:
[I 2023-11-02 15:48:26.678 ServerApp] http://r2i0n25:8877/lab
[I 2023-11-02 15:48:26.678 ServerApp]     http://127.0.0.1:8877/lab
[I 2023-11-02 15:48:26.678 ServerApp] Use Control-C to stop this server and shut down all kernels (twice to skip confirmation).
[I 2023-11-02 15:48:26.716 ServerApp] Skipped non-installed server(s): bash-language-server, dockerfile-language-server-nodejs, javascript-typescript-langserver, jedi-language-server, julia-language-server, pyright, python-language-server, python-lsp-server, r-languageserver, sql-language-server, texlab, typescript-language-server, unified-language-server, vscode-css-languageserver-bin, vscode-html-languageserver-bin, vscode-json-languageserver-bin, yaml-language-server
[W 2023-11-02 15:48:30.812 ServerApp] 404 GET /api/kernels/32e2c6bb-9b1e-46ae-84d3-ab31319c56ff?1698940110681 (10.148.1.145): Kernel does not exist: 32e2c6bb-9b1e-46ae-84d3-ab31319c56ff
[W 2023-11-02 15:48:30.812 ServerApp] wrote error: 'Kernel does not exist: 32e2c6bb-9b1e-46ae-84d3-ab31319c56ff'
    Traceback (most recent call last):
      File "/home1/datahome/mdemol/.miniconda3/envs/histenv2/lib/python3.9/site-packages/tornado/web.py", line 1786, in _execute
        result = await result
      File "/home1/datahome/mdemol/.miniconda3/envs/histenv2/lib/python3.9/site-packages/jupyter_server/services/kernels/handlers.py", line 75, in get
        model = await ensure_async(km.kernel_model(kernel_id))
      File "/home1/datahome/mdemol/.miniconda3/envs/histenv2/lib/python3.9/site-packages/jupyter_server/services/kernels/kernelmanager.py", line 500, in kernel_model
        self._check_kernel_id(kernel_id)
      File "/home1/datahome/mdemol/.miniconda3/envs/histenv2/lib/python3.9/site-packages/jupyter_server/services/kernels/kernelmanager.py", line 531, in _check_kernel_id
        raise web.HTTPError(404, "Kernel does not exist: %s" % kernel_id)
    tornado.web.HTTPError: HTTP 404: Not Found (Kernel does not exist: 32e2c6bb-9b1e-46ae-84d3-ab31319c56ff)
[W 2023-11-02 15:48:30.814 ServerApp] 404 GET /api/kernels/32e2c6bb-9b1e-46ae-84d3-ab31319c56ff?1698940110681 (561c211cf284414792903f89972ed90c@10.148.1.145) 2.80ms referer=http://localhost:8877/lab/tree/historical_analysis/1_zarr_coloc.ipynb
[W 2023-11-02 15:48:31.184 ServerApp] 404 GET /api/kernels/32e2c6bb-9b1e-46ae-84d3-ab31319c56ff/channels?session_id=3df6d3bf-1885-40a9-bd87-61557e4e3d2f (10.148.1.145): Kernel does not exist: 32e2c6bb-9b1e-46ae-84d3-ab31319c56ff
[W 2023-11-02 15:48:31.210 ServerApp] 404 GET /api/kernels/32e2c6bb-9b1e-46ae-84d3-ab31319c56ff/channels?session_id=3df6d3bf-1885-40a9-bd87-61557e4e3d2f (561c211cf284414792903f89972ed90c@10.148.1.145) 26.37ms referer=None
[W 2023-11-02 15:48:31.340 ServerApp] 404 GET /api/kernels/32e2c6bb-9b1e-46ae-84d3-ab31319c56ff?1698940111255 (10.148.1.145): Kernel does not exist: 32e2c6bb-9b1e-46ae-84d3-ab31319c56ff
[W 2023-11-02 15:48:31.340 ServerApp] wrote error: 'Kernel does not exist: 32e2c6bb-9b1e-46ae-84d3-ab31319c56ff'
    Traceback (most recent call last):
      File "/home1/datahome/mdemol/.miniconda3/envs/histenv2/lib/python3.9/site-packages/tornado/web.py", line 1786, in _execute
        result = await result
      File "/home1/datahome/mdemol/.miniconda3/envs/histenv2/lib/python3.9/site-packages/jupyter_server/services/kernels/handlers.py", line 75, in get
        model = await ensure_async(km.kernel_model(kernel_id))
      File "/home1/datahome/mdemol/.miniconda3/envs/histenv2/lib/python3.9/site-packages/jupyter_server/services/kernels/kernelmanager.py", line 500, in kernel_model
        self._check_kernel_id(kernel_id)
      File "/home1/datahome/mdemol/.miniconda3/envs/histenv2/lib/python3.9/site-packages/jupyter_server/services/kernels/kernelmanager.py", line 531, in _check_kernel_id
        raise web.HTTPError(404, "Kernel does not exist: %s" % kernel_id)
    tornado.web.HTTPError: HTTP 404: Not Found (Kernel does not exist: 32e2c6bb-9b1e-46ae-84d3-ab31319c56ff)
[W 2023-11-02 15:48:31.341 ServerApp] 404 GET /api/kernels/32e2c6bb-9b1e-46ae-84d3-ab31319c56ff?1698940111255 (561c211cf284414792903f89972ed90c@10.148.1.145) 1.10ms referer=http://localhost:8877/lab/tree/historical_analysis/1_zarr_coloc.ipynb
[W 2023-11-02 15:48:32.804 ServerApp] 404 GET /api/kernels/32e2c6bb-9b1e-46ae-84d3-ab31319c56ff/channels?session_id=3df6d3bf-1885-40a9-bd87-61557e4e3d2f (10.148.1.145): Kernel does not exist: 32e2c6bb-9b1e-46ae-84d3-ab31319c56ff
[W 2023-11-02 15:48:32.804 ServerApp] 404 GET /api/kernels/32e2c6bb-9b1e-46ae-84d3-ab31319c56ff/channels?session_id=3df6d3bf-1885-40a9-bd87-61557e4e3d2f (561c211cf284414792903f89972ed90c@10.148.1.145) 0.99ms referer=None
[W 2023-11-02 15:48:32.882 ServerApp] 404 GET /api/kernels/54d7b563-d536-47a4-aaa2-26ce93745185?1698940112797 (10.148.1.145): Kernel does not exist: 54d7b563-d536-47a4-aaa2-26ce93745185
[W 2023-11-02 15:48:32.882 ServerApp] wrote error: 'Kernel does not exist: 54d7b563-d536-47a4-aaa2-26ce93745185'
    Traceback (most recent call last):
      File "/home1/datahome/mdemol/.miniconda3/envs/histenv2/lib/python3.9/site-packages/tornado/web.py", line 1786, in _execute
        result = await result
      File "/home1/datahome/mdemol/.miniconda3/envs/histenv2/lib/python3.9/site-packages/jupyter_server/services/kernels/handlers.py", line 75, in get
        model = await ensure_async(km.kernel_model(kernel_id))
      File "/home1/datahome/mdemol/.miniconda3/envs/histenv2/lib/python3.9/site-packages/jupyter_server/services/kernels/kernelmanager.py", line 500, in kernel_model
        self._check_kernel_id(kernel_id)
      File "/home1/datahome/mdemol/.miniconda3/envs/histenv2/lib/python3.9/site-packages/jupyter_server/services/kernels/kernelmanager.py", line 531, in _check_kernel_id
        raise web.HTTPError(404, "Kernel does not exist: %s" % kernel_id)
    tornado.web.HTTPError: HTTP 404: Not Found (Kernel does not exist: 54d7b563-d536-47a4-aaa2-26ce93745185)
[W 2023-11-02 15:48:32.882 ServerApp] 404 GET /api/kernels/54d7b563-d536-47a4-aaa2-26ce93745185?1698940112797 (561c211cf284414792903f89972ed90c@10.148.1.145) 0.86ms referer=http://localhost:8877/lab/tree/historical_analysis/1_zarr_coloc.ipynb
[W 2023-11-02 15:48:32.956 ServerApp] 404 GET /api/kernels/32e2c6bb-9b1e-46ae-84d3-ab31319c56ff?1698940112824 (10.148.1.145): Kernel does not exist: 32e2c6bb-9b1e-46ae-84d3-ab31319c56ff
[W 2023-11-02 15:48:32.956 ServerApp] wrote error: 'Kernel does not exist: 32e2c6bb-9b1e-46ae-84d3-ab31319c56ff'
    Traceback (most recent call last):
      File "/home1/datahome/mdemol/.miniconda3/envs/histenv2/lib/python3.9/site-packages/tornado/web.py", line 1786, in _execute
        result = await result
      File "/home1/datahome/mdemol/.miniconda3/envs/histenv2/lib/python3.9/site-packages/jupyter_server/services/kernels/handlers.py", line 75, in get
        model = await ensure_async(km.kernel_model(kernel_id))
      File "/home1/datahome/mdemol/.miniconda3/envs/histenv2/lib/python3.9/site-packages/jupyter_server/services/kernels/kernelmanager.py", line 500, in kernel_model
        self._check_kernel_id(kernel_id)
      File "/home1/datahome/mdemol/.miniconda3/envs/histenv2/lib/python3.9/site-packages/jupyter_server/services/kernels/kernelmanager.py", line 531, in _check_kernel_id
        raise web.HTTPError(404, "Kernel does not exist: %s" % kernel_id)
    tornado.web.HTTPError: HTTP 404: Not Found (Kernel does not exist: 32e2c6bb-9b1e-46ae-84d3-ab31319c56ff)
[W 2023-11-02 15:48:32.956 ServerApp] 404 GET /api/kernels/32e2c6bb-9b1e-46ae-84d3-ab31319c56ff?1698940112824 (561c211cf284414792903f89972ed90c@10.148.1.145) 0.87ms referer=http://localhost:8877/lab/tree/historical_analysis/1_zarr_coloc.ipynb
[W 2023-11-02 15:48:33.272 ServerApp] 404 GET /api/kernels/54d7b563-d536-47a4-aaa2-26ce93745185/channels?session_id=06615414-03e3-462e-80e4-19ff5ecf544a (10.148.1.145): Kernel does not exist: 54d7b563-d536-47a4-aaa2-26ce93745185
[W 2023-11-02 15:48:33.272 ServerApp] 404 GET /api/kernels/54d7b563-d536-47a4-aaa2-26ce93745185/channels?session_id=06615414-03e3-462e-80e4-19ff5ecf544a (561c211cf284414792903f89972ed90c@10.148.1.145) 0.94ms referer=None
[W 2023-11-02 15:48:33.360 ServerApp] 404 GET /api/kernels/54d7b563-d536-47a4-aaa2-26ce93745185?1698940113276 (10.148.1.145): Kernel does not exist: 54d7b563-d536-47a4-aaa2-26ce93745185
[W 2023-11-02 15:48:33.360 ServerApp] wrote error: 'Kernel does not exist: 54d7b563-d536-47a4-aaa2-26ce93745185'
    Traceback (most recent call last):
      File "/home1/datahome/mdemol/.miniconda3/envs/histenv2/lib/python3.9/site-packages/tornado/web.py", line 1786, in _execute
        result = await result
      File "/home1/datahome/mdemol/.miniconda3/envs/histenv2/lib/python3.9/site-packages/jupyter_server/services/kernels/handlers.py", line 75, in get
        model = await ensure_async(km.kernel_model(kernel_id))
      File "/home1/datahome/mdemol/.miniconda3/envs/histenv2/lib/python3.9/site-packages/jupyter_server/services/kernels/kernelmanager.py", line 500, in kernel_model
        self._check_kernel_id(kernel_id)
      File "/home1/datahome/mdemol/.miniconda3/envs/histenv2/lib/python3.9/site-packages/jupyter_server/services/kernels/kernelmanager.py", line 531, in _check_kernel_id
        raise web.HTTPError(404, "Kernel does not exist: %s" % kernel_id)
    tornado.web.HTTPError: HTTP 404: Not Found (Kernel does not exist: 54d7b563-d536-47a4-aaa2-26ce93745185)
[W 2023-11-02 15:48:33.360 ServerApp] 404 GET /api/kernels/54d7b563-d536-47a4-aaa2-26ce93745185?1698940113276 (561c211cf284414792903f89972ed90c@10.148.1.145) 0.87ms referer=http://localhost:8877/lab/tree/historical_analysis/1_zarr_coloc.ipynb
[W 2023-11-02 15:48:33.744 ServerApp] 404 GET /api/kernels/32e2c6bb-9b1e-46ae-84d3-ab31319c56ff/channels?session_id=3df6d3bf-1885-40a9-bd87-61557e4e3d2f (10.148.1.145): Kernel does not exist: 32e2c6bb-9b1e-46ae-84d3-ab31319c56ff
[W 2023-11-02 15:48:33.744 ServerApp] 404 GET /api/kernels/32e2c6bb-9b1e-46ae-84d3-ab31319c56ff/channels?session_id=3df6d3bf-1885-40a9-bd87-61557e4e3d2f (561c211cf284414792903f89972ed90c@10.148.1.145) 0.97ms referer=None
[W 2023-11-02 15:48:33.860 ServerApp] 404 GET /api/kernels/32e2c6bb-9b1e-46ae-84d3-ab31319c56ff?1698940113776 (10.148.1.145): Kernel does not exist: 32e2c6bb-9b1e-46ae-84d3-ab31319c56ff
[W 2023-11-02 15:48:33.860 ServerApp] wrote error: 'Kernel does not exist: 32e2c6bb-9b1e-46ae-84d3-ab31319c56ff'
    Traceback (most recent call last):
      File "/home1/datahome/mdemol/.miniconda3/envs/histenv2/lib/python3.9/site-packages/tornado/web.py", line 1786, in _execute
        result = await result
      File "/home1/datahome/mdemol/.miniconda3/envs/histenv2/lib/python3.9/site-packages/jupyter_server/services/kernels/handlers.py", line 75, in get
        model = await ensure_async(km.kernel_model(kernel_id))
      File "/home1/datahome/mdemol/.miniconda3/envs/histenv2/lib/python3.9/site-packages/jupyter_server/services/kernels/kernelmanager.py", line 500, in kernel_model
        self._check_kernel_id(kernel_id)
      File "/home1/datahome/mdemol/.miniconda3/envs/histenv2/lib/python3.9/site-packages/jupyter_server/services/kernels/kernelmanager.py", line 531, in _check_kernel_id
        raise web.HTTPError(404, "Kernel does not exist: %s" % kernel_id)
    tornado.web.HTTPError: HTTP 404: Not Found (Kernel does not exist: 32e2c6bb-9b1e-46ae-84d3-ab31319c56ff)
[W 2023-11-02 15:48:33.860 ServerApp] 404 GET /api/kernels/32e2c6bb-9b1e-46ae-84d3-ab31319c56ff?1698940113776 (561c211cf284414792903f89972ed90c@10.148.1.145) 0.87ms referer=http://localhost:8877/lab/tree/historical_analysis/1_zarr_coloc.ipynb
[W 2023-11-02 15:48:34.178 ServerApp] 404 GET /api/kernels/54d7b563-d536-47a4-aaa2-26ce93745185/channels?session_id=06615414-03e3-462e-80e4-19ff5ecf544a (10.148.1.145): Kernel does not exist: 54d7b563-d536-47a4-aaa2-26ce93745185
[W 2023-11-02 15:48:34.179 ServerApp] 404 GET /api/kernels/54d7b563-d536-47a4-aaa2-26ce93745185/channels?session_id=06615414-03e3-462e-80e4-19ff5ecf544a (561c211cf284414792903f89972ed90c@10.148.1.145) 0.93ms referer=None
[W 2023-11-02 15:48:34.264 ServerApp] 404 GET /api/kernels/54d7b563-d536-47a4-aaa2-26ce93745185?1698940114179 (10.148.1.145): Kernel does not exist: 54d7b563-d536-47a4-aaa2-26ce93745185
[W 2023-11-02 15:48:34.264 ServerApp] wrote error: 'Kernel does not exist: 54d7b563-d536-47a4-aaa2-26ce93745185'
    Traceback (most recent call last):
      File "/home1/datahome/mdemol/.miniconda3/envs/histenv2/lib/python3.9/site-packages/tornado/web.py", line 1786, in _execute
        result = await result
      File "/home1/datahome/mdemol/.miniconda3/envs/histenv2/lib/python3.9/site-packages/jupyter_server/services/kernels/handlers.py", line 75, in get
        model = await ensure_async(km.kernel_model(kernel_id))
      File "/home1/datahome/mdemol/.miniconda3/envs/histenv2/lib/python3.9/site-packages/jupyter_server/services/kernels/kernelmanager.py", line 500, in kernel_model
        self._check_kernel_id(kernel_id)
      File "/home1/datahome/mdemol/.miniconda3/envs/histenv2/lib/python3.9/site-packages/jupyter_server/services/kernels/kernelmanager.py", line 531, in _check_kernel_id
        raise web.HTTPError(404, "Kernel does not exist: %s" % kernel_id)
    tornado.web.HTTPError: HTTP 404: Not Found (Kernel does not exist: 54d7b563-d536-47a4-aaa2-26ce93745185)
[W 2023-11-02 15:48:34.265 ServerApp] 404 GET /api/kernels/54d7b563-d536-47a4-aaa2-26ce93745185?1698940114179 (561c211cf284414792903f89972ed90c@10.148.1.145) 1.16ms referer=http://localhost:8877/lab/tree/historical_analysis/1_zarr_coloc.ipynb
[W 2023-11-02 15:48:35.890 ServerApp] 404 GET /api/kernels/f3f17908-28f5-4a3a-8a8c-94fa9fd02b1a?1698940115796 (10.148.1.145): Kernel does not exist: f3f17908-28f5-4a3a-8a8c-94fa9fd02b1a
[W 2023-11-02 15:48:35.890 ServerApp] wrote error: 'Kernel does not exist: f3f17908-28f5-4a3a-8a8c-94fa9fd02b1a'
    Traceback (most recent call last):
      File "/home1/datahome/mdemol/.miniconda3/envs/histenv2/lib/python3.9/site-packages/tornado/web.py", line 1786, in _execute
        result = await result
      File "/home1/datahome/mdemol/.miniconda3/envs/histenv2/lib/python3.9/site-packages/jupyter_server/services/kernels/handlers.py", line 75, in get
        model = await ensure_async(km.kernel_model(kernel_id))
      File "/home1/datahome/mdemol/.miniconda3/envs/histenv2/lib/python3.9/site-packages/jupyter_server/services/kernels/kernelmanager.py", line 500, in kernel_model
        self._check_kernel_id(kernel_id)
      File "/home1/datahome/mdemol/.miniconda3/envs/histenv2/lib/python3.9/site-packages/jupyter_server/services/kernels/kernelmanager.py", line 531, in _check_kernel_id
        raise web.HTTPError(404, "Kernel does not exist: %s" % kernel_id)
    tornado.web.HTTPError: HTTP 404: Not Found (Kernel does not exist: f3f17908-28f5-4a3a-8a8c-94fa9fd02b1a)
[W 2023-11-02 15:48:35.890 ServerApp] 404 GET /api/kernels/f3f17908-28f5-4a3a-8a8c-94fa9fd02b1a?1698940115796 (561c211cf284414792903f89972ed90c@10.148.1.145) 0.97ms referer=http://localhost:8877/lab/tree/historical_analysis/1_zarr_coloc.ipynb
[W 2023-11-02 15:48:35.934 ServerApp] 404 GET /api/kernels/f3f17908-28f5-4a3a-8a8c-94fa9fd02b1a/channels?session_id=3f77c559-53a7-4124-a2c8-4693f7b5b677 (10.148.1.145): Kernel does not exist: f3f17908-28f5-4a3a-8a8c-94fa9fd02b1a
[W 2023-11-02 15:48:35.934 ServerApp] 404 GET /api/kernels/f3f17908-28f5-4a3a-8a8c-94fa9fd02b1a/channels?session_id=3f77c559-53a7-4124-a2c8-4693f7b5b677 (561c211cf284414792903f89972ed90c@10.148.1.145) 0.94ms referer=None
[W 2023-11-02 15:48:36.026 ServerApp] 404 GET /api/kernels/f3f17908-28f5-4a3a-8a8c-94fa9fd02b1a?1698940115942 (10.148.1.145): Kernel does not exist: f3f17908-28f5-4a3a-8a8c-94fa9fd02b1a
[W 2023-11-02 15:48:36.026 ServerApp] wrote error: 'Kernel does not exist: f3f17908-28f5-4a3a-8a8c-94fa9fd02b1a'
    Traceback (most recent call last):
      File "/home1/datahome/mdemol/.miniconda3/envs/histenv2/lib/python3.9/site-packages/tornado/web.py", line 1786, in _execute
        result = await result
      File "/home1/datahome/mdemol/.miniconda3/envs/histenv2/lib/python3.9/site-packages/jupyter_server/services/kernels/handlers.py", line 75, in get
        model = await ensure_async(km.kernel_model(kernel_id))
      File "/home1/datahome/mdemol/.miniconda3/envs/histenv2/lib/python3.9/site-packages/jupyter_server/services/kernels/kernelmanager.py", line 500, in kernel_model
        self._check_kernel_id(kernel_id)
      File "/home1/datahome/mdemol/.miniconda3/envs/histenv2/lib/python3.9/site-packages/jupyter_server/services/kernels/kernelmanager.py", line 531, in _check_kernel_id
        raise web.HTTPError(404, "Kernel does not exist: %s" % kernel_id)
    tornado.web.HTTPError: HTTP 404: Not Found (Kernel does not exist: f3f17908-28f5-4a3a-8a8c-94fa9fd02b1a)
[W 2023-11-02 15:48:36.026 ServerApp] 404 GET /api/kernels/f3f17908-28f5-4a3a-8a8c-94fa9fd02b1a?1698940115942 (561c211cf284414792903f89972ed90c@10.148.1.145) 0.85ms referer=http://localhost:8877/lab/tree/historical_analysis/1_zarr_coloc.ipynb
[W 2023-11-02 15:48:37.936 ServerApp] 404 GET /api/kernels/be5b2e84-e5c5-411d-9ef2-be0ead5215d1?1698940117842 (10.148.1.145): Kernel does not exist: be5b2e84-e5c5-411d-9ef2-be0ead5215d1
[W 2023-11-02 15:48:37.936 ServerApp] wrote error: 'Kernel does not exist: be5b2e84-e5c5-411d-9ef2-be0ead5215d1'
    Traceback (most recent call last):
      File "/home1/datahome/mdemol/.miniconda3/envs/histenv2/lib/python3.9/site-packages/tornado/web.py", line 1786, in _execute
        result = await result
      File "/home1/datahome/mdemol/.miniconda3/envs/histenv2/lib/python3.9/site-packages/jupyter_server/services/kernels/handlers.py", line 75, in get
        model = await ensure_async(km.kernel_model(kernel_id))
      File "/home1/datahome/mdemol/.miniconda3/envs/histenv2/lib/python3.9/site-packages/jupyter_server/services/kernels/kernelmanager.py", line 500, in kernel_model
        self._check_kernel_id(kernel_id)
      File "/home1/datahome/mdemol/.miniconda3/envs/histenv2/lib/python3.9/site-packages/jupyter_server/services/kernels/kernelmanager.py", line 531, in _check_kernel_id
        raise web.HTTPError(404, "Kernel does not exist: %s" % kernel_id)
    tornado.web.HTTPError: HTTP 404: Not Found (Kernel does not exist: be5b2e84-e5c5-411d-9ef2-be0ead5215d1)
[W 2023-11-02 15:48:37.936 ServerApp] 404 GET /api/kernels/be5b2e84-e5c5-411d-9ef2-be0ead5215d1?1698940117842 (561c211cf284414792903f89972ed90c@10.148.1.145) 0.85ms referer=http://localhost:8877/lab/tree/historical_analysis/1_zarr_coloc.ipynb
[W 2023-11-02 15:48:38.497 ServerApp] 404 GET /api/kernels/f3f17908-28f5-4a3a-8a8c-94fa9fd02b1a/channels?session_id=3f77c559-53a7-4124-a2c8-4693f7b5b677 (10.148.1.145): Kernel does not exist: f3f17908-28f5-4a3a-8a8c-94fa9fd02b1a
[W 2023-11-02 15:48:38.498 ServerApp] 404 GET /api/kernels/f3f17908-28f5-4a3a-8a8c-94fa9fd02b1a/channels?session_id=3f77c559-53a7-4124-a2c8-4693f7b5b677 (561c211cf284414792903f89972ed90c@10.148.1.145) 0.94ms referer=None
[W 2023-11-02 15:48:38.534 ServerApp] 404 GET /api/kernels/be5b2e84-e5c5-411d-9ef2-be0ead5215d1/channels?session_id=998ad2ab-70b2-40f4-870d-26c27c1e75b1 (10.148.1.145): Kernel does not exist: be5b2e84-e5c5-411d-9ef2-be0ead5215d1
[W 2023-11-02 15:48:38.534 ServerApp] 404 GET /api/kernels/be5b2e84-e5c5-411d-9ef2-be0ead5215d1/channels?session_id=998ad2ab-70b2-40f4-870d-26c27c1e75b1 (561c211cf284414792903f89972ed90c@10.148.1.145) 0.93ms referer=None
[I 2023-11-02 15:48:51.836 ServerApp] Saving file at /historical_analysis/1_zarr_coloc.ipynb
[W 2023-11-02 15:49:00.263 LabApp] Could not determine jupyterlab build status without nodejs
[I 2023-11-02 15:49:11.272 ServerApp] Kernel started: 906c9776-584e-40c6-a03d-2869007c5f18
[I 2023-11-02 15:49:11.783 ServerApp] Kernel started: a044e72d-8492-49cf-a70e-cf364712c8b7
[E 2023-11-02 15:49:11.787 ServerApp] Uncaught exception GET /api/kernels?1698940151544 (10.148.1.145)
    HTTPServerRequest(protocol='http', host='localhost:8877', method='GET', uri='/api/kernels?1698940151544', version='HTTP/1.1', remote_ip='10.148.1.145')
    Traceback (most recent call last):
      File "/home1/datahome/mdemol/.miniconda3/envs/histenv2/lib/python3.9/site-packages/traitlets/traitlets.py", line 627, in get
        value = obj._trait_values[self.name]  # type: ignore[index]
    KeyError: 'last_activity'
    
    During handling of the above exception, another exception occurred:
    
    Traceback (most recent call last):
      File "/home1/datahome/mdemol/.miniconda3/envs/histenv2/lib/python3.9/site-packages/tornado/web.py", line 1786, in _execute
        result = await result
      File "/home1/datahome/mdemol/.miniconda3/envs/histenv2/lib/python3.9/site-packages/jupyter_server/services/kernels/handlers.py", line 41, in get
        kernels = await ensure_async(km.list_kernels())
      File "/home1/datahome/mdemol/.miniconda3/envs/histenv2/lib/python3.9/site-packages/jupyter_server/services/kernels/kernelmanager.py", line 520, in list_kernels
        model = self.kernel_model(kernel_id)
      File "/home1/datahome/mdemol/.miniconda3/envs/histenv2/lib/python3.9/site-packages/jupyter_server/services/kernels/kernelmanager.py", line 506, in kernel_model
        "last_activity": isoformat(kernel.last_activity),
      File "/home1/datahome/mdemol/.miniconda3/envs/histenv2/lib/python3.9/site-packages/traitlets/traitlets.py", line 720, in __get__
        return t.cast(G, self.get(obj, cls))  # the G should encode the Optional
      File "/home1/datahome/mdemol/.miniconda3/envs/histenv2/lib/python3.9/site-packages/traitlets/traitlets.py", line 644, in get
        value = self._validate(obj, default)
      File "/home1/datahome/mdemol/.miniconda3/envs/histenv2/lib/python3.9/site-packages/traitlets/traitlets.py", line 756, in _validate
        value = self.validate(obj, value)
      File "/home1/datahome/mdemol/.miniconda3/envs/histenv2/lib/python3.9/site-packages/traitlets/traitlets.py", line 2322, in validate
        self.error(obj, value)
      File "/home1/datahome/mdemol/.miniconda3/envs/histenv2/lib/python3.9/site-packages/traitlets/traitlets.py", line 860, in error
        raise TraitError(e)
    traitlets.traitlets.TraitError: The 'last_activity' trait of a ServerKernelManager instance expected a datetime, not the NoneType None.
[W 2023-11-02 15:49:11.840 ServerApp] wrote error: 'Unhandled error'
    Traceback (most recent call last):
      File "/home1/datahome/mdemol/.miniconda3/envs/histenv2/lib/python3.9/site-packages/traitlets/traitlets.py", line 627, in get
        value = obj._trait_values[self.name]  # type: ignore[index]
    KeyError: 'last_activity'
    
    During handling of the above exception, another exception occurred:
    
    Traceback (most recent call last):
      File "/home1/datahome/mdemol/.miniconda3/envs/histenv2/lib/python3.9/site-packages/tornado/web.py", line 1786, in _execute
        result = await result
      File "/home1/datahome/mdemol/.miniconda3/envs/histenv2/lib/python3.9/site-packages/jupyter_server/services/kernels/handlers.py", line 41, in get
        kernels = await ensure_async(km.list_kernels())
      File "/home1/datahome/mdemol/.miniconda3/envs/histenv2/lib/python3.9/site-packages/jupyter_server/services/kernels/kernelmanager.py", line 520, in list_kernels
        model = self.kernel_model(kernel_id)
      File "/home1/datahome/mdemol/.miniconda3/envs/histenv2/lib/python3.9/site-packages/jupyter_server/services/kernels/kernelmanager.py", line 506, in kernel_model
        "last_activity": isoformat(kernel.last_activity),
      File "/home1/datahome/mdemol/.miniconda3/envs/histenv2/lib/python3.9/site-packages/traitlets/traitlets.py", line 720, in __get__
        return t.cast(G, self.get(obj, cls))  # the G should encode the Optional
      File "/home1/datahome/mdemol/.miniconda3/envs/histenv2/lib/python3.9/site-packages/traitlets/traitlets.py", line 644, in get
        value = self._validate(obj, default)
      File "/home1/datahome/mdemol/.miniconda3/envs/histenv2/lib/python3.9/site-packages/traitlets/traitlets.py", line 756, in _validate
        value = self.validate(obj, value)
      File "/home1/datahome/mdemol/.miniconda3/envs/histenv2/lib/python3.9/site-packages/traitlets/traitlets.py", line 2322, in validate
        self.error(obj, value)
      File "/home1/datahome/mdemol/.miniconda3/envs/histenv2/lib/python3.9/site-packages/traitlets/traitlets.py", line 860, in error
        raise TraitError(e)
    traitlets.traitlets.TraitError: The 'last_activity' trait of a ServerKernelManager instance expected a datetime, not the NoneType None.
[E 2023-11-02 15:49:11.841 ServerApp] {
      "Host": "localhost:8877",
      "Accept": "*/*",
      "Referer": "http://localhost:8877/lab/tree/historical_analysis/1_zarr_coloc.ipynb",
      "User-Agent": "Mozilla/5.0 (Macintosh; Intel Mac OS X 10_15_7) AppleWebKit/605.1.15 (KHTML, like Gecko) Version/15.1 Safari/605.1.15"
    }
[E 2023-11-02 15:49:11.841 ServerApp] 500 GET /api/kernels?1698940151544 (561c211cf284414792903f89972ed90c@10.148.1.145) 54.54ms referer=http://localhost:8877/lab/tree/historical_analysis/1_zarr_coloc.ipynb
[I 2023-11-02 15:49:11.842 ServerApp] Kernel started: 0350eca4-c5b4-460c-b0d1-e0dff370407a
[I 2023-11-02 15:49:11.846 ServerApp] Kernel started: f20f9f64-dc8e-46f9-9297-674084c55c6a
readline: /etc/inputrc: line 19: term: unknown variable name
[I 2023-11-02 15:49:12.337 ServerApp] Connecting to kernel 906c9776-584e-40c6-a03d-2869007c5f18.
readline: /etc/inputrc: line 19: term: unknown variable name
[I 2023-11-02 15:49:12.944 ServerApp] Connecting to kernel a044e72d-8492-49cf-a70e-cf364712c8b7.
readline: /etc/inputrc: line 19: term: unknown variable name
[I 2023-11-02 15:49:13.174 ServerApp] Connecting to kernel 0350eca4-c5b4-460c-b0d1-e0dff370407a.
readline: /etc/inputrc: line 19: term: unknown variable name
[I 2023-11-02 15:49:13.268 ServerApp] Connecting to kernel f20f9f64-dc8e-46f9-9297-674084c55c6a.
[I 2023-11-02 15:49:13.270 ServerApp] Connecting to kernel f20f9f64-dc8e-46f9-9297-674084c55c6a.
[I 2023-11-02 15:49:13.557 ServerApp] Kernel started: 43d01b69-bf86-45a8-9fbe-7f4af90a4ca9
[I 2023-11-02 15:49:13.570 ServerApp] Connecting to kernel f20f9f64-dc8e-46f9-9297-674084c55c6a.
readline: /etc/inputrc: line 19: term: unknown variable name
[I 2023-11-02 15:49:14.766 ServerApp] Connecting to kernel 43d01b69-bf86-45a8-9fbe-7f4af90a4ca9.
[I 2023-11-02 15:51:11.829 ServerApp] Saving file at /historical_analysis/1_zarr_coloc.ipynb
[I 2023-11-02 15:55:13.073 ServerApp] Saving file at /historical_analysis/1_zarr_coloc.ipynb
[I 2023-11-02 15:55:21.891 ServerApp] Saving file at /m2_2022/sandbox/zarr_slacorrection.ipynb
[I 2023-11-02 15:55:23.306 ServerApp] Starting buffering for 906c9776-584e-40c6-a03d-2869007c5f18:168b832a-a42b-431b-98f2-7e2ad1a83457
[I 2023-11-02 15:55:23.306 ServerApp] Starting buffering for 43d01b69-bf86-45a8-9fbe-7f4af90a4ca9:2050d92d-3e25-4007-aba8-be8eb4f8ff6d
[I 2023-11-02 15:55:23.307 ServerApp] Starting buffering for a044e72d-8492-49cf-a70e-cf364712c8b7:f2056425-0d5a-46ac-b7cc-3e5ea2ed50cc
[I 2023-11-02 15:55:23.307 ServerApp] Starting buffering for f20f9f64-dc8e-46f9-9297-674084c55c6a:1957400a-4e64-464f-84e0-b382f847d16a
[I 2023-11-02 15:55:23.308 ServerApp] Starting buffering for 0350eca4-c5b4-460c-b0d1-e0dff370407a:0a3bb6d3-726e-4d6a-8b8b-7ae87dc956df
[W 2023-11-02 15:55:24.997 LabApp] Could not determine jupyterlab build status without nodejs
[I 2023-11-02 15:55:25.097 ServerApp] Connecting to kernel 906c9776-584e-40c6-a03d-2869007c5f18.
[I 2023-11-02 15:55:25.137 ServerApp] Connecting to kernel a044e72d-8492-49cf-a70e-cf364712c8b7.
[I 2023-11-02 15:55:25.139 ServerApp] Connecting to kernel 0350eca4-c5b4-460c-b0d1-e0dff370407a.
[I 2023-11-02 15:55:25.142 ServerApp] Connecting to kernel f20f9f64-dc8e-46f9-9297-674084c55c6a.
[I 2023-11-02 15:55:25.143 ServerApp] Connecting to kernel 43d01b69-bf86-45a8-9fbe-7f4af90a4ca9.
[I 2023-11-02 15:55:25.253 ServerApp] Starting buffering for 906c9776-584e-40c6-a03d-2869007c5f18:35748b5e-eaea-4ed5-9794-6c451fdff765
[I 2023-11-02 15:55:25.261 ServerApp] Starting buffering for a044e72d-8492-49cf-a70e-cf364712c8b7:a7d5a5d8-42f1-4504-8dd5-068bed2ef894
[I 2023-11-02 15:55:25.263 ServerApp] Starting buffering for 0350eca4-c5b4-460c-b0d1-e0dff370407a:eae95577-5465-4758-a78e-76c2b9a9cf7b
[I 2023-11-02 15:55:25.271 ServerApp] Starting buffering for f20f9f64-dc8e-46f9-9297-674084c55c6a:834569cd-22e3-4126-9cae-1a6f2ac25cd2
[I 2023-11-02 15:55:25.272 ServerApp] Starting buffering for 43d01b69-bf86-45a8-9fbe-7f4af90a4ca9:7247bada-5eb5-4451-b59c-2b20bc7310e7
[I 2023-11-02 15:55:27.951 ServerApp] Connecting to kernel 906c9776-584e-40c6-a03d-2869007c5f18.
[I 2023-11-02 15:55:28.358 ServerApp] Connecting to kernel 0350eca4-c5b4-460c-b0d1-e0dff370407a.
[I 2023-11-02 15:55:28.804 ServerApp] Connecting to kernel a044e72d-8492-49cf-a70e-cf364712c8b7.
[I 2023-11-02 15:55:28.807 ServerApp] Connecting to kernel f20f9f64-dc8e-46f9-9297-674084c55c6a.
[I 2023-11-02 15:55:29.043 ServerApp] Connecting to kernel 43d01b69-bf86-45a8-9fbe-7f4af90a4ca9.
[C 2023-11-02 15:56:16.658 ServerApp] received signal 15, stopping
Terminated
[I 2023-11-02 15:56:16.708 ServerApp] Shutting down 6 extensions
[I 2023-11-02 15:56:16.708 ServerApp] Shutting down 5 kernels
[I 2023-11-02 15:56:16.709 ServerApp] Kernel shutdown: 0350eca4-c5b4-460c-b0d1-e0dff370407a
[I 2023-11-02 15:56:16.709 ServerApp] Kernel shutdown: f20f9f64-dc8e-46f9-9297-674084c55c6a
[I 2023-11-02 15:56:16.709 ServerApp] Kernel shutdown: a044e72d-8492-49cf-a70e-cf364712c8b7
[I 2023-11-02 15:56:16.709 ServerApp] Kernel shutdown: 43d01b69-bf86-45a8-9fbe-7f4af90a4ca9
[I 2023-11-02 15:56:16.709 ServerApp] Kernel shutdown: 906c9776-584e-40c6-a03d-2869007c5f18
