Warning: no access to tty (Bad file descriptor).
Thus no job control in this shell.
Wed Nov 15 08:46:07 GMT 2023
/home1/datahome/mdemol/historical_analysis/launch/jlab.py:29: SyntaxWarning: "is not" with a literal. Did you mean "!="?
  elif dashinfo is not "0":
/home1/datahome/mdemol/historical_analysis/launch/jlab.py:32: SyntaxWarning: "is not" with a literal. Did you mean "!="?
  if dashinfo is not "0":
[I 2023-11-15 08:46:30.859 ServerApp] Package jupyterlab took 0.0000s to import
[I 2023-11-15 08:46:31.432 ServerApp] Package jupyter_lsp took 0.5725s to import
[W 2023-11-15 08:46:31.432 ServerApp] A `_jupyter_server_extension_points` function was not found in jupyter_lsp. Instead, a `_jupyter_server_extension_paths` function was found and will be used for now. This function name will be deprecated in future releases of Jupyter Server.
[I 2023-11-15 08:46:31.680 ServerApp] Package jupyter_server_terminals took 0.2477s to import
[I 2023-11-15 08:46:31.681 ServerApp] Package notebook took 0.0000s to import
[I 2023-11-15 08:46:31.691 ServerApp] Package notebook_shim took 0.0000s to import
[W 2023-11-15 08:46:31.692 ServerApp] A `_jupyter_server_extension_points` function was not found in notebook_shim. Instead, a `_jupyter_server_extension_paths` function was found and will be used for now. This function name will be deprecated in future releases of Jupyter Server.
[I 2023-11-15 08:46:57.768 ServerApp] Package panel.io.jupyter_server_extension took 26.0593s to import
[I 2023-11-15 08:46:57.768 ServerApp] jupyter_lsp | extension was successfully linked.
[I 2023-11-15 08:46:57.774 ServerApp] jupyter_server_terminals | extension was successfully linked.
[I 2023-11-15 08:46:57.780 ServerApp] jupyterlab | extension was successfully linked.
[W 2023-11-15 08:46:57.802 JupyterNotebookApp] 'password' has moved from NotebookApp to ServerApp. This config will be passed to ServerApp. Be sure to update your config before our next release.
[W 2023-11-15 08:46:57.806 ServerApp] ServerApp.password config is deprecated in 2.0. Use PasswordIdentityProvider.hashed_password.
[I 2023-11-15 08:46:57.806 ServerApp] notebook | extension was successfully linked.
[I 2023-11-15 08:47:04.369 ServerApp] notebook_shim | extension was successfully linked.
[I 2023-11-15 08:47:04.369 ServerApp] panel.io.jupyter_server_extension | extension was successfully linked.
[I 2023-11-15 08:47:04.702 ServerApp] notebook_shim | extension was successfully loaded.
[I 2023-11-15 08:47:04.704 ServerApp] jupyter_lsp | extension was successfully loaded.
[I 2023-11-15 08:47:04.706 ServerApp] jupyter_server_terminals | extension was successfully loaded.
[I 2023-11-15 08:47:04.826 LabApp] JupyterLab extension loaded from /home1/datahome/mdemol/.miniconda3/envs/histenv2/lib/python3.9/site-packages/jupyterlab
[I 2023-11-15 08:47:04.826 LabApp] JupyterLab application directory is /home1/datahome/mdemol/.miniconda3/envs/histenv2/share/jupyter/lab
[I 2023-11-15 08:47:04.837 LabApp] Extension Manager is 'pypi'.
[I 2023-11-15 08:47:04.840 ServerApp] jupyterlab | extension was successfully loaded.
[I 2023-11-15 08:47:04.844 ServerApp] notebook | extension was successfully loaded.
[I 2023-11-15 08:47:04.845 ServerApp] panel.io.jupyter_server_extension | extension was successfully loaded.
[I 2023-11-15 08:47:04.845 ServerApp] Serving notebooks from local directory: /home1/datahome/mdemol
[I 2023-11-15 08:47:04.845 ServerApp] Jupyter Server 2.9.1 is running at:
[I 2023-11-15 08:47:04.845 ServerApp] http://r1i2n35:8877/lab
[I 2023-11-15 08:47:04.845 ServerApp]     http://127.0.0.1:8877/lab
[I 2023-11-15 08:47:04.845 ServerApp] Use Control-C to stop this server and shut down all kernels (twice to skip confirmation).
[I 2023-11-15 08:47:04.976 ServerApp] Skipped non-installed server(s): bash-language-server, dockerfile-language-server-nodejs, javascript-typescript-langserver, jedi-language-server, julia-language-server, pyright, python-language-server, python-lsp-server, r-languageserver, sql-language-server, texlab, typescript-language-server, unified-language-server, vscode-css-languageserver-bin, vscode-html-languageserver-bin, vscode-json-languageserver-bin, yaml-language-server
[W 2023-11-15 08:48:41.340 ServerApp] 404 GET /api/kernels/fa1ad29c-96f7-4a1d-a958-1f60493564d2?1700038121303 (10.148.1.145): Kernel does not exist: fa1ad29c-96f7-4a1d-a958-1f60493564d2
[W 2023-11-15 08:48:41.341 ServerApp] wrote error: 'Kernel does not exist: fa1ad29c-96f7-4a1d-a958-1f60493564d2'
    Traceback (most recent call last):
      File "/home1/datahome/mdemol/.miniconda3/envs/histenv2/lib/python3.9/site-packages/tornado/web.py", line 1786, in _execute
        result = await result
      File "/home1/datahome/mdemol/.miniconda3/envs/histenv2/lib/python3.9/site-packages/jupyter_server/services/kernels/handlers.py", line 75, in get
        model = await ensure_async(km.kernel_model(kernel_id))
      File "/home1/datahome/mdemol/.miniconda3/envs/histenv2/lib/python3.9/site-packages/jupyter_server/services/kernels/kernelmanager.py", line 500, in kernel_model
        self._check_kernel_id(kernel_id)
      File "/home1/datahome/mdemol/.miniconda3/envs/histenv2/lib/python3.9/site-packages/jupyter_server/services/kernels/kernelmanager.py", line 531, in _check_kernel_id
        raise web.HTTPError(404, "Kernel does not exist: %s" % kernel_id)
    tornado.web.HTTPError: HTTP 404: Not Found (Kernel does not exist: fa1ad29c-96f7-4a1d-a958-1f60493564d2)
[W 2023-11-15 08:48:41.391 ServerApp] 404 GET /api/kernels/fa1ad29c-96f7-4a1d-a958-1f60493564d2?1700038121303 (fab7e86e3096494a86aeccede238bd42@10.148.1.145) 51.78ms referer=http://localhost:8877/lab/tree/historical_analysis/job_distributed.py
[W 2023-11-15 08:48:41.588 ServerApp] 404 GET /api/kernels/fa1ad29c-96f7-4a1d-a958-1f60493564d2/channels?session_id=03311e1b-ceae-447a-9a01-a8c98d75826c (10.148.1.145): Kernel does not exist: fa1ad29c-96f7-4a1d-a958-1f60493564d2
[W 2023-11-15 08:48:41.710 ServerApp] 404 GET /api/kernels/fa1ad29c-96f7-4a1d-a958-1f60493564d2/channels?session_id=03311e1b-ceae-447a-9a01-a8c98d75826c (fab7e86e3096494a86aeccede238bd42@10.148.1.145) 122.20ms referer=None
[W 2023-11-15 08:48:41.889 ServerApp] 404 GET /api/kernels/fa1ad29c-96f7-4a1d-a958-1f60493564d2?1700038121857 (10.148.1.145): Kernel does not exist: fa1ad29c-96f7-4a1d-a958-1f60493564d2
[W 2023-11-15 08:48:41.889 ServerApp] wrote error: 'Kernel does not exist: fa1ad29c-96f7-4a1d-a958-1f60493564d2'
    Traceback (most recent call last):
      File "/home1/datahome/mdemol/.miniconda3/envs/histenv2/lib/python3.9/site-packages/tornado/web.py", line 1786, in _execute
        result = await result
      File "/home1/datahome/mdemol/.miniconda3/envs/histenv2/lib/python3.9/site-packages/jupyter_server/services/kernels/handlers.py", line 75, in get
        model = await ensure_async(km.kernel_model(kernel_id))
      File "/home1/datahome/mdemol/.miniconda3/envs/histenv2/lib/python3.9/site-packages/jupyter_server/services/kernels/kernelmanager.py", line 500, in kernel_model
        self._check_kernel_id(kernel_id)
      File "/home1/datahome/mdemol/.miniconda3/envs/histenv2/lib/python3.9/site-packages/jupyter_server/services/kernels/kernelmanager.py", line 531, in _check_kernel_id
        raise web.HTTPError(404, "Kernel does not exist: %s" % kernel_id)
    tornado.web.HTTPError: HTTP 404: Not Found (Kernel does not exist: fa1ad29c-96f7-4a1d-a958-1f60493564d2)
[W 2023-11-15 08:48:41.890 ServerApp] 404 GET /api/kernels/fa1ad29c-96f7-4a1d-a958-1f60493564d2?1700038121857 (fab7e86e3096494a86aeccede238bd42@10.148.1.145) 1.06ms referer=http://localhost:8877/lab/tree/historical_analysis/job_distributed.py
[W 2023-11-15 08:48:44.821 ServerApp] 404 GET /api/kernels/fa1ad29c-96f7-4a1d-a958-1f60493564d2/channels?session_id=03311e1b-ceae-447a-9a01-a8c98d75826c (10.148.1.145): Kernel does not exist: fa1ad29c-96f7-4a1d-a958-1f60493564d2
[W 2023-11-15 08:48:44.821 ServerApp] 404 GET /api/kernels/fa1ad29c-96f7-4a1d-a958-1f60493564d2/channels?session_id=03311e1b-ceae-447a-9a01-a8c98d75826c (fab7e86e3096494a86aeccede238bd42@10.148.1.145) 0.97ms referer=None
[W 2023-11-15 08:48:45.023 ServerApp] 404 GET /api/kernels/fa1ad29c-96f7-4a1d-a958-1f60493564d2?1700038124990 (10.148.1.145): Kernel does not exist: fa1ad29c-96f7-4a1d-a958-1f60493564d2
[W 2023-11-15 08:48:45.023 ServerApp] wrote error: 'Kernel does not exist: fa1ad29c-96f7-4a1d-a958-1f60493564d2'
    Traceback (most recent call last):
      File "/home1/datahome/mdemol/.miniconda3/envs/histenv2/lib/python3.9/site-packages/tornado/web.py", line 1786, in _execute
        result = await result
      File "/home1/datahome/mdemol/.miniconda3/envs/histenv2/lib/python3.9/site-packages/jupyter_server/services/kernels/handlers.py", line 75, in get
        model = await ensure_async(km.kernel_model(kernel_id))
      File "/home1/datahome/mdemol/.miniconda3/envs/histenv2/lib/python3.9/site-packages/jupyter_server/services/kernels/kernelmanager.py", line 500, in kernel_model
        self._check_kernel_id(kernel_id)
      File "/home1/datahome/mdemol/.miniconda3/envs/histenv2/lib/python3.9/site-packages/jupyter_server/services/kernels/kernelmanager.py", line 531, in _check_kernel_id
        raise web.HTTPError(404, "Kernel does not exist: %s" % kernel_id)
    tornado.web.HTTPError: HTTP 404: Not Found (Kernel does not exist: fa1ad29c-96f7-4a1d-a958-1f60493564d2)
[W 2023-11-15 08:48:45.023 ServerApp] 404 GET /api/kernels/fa1ad29c-96f7-4a1d-a958-1f60493564d2?1700038124990 (fab7e86e3096494a86aeccede238bd42@10.148.1.145) 0.88ms referer=http://localhost:8877/lab/tree/historical_analysis/job_distributed.py
[W 2023-11-15 08:48:45.584 ServerApp] 404 GET /api/kernels/f65502ae-4812-40cf-9848-9254b8f557e2?1700038125552 (10.148.1.145): Kernel does not exist: f65502ae-4812-40cf-9848-9254b8f557e2
[W 2023-11-15 08:48:45.584 ServerApp] wrote error: 'Kernel does not exist: f65502ae-4812-40cf-9848-9254b8f557e2'
    Traceback (most recent call last):
      File "/home1/datahome/mdemol/.miniconda3/envs/histenv2/lib/python3.9/site-packages/tornado/web.py", line 1786, in _execute
        result = await result
      File "/home1/datahome/mdemol/.miniconda3/envs/histenv2/lib/python3.9/site-packages/jupyter_server/services/kernels/handlers.py", line 75, in get
        model = await ensure_async(km.kernel_model(kernel_id))
      File "/home1/datahome/mdemol/.miniconda3/envs/histenv2/lib/python3.9/site-packages/jupyter_server/services/kernels/kernelmanager.py", line 500, in kernel_model
        self._check_kernel_id(kernel_id)
      File "/home1/datahome/mdemol/.miniconda3/envs/histenv2/lib/python3.9/site-packages/jupyter_server/services/kernels/kernelmanager.py", line 531, in _check_kernel_id
        raise web.HTTPError(404, "Kernel does not exist: %s" % kernel_id)
    tornado.web.HTTPError: HTTP 404: Not Found (Kernel does not exist: f65502ae-4812-40cf-9848-9254b8f557e2)
[W 2023-11-15 08:48:45.584 ServerApp] 404 GET /api/kernels/f65502ae-4812-40cf-9848-9254b8f557e2?1700038125552 (fab7e86e3096494a86aeccede238bd42@10.148.1.145) 0.88ms referer=http://localhost:8877/lab/tree/historical_analysis/job_distributed.py
[W 2023-11-15 08:48:46.013 ServerApp] 404 GET /api/kernels/f65502ae-4812-40cf-9848-9254b8f557e2/channels?session_id=23946496-a7af-4e66-b5fe-2dd7ab90d798 (10.148.1.145): Kernel does not exist: f65502ae-4812-40cf-9848-9254b8f557e2
[W 2023-11-15 08:48:46.013 ServerApp] 404 GET /api/kernels/f65502ae-4812-40cf-9848-9254b8f557e2/channels?session_id=23946496-a7af-4e66-b5fe-2dd7ab90d798 (fab7e86e3096494a86aeccede238bd42@10.148.1.145) 0.96ms referer=None
[W 2023-11-15 08:48:46.065 ServerApp] 404 GET /api/kernels/f65502ae-4812-40cf-9848-9254b8f557e2?1700038126035 (10.148.1.145): Kernel does not exist: f65502ae-4812-40cf-9848-9254b8f557e2
[W 2023-11-15 08:48:46.065 ServerApp] wrote error: 'Kernel does not exist: f65502ae-4812-40cf-9848-9254b8f557e2'
    Traceback (most recent call last):
      File "/home1/datahome/mdemol/.miniconda3/envs/histenv2/lib/python3.9/site-packages/tornado/web.py", line 1786, in _execute
        result = await result
      File "/home1/datahome/mdemol/.miniconda3/envs/histenv2/lib/python3.9/site-packages/jupyter_server/services/kernels/handlers.py", line 75, in get
        model = await ensure_async(km.kernel_model(kernel_id))
      File "/home1/datahome/mdemol/.miniconda3/envs/histenv2/lib/python3.9/site-packages/jupyter_server/services/kernels/kernelmanager.py", line 500, in kernel_model
        self._check_kernel_id(kernel_id)
      File "/home1/datahome/mdemol/.miniconda3/envs/histenv2/lib/python3.9/site-packages/jupyter_server/services/kernels/kernelmanager.py", line 531, in _check_kernel_id
        raise web.HTTPError(404, "Kernel does not exist: %s" % kernel_id)
    tornado.web.HTTPError: HTTP 404: Not Found (Kernel does not exist: f65502ae-4812-40cf-9848-9254b8f557e2)
[W 2023-11-15 08:48:46.065 ServerApp] 404 GET /api/kernels/f65502ae-4812-40cf-9848-9254b8f557e2?1700038126035 (fab7e86e3096494a86aeccede238bd42@10.148.1.145) 0.85ms referer=http://localhost:8877/lab/tree/historical_analysis/job_distributed.py
[W 2023-11-15 08:48:46.488 ServerApp] 404 GET /api/kernels/fa1ad29c-96f7-4a1d-a958-1f60493564d2/channels?session_id=03311e1b-ceae-447a-9a01-a8c98d75826c (10.148.1.145): Kernel does not exist: fa1ad29c-96f7-4a1d-a958-1f60493564d2
[W 2023-11-15 08:48:46.489 ServerApp] 404 GET /api/kernels/fa1ad29c-96f7-4a1d-a958-1f60493564d2/channels?session_id=03311e1b-ceae-447a-9a01-a8c98d75826c (fab7e86e3096494a86aeccede238bd42@10.148.1.145) 0.95ms referer=None
[W 2023-11-15 08:48:46.564 ServerApp] 404 GET /api/kernels/fa1ad29c-96f7-4a1d-a958-1f60493564d2?1700038126534 (10.148.1.145): Kernel does not exist: fa1ad29c-96f7-4a1d-a958-1f60493564d2
[W 2023-11-15 08:48:46.564 ServerApp] wrote error: 'Kernel does not exist: fa1ad29c-96f7-4a1d-a958-1f60493564d2'
    Traceback (most recent call last):
      File "/home1/datahome/mdemol/.miniconda3/envs/histenv2/lib/python3.9/site-packages/tornado/web.py", line 1786, in _execute
        result = await result
      File "/home1/datahome/mdemol/.miniconda3/envs/histenv2/lib/python3.9/site-packages/jupyter_server/services/kernels/handlers.py", line 75, in get
        model = await ensure_async(km.kernel_model(kernel_id))
      File "/home1/datahome/mdemol/.miniconda3/envs/histenv2/lib/python3.9/site-packages/jupyter_server/services/kernels/kernelmanager.py", line 500, in kernel_model
        self._check_kernel_id(kernel_id)
      File "/home1/datahome/mdemol/.miniconda3/envs/histenv2/lib/python3.9/site-packages/jupyter_server/services/kernels/kernelmanager.py", line 531, in _check_kernel_id
        raise web.HTTPError(404, "Kernel does not exist: %s" % kernel_id)
    tornado.web.HTTPError: HTTP 404: Not Found (Kernel does not exist: fa1ad29c-96f7-4a1d-a958-1f60493564d2)
[W 2023-11-15 08:48:46.564 ServerApp] 404 GET /api/kernels/fa1ad29c-96f7-4a1d-a958-1f60493564d2?1700038126534 (fab7e86e3096494a86aeccede238bd42@10.148.1.145) 0.86ms referer=http://localhost:8877/lab/tree/historical_analysis/job_distributed.py
[W 2023-11-15 08:48:48.675 ServerApp] 404 GET /api/kernels/f65502ae-4812-40cf-9848-9254b8f557e2/channels?session_id=23946496-a7af-4e66-b5fe-2dd7ab90d798 (10.148.1.145): Kernel does not exist: f65502ae-4812-40cf-9848-9254b8f557e2
[W 2023-11-15 08:48:48.675 ServerApp] 404 GET /api/kernels/f65502ae-4812-40cf-9848-9254b8f557e2/channels?session_id=23946496-a7af-4e66-b5fe-2dd7ab90d798 (fab7e86e3096494a86aeccede238bd42@10.148.1.145) 0.95ms referer=None
[W 2023-11-15 08:48:48.703 ServerApp] 404 GET /api/kernels/f65502ae-4812-40cf-9848-9254b8f557e2?1700038128674 (10.148.1.145): Kernel does not exist: f65502ae-4812-40cf-9848-9254b8f557e2
[W 2023-11-15 08:48:48.703 ServerApp] wrote error: 'Kernel does not exist: f65502ae-4812-40cf-9848-9254b8f557e2'
    Traceback (most recent call last):
      File "/home1/datahome/mdemol/.miniconda3/envs/histenv2/lib/python3.9/site-packages/tornado/web.py", line 1786, in _execute
        result = await result
      File "/home1/datahome/mdemol/.miniconda3/envs/histenv2/lib/python3.9/site-packages/jupyter_server/services/kernels/handlers.py", line 75, in get
        model = await ensure_async(km.kernel_model(kernel_id))
      File "/home1/datahome/mdemol/.miniconda3/envs/histenv2/lib/python3.9/site-packages/jupyter_server/services/kernels/kernelmanager.py", line 500, in kernel_model
        self._check_kernel_id(kernel_id)
      File "/home1/datahome/mdemol/.miniconda3/envs/histenv2/lib/python3.9/site-packages/jupyter_server/services/kernels/kernelmanager.py", line 531, in _check_kernel_id
        raise web.HTTPError(404, "Kernel does not exist: %s" % kernel_id)
    tornado.web.HTTPError: HTTP 404: Not Found (Kernel does not exist: f65502ae-4812-40cf-9848-9254b8f557e2)
[W 2023-11-15 08:48:48.703 ServerApp] 404 GET /api/kernels/f65502ae-4812-40cf-9848-9254b8f557e2?1700038128674 (fab7e86e3096494a86aeccede238bd42@10.148.1.145) 0.87ms referer=http://localhost:8877/lab/tree/historical_analysis/job_distributed.py
[W 2023-11-15 08:48:53.211 ServerApp] 404 GET /api/kernels/f65502ae-4812-40cf-9848-9254b8f557e2/channels?session_id=23946496-a7af-4e66-b5fe-2dd7ab90d798 (10.148.1.145): Kernel does not exist: f65502ae-4812-40cf-9848-9254b8f557e2
[W 2023-11-15 08:48:53.212 ServerApp] 404 GET /api/kernels/f65502ae-4812-40cf-9848-9254b8f557e2/channels?session_id=23946496-a7af-4e66-b5fe-2dd7ab90d798 (fab7e86e3096494a86aeccede238bd42@10.148.1.145) 1.05ms referer=None
[W 2023-11-15 08:48:53.249 ServerApp] 404 GET /api/kernels/f65502ae-4812-40cf-9848-9254b8f557e2?1700038133220 (10.148.1.145): Kernel does not exist: f65502ae-4812-40cf-9848-9254b8f557e2
[W 2023-11-15 08:48:53.249 ServerApp] wrote error: 'Kernel does not exist: f65502ae-4812-40cf-9848-9254b8f557e2'
    Traceback (most recent call last):
      File "/home1/datahome/mdemol/.miniconda3/envs/histenv2/lib/python3.9/site-packages/tornado/web.py", line 1786, in _execute
        result = await result
      File "/home1/datahome/mdemol/.miniconda3/envs/histenv2/lib/python3.9/site-packages/jupyter_server/services/kernels/handlers.py", line 75, in get
        model = await ensure_async(km.kernel_model(kernel_id))
      File "/home1/datahome/mdemol/.miniconda3/envs/histenv2/lib/python3.9/site-packages/jupyter_server/services/kernels/kernelmanager.py", line 500, in kernel_model
        self._check_kernel_id(kernel_id)
      File "/home1/datahome/mdemol/.miniconda3/envs/histenv2/lib/python3.9/site-packages/jupyter_server/services/kernels/kernelmanager.py", line 531, in _check_kernel_id
        raise web.HTTPError(404, "Kernel does not exist: %s" % kernel_id)
    tornado.web.HTTPError: HTTP 404: Not Found (Kernel does not exist: f65502ae-4812-40cf-9848-9254b8f557e2)
[W 2023-11-15 08:48:53.250 ServerApp] 404 GET /api/kernels/f65502ae-4812-40cf-9848-9254b8f557e2?1700038133220 (fab7e86e3096494a86aeccede238bd42@10.148.1.145) 0.85ms referer=http://localhost:8877/lab/tree/historical_analysis/job_distributed.py
[W 2023-11-15 08:48:56.726 ServerApp] 404 GET /api/kernels/fa1ad29c-96f7-4a1d-a958-1f60493564d2/channels?session_id=03311e1b-ceae-447a-9a01-a8c98d75826c (10.148.1.145): Kernel does not exist: fa1ad29c-96f7-4a1d-a958-1f60493564d2
[W 2023-11-15 08:48:56.727 ServerApp] 404 GET /api/kernels/fa1ad29c-96f7-4a1d-a958-1f60493564d2/channels?session_id=03311e1b-ceae-447a-9a01-a8c98d75826c (fab7e86e3096494a86aeccede238bd42@10.148.1.145) 1.41ms referer=None
[W 2023-11-15 08:48:56.749 ServerApp] 404 GET /api/kernels/fa1ad29c-96f7-4a1d-a958-1f60493564d2?1700038136720 (10.148.1.145): Kernel does not exist: fa1ad29c-96f7-4a1d-a958-1f60493564d2
[W 2023-11-15 08:48:56.749 ServerApp] wrote error: 'Kernel does not exist: fa1ad29c-96f7-4a1d-a958-1f60493564d2'
    Traceback (most recent call last):
      File "/home1/datahome/mdemol/.miniconda3/envs/histenv2/lib/python3.9/site-packages/tornado/web.py", line 1786, in _execute
        result = await result
      File "/home1/datahome/mdemol/.miniconda3/envs/histenv2/lib/python3.9/site-packages/jupyter_server/services/kernels/handlers.py", line 75, in get
        model = await ensure_async(km.kernel_model(kernel_id))
      File "/home1/datahome/mdemol/.miniconda3/envs/histenv2/lib/python3.9/site-packages/jupyter_server/services/kernels/kernelmanager.py", line 500, in kernel_model
        self._check_kernel_id(kernel_id)
      File "/home1/datahome/mdemol/.miniconda3/envs/histenv2/lib/python3.9/site-packages/jupyter_server/services/kernels/kernelmanager.py", line 531, in _check_kernel_id
        raise web.HTTPError(404, "Kernel does not exist: %s" % kernel_id)
    tornado.web.HTTPError: HTTP 404: Not Found (Kernel does not exist: fa1ad29c-96f7-4a1d-a958-1f60493564d2)
[W 2023-11-15 08:48:56.750 ServerApp] 404 GET /api/kernels/fa1ad29c-96f7-4a1d-a958-1f60493564d2?1700038136720 (fab7e86e3096494a86aeccede238bd42@10.148.1.145) 0.95ms referer=http://localhost:8877/lab/tree/historical_analysis/job_distributed.py
[W 2023-11-15 08:48:59.433 ServerApp] 404 GET /api/kernels/fa1ad29c-96f7-4a1d-a958-1f60493564d2/channels?session_id=03311e1b-ceae-447a-9a01-a8c98d75826c (10.148.1.145): Kernel does not exist: fa1ad29c-96f7-4a1d-a958-1f60493564d2
[W 2023-11-15 08:48:59.434 ServerApp] 404 GET /api/kernels/fa1ad29c-96f7-4a1d-a958-1f60493564d2/channels?session_id=03311e1b-ceae-447a-9a01-a8c98d75826c (fab7e86e3096494a86aeccede238bd42@10.148.1.145) 1.00ms referer=None
[W 2023-11-15 08:48:59.533 ServerApp] 404 GET /api/kernels/fa1ad29c-96f7-4a1d-a958-1f60493564d2?1700038139503 (10.148.1.145): Kernel does not exist: fa1ad29c-96f7-4a1d-a958-1f60493564d2
[W 2023-11-15 08:48:59.533 ServerApp] wrote error: 'Kernel does not exist: fa1ad29c-96f7-4a1d-a958-1f60493564d2'
    Traceback (most recent call last):
      File "/home1/datahome/mdemol/.miniconda3/envs/histenv2/lib/python3.9/site-packages/tornado/web.py", line 1786, in _execute
        result = await result
      File "/home1/datahome/mdemol/.miniconda3/envs/histenv2/lib/python3.9/site-packages/jupyter_server/services/kernels/handlers.py", line 75, in get
        model = await ensure_async(km.kernel_model(kernel_id))
      File "/home1/datahome/mdemol/.miniconda3/envs/histenv2/lib/python3.9/site-packages/jupyter_server/services/kernels/kernelmanager.py", line 500, in kernel_model
        self._check_kernel_id(kernel_id)
      File "/home1/datahome/mdemol/.miniconda3/envs/histenv2/lib/python3.9/site-packages/jupyter_server/services/kernels/kernelmanager.py", line 531, in _check_kernel_id
        raise web.HTTPError(404, "Kernel does not exist: %s" % kernel_id)
    tornado.web.HTTPError: HTTP 404: Not Found (Kernel does not exist: fa1ad29c-96f7-4a1d-a958-1f60493564d2)
[W 2023-11-15 08:48:59.533 ServerApp] 404 GET /api/kernels/fa1ad29c-96f7-4a1d-a958-1f60493564d2?1700038139503 (fab7e86e3096494a86aeccede238bd42@10.148.1.145) 0.85ms referer=http://localhost:8877/lab/tree/historical_analysis/job_distributed.py
[W 2023-11-15 08:49:01.785 ServerApp] 404 GET /api/kernels/f65502ae-4812-40cf-9848-9254b8f557e2/channels?session_id=23946496-a7af-4e66-b5fe-2dd7ab90d798 (10.148.1.145): Kernel does not exist: f65502ae-4812-40cf-9848-9254b8f557e2
[W 2023-11-15 08:49:01.785 ServerApp] 404 GET /api/kernels/f65502ae-4812-40cf-9848-9254b8f557e2/channels?session_id=23946496-a7af-4e66-b5fe-2dd7ab90d798 (fab7e86e3096494a86aeccede238bd42@10.148.1.145) 0.95ms referer=None
[W 2023-11-15 08:49:01.814 ServerApp] 404 GET /api/kernels/f65502ae-4812-40cf-9848-9254b8f557e2?1700038141784 (10.148.1.145): Kernel does not exist: f65502ae-4812-40cf-9848-9254b8f557e2
[W 2023-11-15 08:49:01.814 ServerApp] wrote error: 'Kernel does not exist: f65502ae-4812-40cf-9848-9254b8f557e2'
    Traceback (most recent call last):
      File "/home1/datahome/mdemol/.miniconda3/envs/histenv2/lib/python3.9/site-packages/tornado/web.py", line 1786, in _execute
        result = await result
      File "/home1/datahome/mdemol/.miniconda3/envs/histenv2/lib/python3.9/site-packages/jupyter_server/services/kernels/handlers.py", line 75, in get
        model = await ensure_async(km.kernel_model(kernel_id))
      File "/home1/datahome/mdemol/.miniconda3/envs/histenv2/lib/python3.9/site-packages/jupyter_server/services/kernels/kernelmanager.py", line 500, in kernel_model
        self._check_kernel_id(kernel_id)
      File "/home1/datahome/mdemol/.miniconda3/envs/histenv2/lib/python3.9/site-packages/jupyter_server/services/kernels/kernelmanager.py", line 531, in _check_kernel_id
        raise web.HTTPError(404, "Kernel does not exist: %s" % kernel_id)
    tornado.web.HTTPError: HTTP 404: Not Found (Kernel does not exist: f65502ae-4812-40cf-9848-9254b8f557e2)
[W 2023-11-15 08:49:01.814 ServerApp] 404 GET /api/kernels/f65502ae-4812-40cf-9848-9254b8f557e2?1700038141784 (fab7e86e3096494a86aeccede238bd42@10.148.1.145) 0.85ms referer=http://localhost:8877/lab/tree/historical_analysis/job_distributed.py
[W 2023-11-15 08:49:07.765 ServerApp] 404 GET /api/kernels/f65502ae-4812-40cf-9848-9254b8f557e2/channels?session_id=23946496-a7af-4e66-b5fe-2dd7ab90d798 (10.148.1.145): Kernel does not exist: f65502ae-4812-40cf-9848-9254b8f557e2
[W 2023-11-15 08:49:07.766 ServerApp] 404 GET /api/kernels/f65502ae-4812-40cf-9848-9254b8f557e2/channels?session_id=23946496-a7af-4e66-b5fe-2dd7ab90d798 (fab7e86e3096494a86aeccede238bd42@10.148.1.145) 0.97ms referer=None
[W 2023-11-15 08:49:07.810 ServerApp] 404 GET /api/kernels/f65502ae-4812-40cf-9848-9254b8f557e2?1700038147772 (10.148.1.145): Kernel does not exist: f65502ae-4812-40cf-9848-9254b8f557e2
[W 2023-11-15 08:49:07.810 ServerApp] wrote error: 'Kernel does not exist: f65502ae-4812-40cf-9848-9254b8f557e2'
    Traceback (most recent call last):
      File "/home1/datahome/mdemol/.miniconda3/envs/histenv2/lib/python3.9/site-packages/tornado/web.py", line 1786, in _execute
        result = await result
      File "/home1/datahome/mdemol/.miniconda3/envs/histenv2/lib/python3.9/site-packages/jupyter_server/services/kernels/handlers.py", line 75, in get
        model = await ensure_async(km.kernel_model(kernel_id))
      File "/home1/datahome/mdemol/.miniconda3/envs/histenv2/lib/python3.9/site-packages/jupyter_server/services/kernels/kernelmanager.py", line 500, in kernel_model
        self._check_kernel_id(kernel_id)
      File "/home1/datahome/mdemol/.miniconda3/envs/histenv2/lib/python3.9/site-packages/jupyter_server/services/kernels/kernelmanager.py", line 531, in _check_kernel_id
        raise web.HTTPError(404, "Kernel does not exist: %s" % kernel_id)
    tornado.web.HTTPError: HTTP 404: Not Found (Kernel does not exist: f65502ae-4812-40cf-9848-9254b8f557e2)
[W 2023-11-15 08:49:07.810 ServerApp] 404 GET /api/kernels/f65502ae-4812-40cf-9848-9254b8f557e2?1700038147772 (fab7e86e3096494a86aeccede238bd42@10.148.1.145) 0.84ms referer=http://localhost:8877/lab/tree/historical_analysis/job_distributed.py
[W 2023-11-15 08:49:14.426 ServerApp] 404 GET /api/kernels/fa1ad29c-96f7-4a1d-a958-1f60493564d2/channels?session_id=03311e1b-ceae-447a-9a01-a8c98d75826c (10.148.1.145): Kernel does not exist: fa1ad29c-96f7-4a1d-a958-1f60493564d2
[W 2023-11-15 08:49:14.427 ServerApp] 404 GET /api/kernels/fa1ad29c-96f7-4a1d-a958-1f60493564d2/channels?session_id=03311e1b-ceae-447a-9a01-a8c98d75826c (fab7e86e3096494a86aeccede238bd42@10.148.1.145) 1.53ms referer=None
[W 2023-11-15 08:49:14.525 ServerApp] 404 GET /api/kernels/fa1ad29c-96f7-4a1d-a958-1f60493564d2?1700038154496 (10.148.1.145): Kernel does not exist: fa1ad29c-96f7-4a1d-a958-1f60493564d2
[W 2023-11-15 08:49:14.525 ServerApp] wrote error: 'Kernel does not exist: fa1ad29c-96f7-4a1d-a958-1f60493564d2'
    Traceback (most recent call last):
      File "/home1/datahome/mdemol/.miniconda3/envs/histenv2/lib/python3.9/site-packages/tornado/web.py", line 1786, in _execute
        result = await result
      File "/home1/datahome/mdemol/.miniconda3/envs/histenv2/lib/python3.9/site-packages/jupyter_server/services/kernels/handlers.py", line 75, in get
        model = await ensure_async(km.kernel_model(kernel_id))
      File "/home1/datahome/mdemol/.miniconda3/envs/histenv2/lib/python3.9/site-packages/jupyter_server/services/kernels/kernelmanager.py", line 500, in kernel_model
        self._check_kernel_id(kernel_id)
      File "/home1/datahome/mdemol/.miniconda3/envs/histenv2/lib/python3.9/site-packages/jupyter_server/services/kernels/kernelmanager.py", line 531, in _check_kernel_id
        raise web.HTTPError(404, "Kernel does not exist: %s" % kernel_id)
    tornado.web.HTTPError: HTTP 404: Not Found (Kernel does not exist: fa1ad29c-96f7-4a1d-a958-1f60493564d2)
[W 2023-11-15 08:49:14.526 ServerApp] 404 GET /api/kernels/fa1ad29c-96f7-4a1d-a958-1f60493564d2?1700038154496 (fab7e86e3096494a86aeccede238bd42@10.148.1.145) 1.33ms referer=http://localhost:8877/lab/tree/historical_analysis/job_distributed.py
[W 2023-11-15 08:52:27.393 LabApp] Could not determine jupyterlab build status without nodejs
[I 2023-11-15 08:52:40.566 ServerApp] Kernel started: 486520bc-e5f9-480c-b968-be84b0014b72
[I 2023-11-15 08:52:40.568 ServerApp] Kernel started: fe5f49cb-2b45-425f-92dc-5d3ce83d3c3e
readline: readline: /etc/inputrc: line 19: term: unknown variable name
/etc/inputrc: line 19: term: unknown variable name
[I 2023-11-15 08:53:16.083 ServerApp] Connecting to kernel fe5f49cb-2b45-425f-92dc-5d3ce83d3c3e.
[I 2023-11-15 08:53:16.085 ServerApp] Connecting to kernel fe5f49cb-2b45-425f-92dc-5d3ce83d3c3e.
[I 2023-11-15 08:53:16.087 ServerApp] Connecting to kernel fe5f49cb-2b45-425f-92dc-5d3ce83d3c3e.
[I 2023-11-15 08:53:16.122 ServerApp] Connecting to kernel 486520bc-e5f9-480c-b968-be84b0014b72.
[I 2023-11-15 08:53:33.092 ServerApp] Saving file at /historical_analysis/job_distributed.py
[I 2023-11-15 09:04:34.418 ServerApp] Starting buffering for 486520bc-e5f9-480c-b968-be84b0014b72:4b1e021a-5e4f-40f1-ac66-500c133e8c58
[I 2023-11-15 09:04:34.419 ServerApp] Starting buffering for fe5f49cb-2b45-425f-92dc-5d3ce83d3c3e:559b392f-4d94-43f7-8caf-d3bf7e34482b
[I 2023-11-15 09:12:22.353 ServerApp] Connecting to kernel 486520bc-e5f9-480c-b968-be84b0014b72.
[I 2023-11-15 09:12:22.353 ServerApp] Restoring connection for 486520bc-e5f9-480c-b968-be84b0014b72:4b1e021a-5e4f-40f1-ac66-500c133e8c58
[I 2023-11-15 09:12:40.350 ServerApp] Connecting to kernel fe5f49cb-2b45-425f-92dc-5d3ce83d3c3e.
[I 2023-11-15 09:12:40.350 ServerApp] Restoring connection for fe5f49cb-2b45-425f-92dc-5d3ce83d3c3e:559b392f-4d94-43f7-8caf-d3bf7e34482b
[I 2023-11-15 09:12:45.312 ServerApp] Starting buffering for 486520bc-e5f9-480c-b968-be84b0014b72:4b1e021a-5e4f-40f1-ac66-500c133e8c58
[I 2023-11-15 09:12:45.313 ServerApp] Starting buffering for fe5f49cb-2b45-425f-92dc-5d3ce83d3c3e:559b392f-4d94-43f7-8caf-d3bf7e34482b
[W 2023-11-15 18:05:45.547 LabApp] Could not determine jupyterlab build status without nodejs
[I 2023-11-15 18:05:45.566 ServerApp] Connecting to kernel 486520bc-e5f9-480c-b968-be84b0014b72.
[I 2023-11-15 18:05:45.570 ServerApp] Connecting to kernel fe5f49cb-2b45-425f-92dc-5d3ce83d3c3e.
[I 2023-11-15 18:05:45.677 ServerApp] Starting buffering for 486520bc-e5f9-480c-b968-be84b0014b72:5dadc40b-436b-45d6-a3bf-7f5e31775a0c
[I 2023-11-15 18:05:45.693 ServerApp] Starting buffering for fe5f49cb-2b45-425f-92dc-5d3ce83d3c3e:fe45ed31-44c9-4097-b09a-dc5aab21e757
[I 2023-11-15 18:05:47.273 ServerApp] Connecting to kernel fe5f49cb-2b45-425f-92dc-5d3ce83d3c3e.
[I 2023-11-15 18:05:47.421 ServerApp] Connecting to kernel 486520bc-e5f9-480c-b968-be84b0014b72.
[I 2023-11-15 18:06:03.224 ServerApp] Saving file at /historical_analysis/job_distributed.py
[I 2023-11-15 18:06:29.485 ServerApp] Starting buffering for fe5f49cb-2b45-425f-92dc-5d3ce83d3c3e:a6d15cc7-9fb9-4446-a1e2-e9819df5894b
[I 2023-11-15 18:06:29.486 ServerApp] Starting buffering for 486520bc-e5f9-480c-b968-be84b0014b72:7d9ebb3b-c260-488d-93b8-3271da44617f
[I 2023-11-15 18:06:43.516 ServerApp] Connecting to kernel fe5f49cb-2b45-425f-92dc-5d3ce83d3c3e.
[I 2023-11-15 18:06:43.517 ServerApp] Restoring connection for fe5f49cb-2b45-425f-92dc-5d3ce83d3c3e:a6d15cc7-9fb9-4446-a1e2-e9819df5894b
[I 2023-11-15 18:06:46.977 ServerApp] Connecting to kernel 486520bc-e5f9-480c-b968-be84b0014b72.
[I 2023-11-15 18:06:46.978 ServerApp] Restoring connection for 486520bc-e5f9-480c-b968-be84b0014b72:7d9ebb3b-c260-488d-93b8-3271da44617f
[I 2023-11-15 18:08:03.334 ServerApp] Saving file at /historical_analysis/job_distributed.py
[I 2023-11-15 18:09:14.846 ServerApp] Saving file at /historical_analysis/job_distributed.py
[I 2023-11-15 18:09:52.385 ServerApp] Saving file at /historical_analysis/job_distributed.py
[I 2023-11-15 18:12:16.320 ServerApp] Saving file at /historical_analysis/job_distributed.py
[W 2023-11-15 18:16:13.518 ServerApp] WebSocket ping timeout after 119968 ms.
[W 2023-11-15 18:16:16.979 ServerApp] WebSocket ping timeout after 119968 ms.
[I 2023-11-15 18:16:18.521 ServerApp] Starting buffering for fe5f49cb-2b45-425f-92dc-5d3ce83d3c3e:a6d15cc7-9fb9-4446-a1e2-e9819df5894b
[I 2023-11-15 18:16:21.982 ServerApp] Starting buffering for 486520bc-e5f9-480c-b968-be84b0014b72:7d9ebb3b-c260-488d-93b8-3271da44617f
[I 2023-11-15 23:09:34.958 ServerApp] Connecting to kernel 486520bc-e5f9-480c-b968-be84b0014b72.
[I 2023-11-15 23:09:34.959 ServerApp] Restoring connection for 486520bc-e5f9-480c-b968-be84b0014b72:7d9ebb3b-c260-488d-93b8-3271da44617f
[I 2023-11-15 23:09:36.288 ServerApp] Connecting to kernel fe5f49cb-2b45-425f-92dc-5d3ce83d3c3e.
[I 2023-11-15 23:09:36.288 ServerApp] Restoring connection for fe5f49cb-2b45-425f-92dc-5d3ce83d3c3e:a6d15cc7-9fb9-4446-a1e2-e9819df5894b
[I 2023-11-15 23:10:06.531 ServerApp] Starting buffering for 486520bc-e5f9-480c-b968-be84b0014b72:7d9ebb3b-c260-488d-93b8-3271da44617f
[I 2023-11-15 23:10:06.532 ServerApp] Starting buffering for fe5f49cb-2b45-425f-92dc-5d3ce83d3c3e:a6d15cc7-9fb9-4446-a1e2-e9819df5894b
[W 2023-11-15 23:10:12.618 LabApp] Could not determine jupyterlab build status without nodejs
[I 2023-11-15 23:10:13.791 ServerApp] Connecting to kernel 486520bc-e5f9-480c-b968-be84b0014b72.
[I 2023-11-15 23:10:13.793 ServerApp] Connecting to kernel fe5f49cb-2b45-425f-92dc-5d3ce83d3c3e.
[I 2023-11-15 23:10:13.941 ServerApp] Starting buffering for 486520bc-e5f9-480c-b968-be84b0014b72:7767eef8-3020-45b2-9199-48d135b01ff5
[I 2023-11-15 23:10:13.950 ServerApp] Starting buffering for fe5f49cb-2b45-425f-92dc-5d3ce83d3c3e:d823068f-cb78-4f83-aec9-5f98caffe0b0
[I 2023-11-15 23:10:27.928 ServerApp] Connecting to kernel fe5f49cb-2b45-425f-92dc-5d3ce83d3c3e.
[I 2023-11-15 23:10:27.962 ServerApp] Connecting to kernel 486520bc-e5f9-480c-b968-be84b0014b72.
[I 2023-11-15 23:12:00.348 ServerApp] Saving file at /historical_analysis/job_distributed.py
[I 2023-11-15 23:12:06.851 ServerApp] Saving file at /historical_analysis/job_distributed.py
[I 2023-11-15 23:12:28.959 ServerApp] Saving file at /historical_analysis/job_distributed.py
[W 2023-11-15 23:12:29.060 ServerApp] /home1/datahome/mdemol/historical_analysis/.~job_distributed.py doesn't exist
[I 2023-11-15 23:12:59.440 ServerApp] Saving file at /historical_analysis/job_distributed.py
[I 2023-11-15 23:13:00.781 ServerApp] Saving file at /historical_analysis/job_distributed.pbs.o7439708
[I 2023-11-15 23:13:00.823 ServerApp] Saving file at /historical_analysis/job_distributed.pbs.o7439729
[I 2023-11-15 23:13:00.832 ServerApp] Saving file at /historical_analysis/distributed.log
[I 2023-11-15 23:13:00.886 ServerApp] Saving file at /historical_analysis/job_distributed.pbs.o7435157
[I 2023-11-15 23:13:05.202 ServerApp] Saving file at /historical_analysis/histlib/cstes.py
[I 2023-11-15 23:13:12.050 ServerApp] Saving file at /historical_analysis/Untitled.ipynb
[I 2023-11-15 23:13:26.795 ServerApp] Saving file at /historical_analysis/21_zarr_aviso.ipynb
[I 2023-11-15 23:16:20.503 ServerApp] Starting buffering for fe5f49cb-2b45-425f-92dc-5d3ce83d3c3e:efa5ff91-4120-43da-8249-f63045309a82
[I 2023-11-15 23:16:20.504 ServerApp] Starting buffering for 486520bc-e5f9-480c-b968-be84b0014b72:a865eac5-b8fe-42c2-bef5-3bad6d3f99f5
Terminated
[C 2023-11-16 08:18:28.056 ServerApp] received signal 15, stopping
[I 2023-11-16 08:18:28.172 ServerApp] Shutting down 6 extensions
[I 2023-11-16 08:18:28.172 ServerApp] Shutting down 2 kernels
[I 2023-11-16 08:18:28.173 ServerApp] Kernel shutdown: fe5f49cb-2b45-425f-92dc-5d3ce83d3c3e
[I 2023-11-16 08:18:28.173 ServerApp] Kernel shutdown: 486520bc-e5f9-480c-b968-be84b0014b72
