Warning: no access to tty (Bad file descriptor).
Thus no job control in this shell.
Wed Nov  8 14:35:41 GMT 2023
/home1/datahome/mdemol/historical_analysis/launch/jlab.py:29: SyntaxWarning: "is not" with a literal. Did you mean "!="?
  elif dashinfo is not "0":
/home1/datahome/mdemol/historical_analysis/launch/jlab.py:32: SyntaxWarning: "is not" with a literal. Did you mean "!="?
  if dashinfo is not "0":
[I 2023-11-08 14:35:42.775 ServerApp] Package jupyterlab took 0.0000s to import
[I 2023-11-08 14:35:42.799 ServerApp] Package jupyter_lsp took 0.0234s to import
[W 2023-11-08 14:35:42.799 ServerApp] A `_jupyter_server_extension_points` function was not found in jupyter_lsp. Instead, a `_jupyter_server_extension_paths` function was found and will be used for now. This function name will be deprecated in future releases of Jupyter Server.
[I 2023-11-08 14:35:42.809 ServerApp] Package jupyter_server_terminals took 0.0091s to import
[I 2023-11-08 14:35:42.809 ServerApp] Package notebook took 0.0000s to import
[I 2023-11-08 14:35:42.812 ServerApp] Package notebook_shim took 0.0000s to import
[W 2023-11-08 14:35:42.812 ServerApp] A `_jupyter_server_extension_points` function was not found in notebook_shim. Instead, a `_jupyter_server_extension_paths` function was found and will be used for now. This function name will be deprecated in future releases of Jupyter Server.
[I 2023-11-08 14:35:44.355 ServerApp] Package panel.io.jupyter_server_extension took 1.5423s to import
[I 2023-11-08 14:35:44.355 ServerApp] jupyter_lsp | extension was successfully linked.
[I 2023-11-08 14:35:44.360 ServerApp] jupyter_server_terminals | extension was successfully linked.
[I 2023-11-08 14:35:44.365 ServerApp] jupyterlab | extension was successfully linked.
[W 2023-11-08 14:35:44.367 JupyterNotebookApp] 'password' has moved from NotebookApp to ServerApp. This config will be passed to ServerApp. Be sure to update your config before our next release.
[W 2023-11-08 14:35:44.370 ServerApp] ServerApp.password config is deprecated in 2.0. Use PasswordIdentityProvider.hashed_password.
[I 2023-11-08 14:35:44.371 ServerApp] notebook | extension was successfully linked.
[I 2023-11-08 14:35:44.775 ServerApp] notebook_shim | extension was successfully linked.
[I 2023-11-08 14:35:44.775 ServerApp] panel.io.jupyter_server_extension | extension was successfully linked.
[I 2023-11-08 14:35:44.809 ServerApp] notebook_shim | extension was successfully loaded.
[I 2023-11-08 14:35:44.812 ServerApp] jupyter_lsp | extension was successfully loaded.
[I 2023-11-08 14:35:44.813 ServerApp] jupyter_server_terminals | extension was successfully loaded.
[I 2023-11-08 14:35:44.818 LabApp] JupyterLab extension loaded from /home1/datahome/mdemol/.miniconda3/envs/histenv2/lib/python3.9/site-packages/jupyterlab
[I 2023-11-08 14:35:44.818 LabApp] JupyterLab application directory is /home1/datahome/mdemol/.miniconda3/envs/histenv2/share/jupyter/lab
[I 2023-11-08 14:35:44.818 LabApp] Extension Manager is 'pypi'.
[I 2023-11-08 14:35:44.822 ServerApp] jupyterlab | extension was successfully loaded.
[I 2023-11-08 14:35:44.825 ServerApp] notebook | extension was successfully loaded.
[I 2023-11-08 14:35:44.826 ServerApp] panel.io.jupyter_server_extension | extension was successfully loaded.
[I 2023-11-08 14:35:44.826 ServerApp] Serving notebooks from local directory: /home1/datahome/mdemol
[I 2023-11-08 14:35:44.826 ServerApp] Jupyter Server 2.9.1 is running at:
[I 2023-11-08 14:35:44.827 ServerApp] http://r2i0n19:8877/lab
[I 2023-11-08 14:35:44.827 ServerApp]     http://127.0.0.1:8877/lab
[I 2023-11-08 14:35:44.827 ServerApp] Use Control-C to stop this server and shut down all kernels (twice to skip confirmation).
[I 2023-11-08 14:35:44.871 ServerApp] Skipped non-installed server(s): bash-language-server, dockerfile-language-server-nodejs, javascript-typescript-langserver, jedi-language-server, julia-language-server, pyright, python-language-server, python-lsp-server, r-languageserver, sql-language-server, texlab, typescript-language-server, unified-language-server, vscode-css-languageserver-bin, vscode-html-languageserver-bin, vscode-json-languageserver-bin, yaml-language-server
[W 2023-11-08 14:36:52.916 ServerApp] 404 GET /api/kernels/b102d20a-e925-46f9-bb34-75faea07eb71?1699454212837 (10.148.1.145): Kernel does not exist: b102d20a-e925-46f9-bb34-75faea07eb71
[W 2023-11-08 14:36:52.917 ServerApp] wrote error: 'Kernel does not exist: b102d20a-e925-46f9-bb34-75faea07eb71'
    Traceback (most recent call last):
      File "/home1/datahome/mdemol/.miniconda3/envs/histenv2/lib/python3.9/site-packages/tornado/web.py", line 1786, in _execute
        result = await result
      File "/home1/datahome/mdemol/.miniconda3/envs/histenv2/lib/python3.9/site-packages/jupyter_server/services/kernels/handlers.py", line 75, in get
        model = await ensure_async(km.kernel_model(kernel_id))
      File "/home1/datahome/mdemol/.miniconda3/envs/histenv2/lib/python3.9/site-packages/jupyter_server/services/kernels/kernelmanager.py", line 500, in kernel_model
        self._check_kernel_id(kernel_id)
      File "/home1/datahome/mdemol/.miniconda3/envs/histenv2/lib/python3.9/site-packages/jupyter_server/services/kernels/kernelmanager.py", line 531, in _check_kernel_id
        raise web.HTTPError(404, "Kernel does not exist: %s" % kernel_id)
    tornado.web.HTTPError: HTTP 404: Not Found (Kernel does not exist: b102d20a-e925-46f9-bb34-75faea07eb71)
[W 2023-11-08 14:36:52.934 ServerApp] 404 GET /api/kernels/b102d20a-e925-46f9-bb34-75faea07eb71?1699454212837 (fab7e86e3096494a86aeccede238bd42@10.148.1.145) 18.70ms referer=http://localhost:8877/lab/tree/historical_analysis/41_diag_overview.ipynb
[W 2023-11-08 14:36:53.836 ServerApp] 404 GET /api/kernels/b102d20a-e925-46f9-bb34-75faea07eb71/channels?session_id=4dfc2661-2e75-4963-a892-612c3841dfbe (10.148.1.145): Kernel does not exist: b102d20a-e925-46f9-bb34-75faea07eb71
[W 2023-11-08 14:36:53.869 ServerApp] 404 GET /api/kernels/b102d20a-e925-46f9-bb34-75faea07eb71/channels?session_id=4dfc2661-2e75-4963-a892-612c3841dfbe (fab7e86e3096494a86aeccede238bd42@10.148.1.145) 33.59ms referer=None
[W 2023-11-08 14:36:53.981 ServerApp] 404 GET /api/kernels/b102d20a-e925-46f9-bb34-75faea07eb71?1699454213904 (10.148.1.145): Kernel does not exist: b102d20a-e925-46f9-bb34-75faea07eb71
[W 2023-11-08 14:36:53.981 ServerApp] wrote error: 'Kernel does not exist: b102d20a-e925-46f9-bb34-75faea07eb71'
    Traceback (most recent call last):
      File "/home1/datahome/mdemol/.miniconda3/envs/histenv2/lib/python3.9/site-packages/tornado/web.py", line 1786, in _execute
        result = await result
      File "/home1/datahome/mdemol/.miniconda3/envs/histenv2/lib/python3.9/site-packages/jupyter_server/services/kernels/handlers.py", line 75, in get
        model = await ensure_async(km.kernel_model(kernel_id))
      File "/home1/datahome/mdemol/.miniconda3/envs/histenv2/lib/python3.9/site-packages/jupyter_server/services/kernels/kernelmanager.py", line 500, in kernel_model
        self._check_kernel_id(kernel_id)
      File "/home1/datahome/mdemol/.miniconda3/envs/histenv2/lib/python3.9/site-packages/jupyter_server/services/kernels/kernelmanager.py", line 531, in _check_kernel_id
        raise web.HTTPError(404, "Kernel does not exist: %s" % kernel_id)
    tornado.web.HTTPError: HTTP 404: Not Found (Kernel does not exist: b102d20a-e925-46f9-bb34-75faea07eb71)
[W 2023-11-08 14:36:53.982 ServerApp] 404 GET /api/kernels/b102d20a-e925-46f9-bb34-75faea07eb71?1699454213904 (fab7e86e3096494a86aeccede238bd42@10.148.1.145) 1.04ms referer=http://localhost:8877/lab/tree/historical_analysis/41_diag_overview.ipynb
[W 2023-11-08 14:36:54.751 ServerApp] 404 GET /api/kernels/7b1846f6-9399-4f4c-b130-763d008df46f?1699454214673 (10.148.1.145): Kernel does not exist: 7b1846f6-9399-4f4c-b130-763d008df46f
[W 2023-11-08 14:36:54.751 ServerApp] wrote error: 'Kernel does not exist: 7b1846f6-9399-4f4c-b130-763d008df46f'
    Traceback (most recent call last):
      File "/home1/datahome/mdemol/.miniconda3/envs/histenv2/lib/python3.9/site-packages/tornado/web.py", line 1786, in _execute
        result = await result
      File "/home1/datahome/mdemol/.miniconda3/envs/histenv2/lib/python3.9/site-packages/jupyter_server/services/kernels/handlers.py", line 75, in get
        model = await ensure_async(km.kernel_model(kernel_id))
      File "/home1/datahome/mdemol/.miniconda3/envs/histenv2/lib/python3.9/site-packages/jupyter_server/services/kernels/kernelmanager.py", line 500, in kernel_model
        self._check_kernel_id(kernel_id)
      File "/home1/datahome/mdemol/.miniconda3/envs/histenv2/lib/python3.9/site-packages/jupyter_server/services/kernels/kernelmanager.py", line 531, in _check_kernel_id
        raise web.HTTPError(404, "Kernel does not exist: %s" % kernel_id)
    tornado.web.HTTPError: HTTP 404: Not Found (Kernel does not exist: 7b1846f6-9399-4f4c-b130-763d008df46f)
[W 2023-11-08 14:36:54.752 ServerApp] 404 GET /api/kernels/7b1846f6-9399-4f4c-b130-763d008df46f?1699454214673 (fab7e86e3096494a86aeccede238bd42@10.148.1.145) 0.86ms referer=http://localhost:8877/lab/tree/historical_analysis/41_diag_overview.ipynb
[W 2023-11-08 14:36:55.551 ServerApp] 404 GET /api/kernels/7b1846f6-9399-4f4c-b130-763d008df46f/channels?session_id=94e72856-b32d-4243-98cf-1072fb889364 (10.148.1.145): Kernel does not exist: 7b1846f6-9399-4f4c-b130-763d008df46f
[W 2023-11-08 14:36:55.551 ServerApp] 404 GET /api/kernels/7b1846f6-9399-4f4c-b130-763d008df46f/channels?session_id=94e72856-b32d-4243-98cf-1072fb889364 (fab7e86e3096494a86aeccede238bd42@10.148.1.145) 0.94ms referer=None
[W 2023-11-08 14:36:55.618 ServerApp] 404 GET /api/kernels/7b1846f6-9399-4f4c-b130-763d008df46f?1699454215541 (10.148.1.145): Kernel does not exist: 7b1846f6-9399-4f4c-b130-763d008df46f
[W 2023-11-08 14:36:55.618 ServerApp] wrote error: 'Kernel does not exist: 7b1846f6-9399-4f4c-b130-763d008df46f'
    Traceback (most recent call last):
      File "/home1/datahome/mdemol/.miniconda3/envs/histenv2/lib/python3.9/site-packages/tornado/web.py", line 1786, in _execute
        result = await result
      File "/home1/datahome/mdemol/.miniconda3/envs/histenv2/lib/python3.9/site-packages/jupyter_server/services/kernels/handlers.py", line 75, in get
        model = await ensure_async(km.kernel_model(kernel_id))
      File "/home1/datahome/mdemol/.miniconda3/envs/histenv2/lib/python3.9/site-packages/jupyter_server/services/kernels/kernelmanager.py", line 500, in kernel_model
        self._check_kernel_id(kernel_id)
      File "/home1/datahome/mdemol/.miniconda3/envs/histenv2/lib/python3.9/site-packages/jupyter_server/services/kernels/kernelmanager.py", line 531, in _check_kernel_id
        raise web.HTTPError(404, "Kernel does not exist: %s" % kernel_id)
    tornado.web.HTTPError: HTTP 404: Not Found (Kernel does not exist: 7b1846f6-9399-4f4c-b130-763d008df46f)
[W 2023-11-08 14:36:55.619 ServerApp] 404 GET /api/kernels/7b1846f6-9399-4f4c-b130-763d008df46f?1699454215541 (fab7e86e3096494a86aeccede238bd42@10.148.1.145) 0.83ms referer=http://localhost:8877/lab/tree/historical_analysis/41_diag_overview.ipynb
[W 2023-11-08 14:36:56.656 ServerApp] 404 GET /api/kernels/b102d20a-e925-46f9-bb34-75faea07eb71/channels?session_id=4dfc2661-2e75-4963-a892-612c3841dfbe (10.148.1.145): Kernel does not exist: b102d20a-e925-46f9-bb34-75faea07eb71
[W 2023-11-08 14:36:56.657 ServerApp] 404 GET /api/kernels/b102d20a-e925-46f9-bb34-75faea07eb71/channels?session_id=4dfc2661-2e75-4963-a892-612c3841dfbe (fab7e86e3096494a86aeccede238bd42@10.148.1.145) 0.93ms referer=None
[W 2023-11-08 14:36:56.686 ServerApp] 404 GET /api/kernels/b102d20a-e925-46f9-bb34-75faea07eb71?1699454216607 (10.148.1.145): Kernel does not exist: b102d20a-e925-46f9-bb34-75faea07eb71
[W 2023-11-08 14:36:56.686 ServerApp] wrote error: 'Kernel does not exist: b102d20a-e925-46f9-bb34-75faea07eb71'
    Traceback (most recent call last):
      File "/home1/datahome/mdemol/.miniconda3/envs/histenv2/lib/python3.9/site-packages/tornado/web.py", line 1786, in _execute
        result = await result
      File "/home1/datahome/mdemol/.miniconda3/envs/histenv2/lib/python3.9/site-packages/jupyter_server/services/kernels/handlers.py", line 75, in get
        model = await ensure_async(km.kernel_model(kernel_id))
      File "/home1/datahome/mdemol/.miniconda3/envs/histenv2/lib/python3.9/site-packages/jupyter_server/services/kernels/kernelmanager.py", line 500, in kernel_model
        self._check_kernel_id(kernel_id)
      File "/home1/datahome/mdemol/.miniconda3/envs/histenv2/lib/python3.9/site-packages/jupyter_server/services/kernels/kernelmanager.py", line 531, in _check_kernel_id
        raise web.HTTPError(404, "Kernel does not exist: %s" % kernel_id)
    tornado.web.HTTPError: HTTP 404: Not Found (Kernel does not exist: b102d20a-e925-46f9-bb34-75faea07eb71)
[W 2023-11-08 14:36:56.686 ServerApp] 404 GET /api/kernels/b102d20a-e925-46f9-bb34-75faea07eb71?1699454216607 (fab7e86e3096494a86aeccede238bd42@10.148.1.145) 0.84ms referer=http://localhost:8877/lab/tree/historical_analysis/41_diag_overview.ipynb
[W 2023-11-08 14:36:57.583 ServerApp] 404 GET /api/kernels/7b1846f6-9399-4f4c-b130-763d008df46f/channels?session_id=94e72856-b32d-4243-98cf-1072fb889364 (10.148.1.145): Kernel does not exist: 7b1846f6-9399-4f4c-b130-763d008df46f
[W 2023-11-08 14:36:57.583 ServerApp] 404 GET /api/kernels/7b1846f6-9399-4f4c-b130-763d008df46f/channels?session_id=94e72856-b32d-4243-98cf-1072fb889364 (fab7e86e3096494a86aeccede238bd42@10.148.1.145) 0.93ms referer=None
[W 2023-11-08 14:36:57.673 ServerApp] 404 GET /api/kernels/7b1846f6-9399-4f4c-b130-763d008df46f?1699454217595 (10.148.1.145): Kernel does not exist: 7b1846f6-9399-4f4c-b130-763d008df46f
[W 2023-11-08 14:36:57.673 ServerApp] wrote error: 'Kernel does not exist: 7b1846f6-9399-4f4c-b130-763d008df46f'
    Traceback (most recent call last):
      File "/home1/datahome/mdemol/.miniconda3/envs/histenv2/lib/python3.9/site-packages/tornado/web.py", line 1786, in _execute
        result = await result
      File "/home1/datahome/mdemol/.miniconda3/envs/histenv2/lib/python3.9/site-packages/jupyter_server/services/kernels/handlers.py", line 75, in get
        model = await ensure_async(km.kernel_model(kernel_id))
      File "/home1/datahome/mdemol/.miniconda3/envs/histenv2/lib/python3.9/site-packages/jupyter_server/services/kernels/kernelmanager.py", line 500, in kernel_model
        self._check_kernel_id(kernel_id)
      File "/home1/datahome/mdemol/.miniconda3/envs/histenv2/lib/python3.9/site-packages/jupyter_server/services/kernels/kernelmanager.py", line 531, in _check_kernel_id
        raise web.HTTPError(404, "Kernel does not exist: %s" % kernel_id)
    tornado.web.HTTPError: HTTP 404: Not Found (Kernel does not exist: 7b1846f6-9399-4f4c-b130-763d008df46f)
[W 2023-11-08 14:36:57.673 ServerApp] 404 GET /api/kernels/7b1846f6-9399-4f4c-b130-763d008df46f?1699454217595 (fab7e86e3096494a86aeccede238bd42@10.148.1.145) 0.84ms referer=http://localhost:8877/lab/tree/historical_analysis/21_zarr_aviso.ipynb
[W 2023-11-08 14:36:57.911 ServerApp] 404 GET /api/kernels/b102d20a-e925-46f9-bb34-75faea07eb71/channels?session_id=4dfc2661-2e75-4963-a892-612c3841dfbe (10.148.1.145): Kernel does not exist: b102d20a-e925-46f9-bb34-75faea07eb71
[W 2023-11-08 14:36:57.912 ServerApp] 404 GET /api/kernels/b102d20a-e925-46f9-bb34-75faea07eb71/channels?session_id=4dfc2661-2e75-4963-a892-612c3841dfbe (fab7e86e3096494a86aeccede238bd42@10.148.1.145) 0.92ms referer=None
[W 2023-11-08 14:36:58.020 ServerApp] 404 GET /api/kernels/b102d20a-e925-46f9-bb34-75faea07eb71?1699454217937 (10.148.1.145): Kernel does not exist: b102d20a-e925-46f9-bb34-75faea07eb71
[W 2023-11-08 14:36:58.020 ServerApp] wrote error: 'Kernel does not exist: b102d20a-e925-46f9-bb34-75faea07eb71'
    Traceback (most recent call last):
      File "/home1/datahome/mdemol/.miniconda3/envs/histenv2/lib/python3.9/site-packages/tornado/web.py", line 1786, in _execute
        result = await result
      File "/home1/datahome/mdemol/.miniconda3/envs/histenv2/lib/python3.9/site-packages/jupyter_server/services/kernels/handlers.py", line 75, in get
        model = await ensure_async(km.kernel_model(kernel_id))
      File "/home1/datahome/mdemol/.miniconda3/envs/histenv2/lib/python3.9/site-packages/jupyter_server/services/kernels/kernelmanager.py", line 500, in kernel_model
        self._check_kernel_id(kernel_id)
      File "/home1/datahome/mdemol/.miniconda3/envs/histenv2/lib/python3.9/site-packages/jupyter_server/services/kernels/kernelmanager.py", line 531, in _check_kernel_id
        raise web.HTTPError(404, "Kernel does not exist: %s" % kernel_id)
    tornado.web.HTTPError: HTTP 404: Not Found (Kernel does not exist: b102d20a-e925-46f9-bb34-75faea07eb71)
[W 2023-11-08 14:36:58.021 ServerApp] 404 GET /api/kernels/b102d20a-e925-46f9-bb34-75faea07eb71?1699454217937 (fab7e86e3096494a86aeccede238bd42@10.148.1.145) 0.86ms referer=http://localhost:8877/lab/tree/historical_analysis/21_zarr_aviso.ipynb
[W 2023-11-08 14:37:02.077 ServerApp] 404 GET /api/kernels/b102d20a-e925-46f9-bb34-75faea07eb71/channels?session_id=4dfc2661-2e75-4963-a892-612c3841dfbe (10.148.1.145): Kernel does not exist: b102d20a-e925-46f9-bb34-75faea07eb71
[W 2023-11-08 14:37:02.078 ServerApp] 404 GET /api/kernels/b102d20a-e925-46f9-bb34-75faea07eb71/channels?session_id=4dfc2661-2e75-4963-a892-612c3841dfbe (fab7e86e3096494a86aeccede238bd42@10.148.1.145) 1.43ms referer=None
[W 2023-11-08 14:37:02.160 ServerApp] 404 GET /api/kernels/b102d20a-e925-46f9-bb34-75faea07eb71?1699454222080 (10.148.1.145): Kernel does not exist: b102d20a-e925-46f9-bb34-75faea07eb71
[W 2023-11-08 14:37:02.160 ServerApp] wrote error: 'Kernel does not exist: b102d20a-e925-46f9-bb34-75faea07eb71'
    Traceback (most recent call last):
      File "/home1/datahome/mdemol/.miniconda3/envs/histenv2/lib/python3.9/site-packages/tornado/web.py", line 1786, in _execute
        result = await result
      File "/home1/datahome/mdemol/.miniconda3/envs/histenv2/lib/python3.9/site-packages/jupyter_server/services/kernels/handlers.py", line 75, in get
        model = await ensure_async(km.kernel_model(kernel_id))
      File "/home1/datahome/mdemol/.miniconda3/envs/histenv2/lib/python3.9/site-packages/jupyter_server/services/kernels/kernelmanager.py", line 500, in kernel_model
        self._check_kernel_id(kernel_id)
      File "/home1/datahome/mdemol/.miniconda3/envs/histenv2/lib/python3.9/site-packages/jupyter_server/services/kernels/kernelmanager.py", line 531, in _check_kernel_id
        raise web.HTTPError(404, "Kernel does not exist: %s" % kernel_id)
    tornado.web.HTTPError: HTTP 404: Not Found (Kernel does not exist: b102d20a-e925-46f9-bb34-75faea07eb71)
[W 2023-11-08 14:37:02.161 ServerApp] 404 GET /api/kernels/b102d20a-e925-46f9-bb34-75faea07eb71?1699454222080 (fab7e86e3096494a86aeccede238bd42@10.148.1.145) 0.94ms referer=http://localhost:8877/lab/tree/historical_analysis/21_zarr_aviso.ipynb
[W 2023-11-08 14:37:04.070 ServerApp] 404 GET /api/kernels/7b1846f6-9399-4f4c-b130-763d008df46f/channels?session_id=94e72856-b32d-4243-98cf-1072fb889364 (10.148.1.145): Kernel does not exist: 7b1846f6-9399-4f4c-b130-763d008df46f
[W 2023-11-08 14:37:04.070 ServerApp] 404 GET /api/kernels/7b1846f6-9399-4f4c-b130-763d008df46f/channels?session_id=94e72856-b32d-4243-98cf-1072fb889364 (fab7e86e3096494a86aeccede238bd42@10.148.1.145) 0.99ms referer=None
[W 2023-11-08 14:37:04.143 ServerApp] 404 GET /api/kernels/7b1846f6-9399-4f4c-b130-763d008df46f?1699454224063 (10.148.1.145): Kernel does not exist: 7b1846f6-9399-4f4c-b130-763d008df46f
[W 2023-11-08 14:37:04.144 ServerApp] wrote error: 'Kernel does not exist: 7b1846f6-9399-4f4c-b130-763d008df46f'
    Traceback (most recent call last):
      File "/home1/datahome/mdemol/.miniconda3/envs/histenv2/lib/python3.9/site-packages/tornado/web.py", line 1786, in _execute
        result = await result
      File "/home1/datahome/mdemol/.miniconda3/envs/histenv2/lib/python3.9/site-packages/jupyter_server/services/kernels/handlers.py", line 75, in get
        model = await ensure_async(km.kernel_model(kernel_id))
      File "/home1/datahome/mdemol/.miniconda3/envs/histenv2/lib/python3.9/site-packages/jupyter_server/services/kernels/kernelmanager.py", line 500, in kernel_model
        self._check_kernel_id(kernel_id)
      File "/home1/datahome/mdemol/.miniconda3/envs/histenv2/lib/python3.9/site-packages/jupyter_server/services/kernels/kernelmanager.py", line 531, in _check_kernel_id
        raise web.HTTPError(404, "Kernel does not exist: %s" % kernel_id)
    tornado.web.HTTPError: HTTP 404: Not Found (Kernel does not exist: 7b1846f6-9399-4f4c-b130-763d008df46f)
[W 2023-11-08 14:37:04.144 ServerApp] 404 GET /api/kernels/7b1846f6-9399-4f4c-b130-763d008df46f?1699454224063 (fab7e86e3096494a86aeccede238bd42@10.148.1.145) 0.85ms referer=http://localhost:8877/lab/tree/historical_analysis/21_zarr_aviso.ipynb
[I 2023-11-08 14:37:42.167 ServerApp] Kernel started: 0c9943f3-3d6f-4638-9a45-412a87b2f67e
readline: /etc/inputrc: line 19: term: unknown variable name
[I 2023-11-08 14:37:43.092 ServerApp] Connecting to kernel 0c9943f3-3d6f-4638-9a45-412a87b2f67e.
[I 2023-11-08 14:38:23.360 ServerApp] Saving file at /historical_analysis/21_zarr_aviso.ipynb
[I 2023-11-08 14:40:23.720 ServerApp] Saving file at /historical_analysis/21_zarr_aviso.ipynb
[I 2023-11-08 14:41:19.088 ServerApp] Saving file at /historical_analysis/histlib/aviso.py
[I 2023-11-08 14:42:34.765 ServerApp] Saving file at /historical_analysis/histlib/aviso.py
[I 2023-11-08 14:43:20.940 ServerApp] Starting buffering for 0c9943f3-3d6f-4638-9a45-412a87b2f67e:b513167b-8ffc-4194-89ac-5052921628da
[W 2023-11-08 14:43:22.297 LabApp] Could not determine jupyterlab build status without nodejs
[I 2023-11-08 14:43:22.371 ServerApp] Connecting to kernel 0c9943f3-3d6f-4638-9a45-412a87b2f67e.
[I 2023-11-08 14:43:22.497 ServerApp] Starting buffering for 0c9943f3-3d6f-4638-9a45-412a87b2f67e:9ec6fc6b-b2f7-4b08-8784-37fceb9984ce
[E 2023-11-08 14:43:30.401 ServerApp] Uncaught exception GET /lab/api/settings?ids_only=true&1699454602661 (10.148.1.145)
    HTTPServerRequest(protocol='http', host='localhost:8877', method='GET', uri='/lab/api/settings?ids_only=true&1699454602661', version='HTTP/1.1', remote_ip='10.148.1.145')
    Traceback (most recent call last):
      File "/home1/datahome/mdemol/.miniconda3/envs/histenv2/lib/python3.9/site-packages/tornado/web.py", line 1786, in _execute
        result = await result
    tornado.iostream.StreamClosedError: Stream is closed
[W 2023-11-08 14:43:41.592 LabApp] Could not determine jupyterlab build status without nodejs
[I 2023-11-08 14:43:41.682 ServerApp] Connecting to kernel 0c9943f3-3d6f-4638-9a45-412a87b2f67e.
[I 2023-11-08 14:43:41.980 ServerApp] Starting buffering for 0c9943f3-3d6f-4638-9a45-412a87b2f67e:ad88d004-b58c-4608-b324-132cee31ad6c
[I 2023-11-08 14:43:43.881 ServerApp] Connecting to kernel 0c9943f3-3d6f-4638-9a45-412a87b2f67e.
[I 2023-11-08 14:43:43.938 ServerApp] Kernel started: eb780ec5-cfa5-4b7a-9f59-bd4370f51e8b
readline: /etc/inputrc: line 19: term: unknown variable name
[I 2023-11-08 14:43:50.553 ServerApp] Connecting to kernel eb780ec5-cfa5-4b7a-9f59-bd4370f51e8b.
[I 2023-11-08 14:44:52.296 ServerApp] Kernel started: b667e96e-306a-4540-9aab-98c57fd5da5c
readline: /etc/inputrc: line 19: term: unknown variable name
[I 2023-11-08 14:44:53.141 ServerApp] Connecting to kernel b667e96e-306a-4540-9aab-98c57fd5da5c.
[I 2023-11-08 14:45:43.055 ServerApp] Saving file at /historical_analysis/21_zarr_aviso.ipynb
[I 2023-11-08 14:45:43.813 ServerApp] Saving file at /historical_analysis/41_diag_overview.ipynb
[I 2023-11-08 14:47:43.507 ServerApp] Saving file at /historical_analysis/21_zarr_aviso.ipynb
[I 2023-11-08 14:52:25.987 ServerApp] Starting buffering for b667e96e-306a-4540-9aab-98c57fd5da5c:feb7b5b4-4859-42f8-808f-33191f4e11b8
[I 2023-11-08 14:52:25.988 ServerApp] Starting buffering for 0c9943f3-3d6f-4638-9a45-412a87b2f67e:a3aa58c0-2f40-4c74-9413-08359362902d
[I 2023-11-08 14:52:25.989 ServerApp] Starting buffering for eb780ec5-cfa5-4b7a-9f59-bd4370f51e8b:9c0039f5-d259-4832-92bc-1c8596f43b34
[W 2023-11-08 14:52:27.326 LabApp] Could not determine jupyterlab build status without nodejs
[I 2023-11-08 14:52:27.371 ServerApp] Connecting to kernel 0c9943f3-3d6f-4638-9a45-412a87b2f67e.
[I 2023-11-08 14:52:27.378 ServerApp] Connecting to kernel eb780ec5-cfa5-4b7a-9f59-bd4370f51e8b.
[I 2023-11-08 14:52:27.380 ServerApp] Connecting to kernel b667e96e-306a-4540-9aab-98c57fd5da5c.
[I 2023-11-08 14:52:27.471 ServerApp] Starting buffering for eb780ec5-cfa5-4b7a-9f59-bd4370f51e8b:f41867fb-14ed-43ec-8907-95613d7229fa
[I 2023-11-08 14:52:27.472 ServerApp] Starting buffering for b667e96e-306a-4540-9aab-98c57fd5da5c:1992c43b-83cd-48fc-84ed-a8cc09e1dea9
[I 2023-11-08 14:52:28.676 ServerApp] Connecting to kernel 0c9943f3-3d6f-4638-9a45-412a87b2f67e.
[I 2023-11-08 14:52:28.680 ServerApp] Connecting to kernel b667e96e-306a-4540-9aab-98c57fd5da5c.
[I 2023-11-08 14:52:28.683 ServerApp] Connecting to kernel eb780ec5-cfa5-4b7a-9f59-bd4370f51e8b.
[I 2023-11-08 14:52:31.523 ServerApp] Starting buffering for 0c9943f3-3d6f-4638-9a45-412a87b2f67e:fc7aa252-fb68-416d-9c17-47128dd4a7ea
[I 2023-11-08 14:52:31.524 ServerApp] Starting buffering for b667e96e-306a-4540-9aab-98c57fd5da5c:ad520eeb-ffbf-4af3-9bd4-c6d5f7a54c3d
[I 2023-11-08 14:52:31.524 ServerApp] Starting buffering for eb780ec5-cfa5-4b7a-9f59-bd4370f51e8b:c976ff99-b6e1-4b42-a8c8-1020a6d9cdb7
[W 2023-11-08 14:52:37.195 LabApp] Could not determine jupyterlab build status without nodejs
[I 2023-11-08 14:52:37.263 ServerApp] Connecting to kernel 0c9943f3-3d6f-4638-9a45-412a87b2f67e.
[I 2023-11-08 14:52:37.269 ServerApp] Connecting to kernel eb780ec5-cfa5-4b7a-9f59-bd4370f51e8b.
[I 2023-11-08 14:52:37.271 ServerApp] Connecting to kernel b667e96e-306a-4540-9aab-98c57fd5da5c.
[I 2023-11-08 14:52:37.372 ServerApp] Starting buffering for eb780ec5-cfa5-4b7a-9f59-bd4370f51e8b:caa995fd-06c1-4374-8ea1-cfe1a88c81cc
[I 2023-11-08 14:52:37.372 ServerApp] Starting buffering for b667e96e-306a-4540-9aab-98c57fd5da5c:8964daaf-6166-42ef-b0af-ce34a7b4da22
[I 2023-11-08 14:52:38.640 ServerApp] Connecting to kernel 0c9943f3-3d6f-4638-9a45-412a87b2f67e.
[I 2023-11-08 14:52:38.641 ServerApp] Connecting to kernel b667e96e-306a-4540-9aab-98c57fd5da5c.
[I 2023-11-08 14:52:38.644 ServerApp] Connecting to kernel eb780ec5-cfa5-4b7a-9f59-bd4370f51e8b.
[I 2023-11-08 14:56:37.943 ServerApp] Saving file at /historical_analysis/histlib/aviso.py
[I 2023-11-08 14:56:45.102 ServerApp] Saving file at /historical_analysis/histlib/aviso.py
[I 2023-11-08 14:57:17.802 ServerApp] Kernel interrupted: 0c9943f3-3d6f-4638-9a45-412a87b2f67e
[I 2023-11-08 14:57:18.108 ServerApp] Kernel interrupted: 0c9943f3-3d6f-4638-9a45-412a87b2f67e
[I 2023-11-08 14:57:18.346 ServerApp] Kernel interrupted: 0c9943f3-3d6f-4638-9a45-412a87b2f67e
[I 2023-11-08 14:57:18.598 ServerApp] Kernel interrupted: 0c9943f3-3d6f-4638-9a45-412a87b2f67e
[I 2023-11-08 14:57:18.794 ServerApp] Kernel interrupted: 0c9943f3-3d6f-4638-9a45-412a87b2f67e
[I 2023-11-08 14:57:18.936 ServerApp] Kernel interrupted: 0c9943f3-3d6f-4638-9a45-412a87b2f67e
[I 2023-11-08 14:57:21.664 ServerApp] Kernel interrupted: 0c9943f3-3d6f-4638-9a45-412a87b2f67e
[I 2023-11-08 14:57:21.901 ServerApp] Kernel interrupted: 0c9943f3-3d6f-4638-9a45-412a87b2f67e
[I 2023-11-08 14:57:22.040 ServerApp] Kernel interrupted: 0c9943f3-3d6f-4638-9a45-412a87b2f67e
[I 2023-11-08 14:57:30.516 ServerApp] Kernel interrupted: 0c9943f3-3d6f-4638-9a45-412a87b2f67e
[I 2023-11-08 14:57:30.741 ServerApp] Kernel interrupted: 0c9943f3-3d6f-4638-9a45-412a87b2f67e
[I 2023-11-08 14:57:30.965 ServerApp] Kernel interrupted: 0c9943f3-3d6f-4638-9a45-412a87b2f67e
[I 2023-11-08 14:58:21.817 ServerApp] Starting buffering for 0c9943f3-3d6f-4638-9a45-412a87b2f67e:c1ccf997-bcc0-4935-b9b6-22447358b8a7
[I 2023-11-08 14:58:21.818 ServerApp] Starting buffering for b667e96e-306a-4540-9aab-98c57fd5da5c:d175361b-2c2d-49c9-8db5-e187e6386bd8
[I 2023-11-08 14:58:21.818 ServerApp] Starting buffering for eb780ec5-cfa5-4b7a-9f59-bd4370f51e8b:dcd42874-6067-453c-a0f2-25ec0c79b0c1
[W 2023-11-08 14:58:27.011 LabApp] Could not determine jupyterlab build status without nodejs
[I 2023-11-08 14:58:27.069 ServerApp] Connecting to kernel 0c9943f3-3d6f-4638-9a45-412a87b2f67e.
[I 2023-11-08 14:58:27.077 ServerApp] Connecting to kernel eb780ec5-cfa5-4b7a-9f59-bd4370f51e8b.
[I 2023-11-08 14:58:27.079 ServerApp] Connecting to kernel b667e96e-306a-4540-9aab-98c57fd5da5c.
[I 2023-11-08 14:58:27.177 ServerApp] Starting buffering for 0c9943f3-3d6f-4638-9a45-412a87b2f67e:f3f2272d-513c-44a4-bf23-7a36cac835fe
[I 2023-11-08 14:58:27.177 ServerApp] Starting buffering for eb780ec5-cfa5-4b7a-9f59-bd4370f51e8b:d07a8cf4-b204-4051-8fbd-8cc256cec67c
[I 2023-11-08 14:58:27.177 ServerApp] Starting buffering for b667e96e-306a-4540-9aab-98c57fd5da5c:f6862dd4-a513-46e5-bb12-4cb169e5962b
[I 2023-11-08 14:58:29.066 ServerApp] Connecting to kernel 0c9943f3-3d6f-4638-9a45-412a87b2f67e.
[I 2023-11-08 14:58:29.069 ServerApp] Connecting to kernel b667e96e-306a-4540-9aab-98c57fd5da5c.
[I 2023-11-08 14:58:29.070 ServerApp] Connecting to kernel eb780ec5-cfa5-4b7a-9f59-bd4370f51e8b.
[I 2023-11-08 14:58:36.303 ServerApp] Kernel restarted: 0c9943f3-3d6f-4638-9a45-412a87b2f67e
[I 2023-11-08 14:58:36.310 ServerApp] Starting buffering for 0c9943f3-3d6f-4638-9a45-412a87b2f67e:38d7e5c6-58bf-475f-94d8-f285b9544f07
[I 2023-11-08 14:58:36.319 ServerApp] Connecting to kernel 0c9943f3-3d6f-4638-9a45-412a87b2f67e.
[I 2023-11-08 14:58:36.319 ServerApp] Restoring connection for 0c9943f3-3d6f-4638-9a45-412a87b2f67e:38d7e5c6-58bf-475f-94d8-f285b9544f07
readline: /etc/inputrc: line 19: term: unknown variable name
[I 2023-11-08 14:59:20.086 ServerApp] Saving file at /historical_analysis/histlib/aviso.py
[I 2023-11-08 14:59:26.387 ServerApp] Kernel restarted: 0c9943f3-3d6f-4638-9a45-412a87b2f67e
[I 2023-11-08 14:59:26.393 ServerApp] Starting buffering for 0c9943f3-3d6f-4638-9a45-412a87b2f67e:38d7e5c6-58bf-475f-94d8-f285b9544f07
[I 2023-11-08 14:59:26.402 ServerApp] Connecting to kernel 0c9943f3-3d6f-4638-9a45-412a87b2f67e.
[I 2023-11-08 14:59:26.402 ServerApp] Restoring connection for 0c9943f3-3d6f-4638-9a45-412a87b2f67e:38d7e5c6-58bf-475f-94d8-f285b9544f07
readline: /etc/inputrc: line 19: term: unknown variable name
[I 2023-11-08 15:00:28.462 ServerApp] Saving file at /historical_analysis/21_zarr_aviso.ipynb
[I 2023-11-08 15:02:28.697 ServerApp] Saving file at /historical_analysis/21_zarr_aviso.ipynb
[I 2023-11-08 15:04:12.243 ServerApp] Starting buffering for b667e96e-306a-4540-9aab-98c57fd5da5c:530d0b18-270d-4e22-b31f-d94e8cb0ea3e
[I 2023-11-08 15:04:12.244 ServerApp] Starting buffering for eb780ec5-cfa5-4b7a-9f59-bd4370f51e8b:de6c1ec1-048d-4903-b38b-7cd06fe009ed
[I 2023-11-08 15:04:12.245 ServerApp] Starting buffering for 0c9943f3-3d6f-4638-9a45-412a87b2f67e:38d7e5c6-58bf-475f-94d8-f285b9544f07
[W 2023-11-08 15:04:16.788 LabApp] Could not determine jupyterlab build status without nodejs
[I 2023-11-08 15:04:16.840 ServerApp] Connecting to kernel 0c9943f3-3d6f-4638-9a45-412a87b2f67e.
[I 2023-11-08 15:04:16.846 ServerApp] Connecting to kernel eb780ec5-cfa5-4b7a-9f59-bd4370f51e8b.
[I 2023-11-08 15:04:16.848 ServerApp] Connecting to kernel b667e96e-306a-4540-9aab-98c57fd5da5c.
[I 2023-11-08 15:04:16.940 ServerApp] Starting buffering for eb780ec5-cfa5-4b7a-9f59-bd4370f51e8b:8eb9c9cb-0d68-43f5-9d11-33fdac3bba79
[I 2023-11-08 15:04:16.944 ServerApp] Starting buffering for b667e96e-306a-4540-9aab-98c57fd5da5c:1eeb1b47-447e-4650-8759-18c4074f9de6
[I 2023-11-08 15:04:17.270 ServerApp] Starting buffering for 0c9943f3-3d6f-4638-9a45-412a87b2f67e:4cbbbd83-a221-4996-a8d8-bfefb473213e
[I 2023-11-08 15:04:18.387 ServerApp] Connecting to kernel b667e96e-306a-4540-9aab-98c57fd5da5c.
[I 2023-11-08 15:04:18.390 ServerApp] Connecting to kernel 0c9943f3-3d6f-4638-9a45-412a87b2f67e.
[I 2023-11-08 15:04:18.392 ServerApp] Connecting to kernel eb780ec5-cfa5-4b7a-9f59-bd4370f51e8b.
[I 2023-11-08 15:06:17.912 ServerApp] Saving file at /historical_analysis/21_zarr_aviso.ipynb
[I 2023-11-08 15:06:44.665 ServerApp] Starting buffering for b667e96e-306a-4540-9aab-98c57fd5da5c:7c0f5dcf-df79-44b8-8fb7-a5a6554083e5
[I 2023-11-08 15:06:47.833 ServerApp] Starting buffering for eb780ec5-cfa5-4b7a-9f59-bd4370f51e8b:71e8ada0-b7e9-47c7-af6d-bf7b0ebf4735
[W 2023-11-08 15:08:04.258 LabApp] Could not determine jupyterlab build status without nodejs
[I 2023-11-08 15:08:04.320 ServerApp] Connecting to kernel 0c9943f3-3d6f-4638-9a45-412a87b2f67e.
[I 2023-11-08 15:08:04.327 ServerApp] Connecting to kernel eb780ec5-cfa5-4b7a-9f59-bd4370f51e8b.
[I 2023-11-08 15:08:04.329 ServerApp] Connecting to kernel b667e96e-306a-4540-9aab-98c57fd5da5c.
[I 2023-11-08 15:08:04.444 ServerApp] Starting buffering for eb780ec5-cfa5-4b7a-9f59-bd4370f51e8b:4e1aa315-f246-4b26-9ef9-c880c0b540bf
[I 2023-11-08 15:08:04.444 ServerApp] Starting buffering for b667e96e-306a-4540-9aab-98c57fd5da5c:8f598038-03ba-42b2-8b1f-360a8de74bf0
[I 2023-11-08 15:18:41.683 ServerApp] Connecting to kernel 0c9943f3-3d6f-4638-9a45-412a87b2f67e.
[I 2023-11-08 15:24:07.479 ServerApp] Saving file at /historical_analysis/histlib/aviso.py
[I 2023-11-08 15:28:23.999 ServerApp] Starting buffering for 0c9943f3-3d6f-4638-9a45-412a87b2f67e:d5fbcbda-3ee4-4067-b687-ebedbaaef37b
[W 2023-11-08 15:28:25.516 LabApp] Could not determine jupyterlab build status without nodejs
[I 2023-11-08 15:28:25.580 ServerApp] Connecting to kernel 0c9943f3-3d6f-4638-9a45-412a87b2f67e.
[I 2023-11-08 15:28:25.586 ServerApp] Connecting to kernel eb780ec5-cfa5-4b7a-9f59-bd4370f51e8b.
[I 2023-11-08 15:28:25.588 ServerApp] Connecting to kernel b667e96e-306a-4540-9aab-98c57fd5da5c.
[I 2023-11-08 15:28:25.726 ServerApp] Starting buffering for eb780ec5-cfa5-4b7a-9f59-bd4370f51e8b:cb5cb9d9-8e5f-4115-bb35-45c4110a53ac
[I 2023-11-08 15:28:25.727 ServerApp] Starting buffering for b667e96e-306a-4540-9aab-98c57fd5da5c:b8ba5713-8b74-41b6-a671-0aea9f274fdc
[I 2023-11-08 15:28:25.727 ServerApp] Starting buffering for 0c9943f3-3d6f-4638-9a45-412a87b2f67e:c4d913e3-7ad6-4dea-9f8e-ebf63a4a28d2
[I 2023-11-08 15:28:26.881 ServerApp] Connecting to kernel 0c9943f3-3d6f-4638-9a45-412a87b2f67e.
[I 2023-11-08 15:28:31.759 ServerApp] Starting buffering for 0c9943f3-3d6f-4638-9a45-412a87b2f67e:0fcfb0f4-42f0-44a5-910a-494596c7a056
[W 2023-11-08 15:28:36.428 LabApp] Could not determine jupyterlab build status without nodejs
[I 2023-11-08 15:28:36.480 ServerApp] Connecting to kernel 0c9943f3-3d6f-4638-9a45-412a87b2f67e.
[I 2023-11-08 15:28:36.486 ServerApp] Connecting to kernel eb780ec5-cfa5-4b7a-9f59-bd4370f51e8b.
[I 2023-11-08 15:28:36.488 ServerApp] Connecting to kernel b667e96e-306a-4540-9aab-98c57fd5da5c.
[I 2023-11-08 15:28:36.573 ServerApp] Starting buffering for 0c9943f3-3d6f-4638-9a45-412a87b2f67e:7b864eee-b2a2-43c0-a743-104bb292abfb
[I 2023-11-08 15:28:36.573 ServerApp] Starting buffering for b667e96e-306a-4540-9aab-98c57fd5da5c:63b2c9ea-cbac-49a5-8d6e-1505764a53c4
[I 2023-11-08 15:28:36.578 ServerApp] Starting buffering for eb780ec5-cfa5-4b7a-9f59-bd4370f51e8b:5fff9005-420f-42b2-a852-b50b9d73c2f3
[I 2023-11-08 15:28:37.567 ServerApp] Connecting to kernel 0c9943f3-3d6f-4638-9a45-412a87b2f67e.
[I 2023-11-08 15:30:37.190 ServerApp] Saving file at /historical_analysis/21_zarr_aviso.ipynb
[I 2023-11-08 15:33:44.794 ServerApp] Kernel restarted: 0c9943f3-3d6f-4638-9a45-412a87b2f67e
[I 2023-11-08 15:33:44.799 ServerApp] Starting buffering for 0c9943f3-3d6f-4638-9a45-412a87b2f67e:077fc90c-2eae-4ae9-9b4b-786177c1939e
[I 2023-11-08 15:33:44.806 ServerApp] Connecting to kernel 0c9943f3-3d6f-4638-9a45-412a87b2f67e.
[I 2023-11-08 15:33:44.806 ServerApp] Restoring connection for 0c9943f3-3d6f-4638-9a45-412a87b2f67e:077fc90c-2eae-4ae9-9b4b-786177c1939e
readline: /etc/inputrc: line 19: term: unknown variable name
[I 2023-11-08 15:34:37.449 ServerApp] Saving file at /historical_analysis/21_zarr_aviso.ipynb
[I 2023-11-08 15:36:22.500 ServerApp] Starting buffering for 0c9943f3-3d6f-4638-9a45-412a87b2f67e:077fc90c-2eae-4ae9-9b4b-786177c1939e
[W 2023-11-08 15:36:26.314 LabApp] Could not determine jupyterlab build status without nodejs
[I 2023-11-08 15:36:26.368 ServerApp] Connecting to kernel 0c9943f3-3d6f-4638-9a45-412a87b2f67e.
[I 2023-11-08 15:36:26.373 ServerApp] Connecting to kernel eb780ec5-cfa5-4b7a-9f59-bd4370f51e8b.
[I 2023-11-08 15:36:26.375 ServerApp] Connecting to kernel b667e96e-306a-4540-9aab-98c57fd5da5c.
[I 2023-11-08 15:36:26.501 ServerApp] Starting buffering for eb780ec5-cfa5-4b7a-9f59-bd4370f51e8b:59e6a7cb-513a-4216-9d27-bc5156eec762
[I 2023-11-08 15:36:26.509 ServerApp] Starting buffering for b667e96e-306a-4540-9aab-98c57fd5da5c:2a0bd062-67e1-44c7-8253-55fbf18d4161
[I 2023-11-08 15:36:26.586 ServerApp] Starting buffering for 0c9943f3-3d6f-4638-9a45-412a87b2f67e:cc882e96-ed40-48d2-877f-297385bfd858
[I 2023-11-08 15:36:27.630 ServerApp] Connecting to kernel 0c9943f3-3d6f-4638-9a45-412a87b2f67e.
[I 2023-11-08 15:37:38.484 ServerApp] Starting buffering for 0c9943f3-3d6f-4638-9a45-412a87b2f67e:3af3fca7-e5e8-432f-9dfb-133baeee820e
[W 2023-11-08 15:37:42.159 LabApp] Could not determine jupyterlab build status without nodejs
[I 2023-11-08 15:37:42.218 ServerApp] Connecting to kernel 0c9943f3-3d6f-4638-9a45-412a87b2f67e.
[I 2023-11-08 15:37:42.226 ServerApp] Connecting to kernel eb780ec5-cfa5-4b7a-9f59-bd4370f51e8b.
[I 2023-11-08 15:37:42.228 ServerApp] Connecting to kernel b667e96e-306a-4540-9aab-98c57fd5da5c.
[I 2023-11-08 15:37:42.372 ServerApp] Starting buffering for eb780ec5-cfa5-4b7a-9f59-bd4370f51e8b:baad12b6-9e08-4f3c-bc3b-910034f7d547
[I 2023-11-08 15:37:42.373 ServerApp] Starting buffering for b667e96e-306a-4540-9aab-98c57fd5da5c:4fd79aef-4059-4b0f-86f3-478d9a132d71
[I 2023-11-08 15:37:42.461 ServerApp] Starting buffering for 0c9943f3-3d6f-4638-9a45-412a87b2f67e:55f0b87d-01b7-42a8-9617-f194e22d7ce3
[I 2023-11-08 15:37:43.534 ServerApp] Connecting to kernel 0c9943f3-3d6f-4638-9a45-412a87b2f67e.
[I 2023-11-08 15:39:01.971 ServerApp] Kernel restarted: 0c9943f3-3d6f-4638-9a45-412a87b2f67e
[I 2023-11-08 15:39:01.978 ServerApp] Starting buffering for 0c9943f3-3d6f-4638-9a45-412a87b2f67e:be952528-83d7-44ad-b855-2ba9ee060811
[I 2023-11-08 15:39:01.988 ServerApp] Connecting to kernel 0c9943f3-3d6f-4638-9a45-412a87b2f67e.
[I 2023-11-08 15:39:01.988 ServerApp] Restoring connection for 0c9943f3-3d6f-4638-9a45-412a87b2f67e:be952528-83d7-44ad-b855-2ba9ee060811
readline: /etc/inputrc: line 19: term: unknown variable name
[I 2023-11-08 15:39:43.135 ServerApp] Saving file at /historical_analysis/21_zarr_aviso.ipynb
[I 2023-11-08 15:40:24.738 ServerApp] Starting buffering for 0c9943f3-3d6f-4638-9a45-412a87b2f67e:be952528-83d7-44ad-b855-2ba9ee060811
[W 2023-11-08 15:40:29.390 LabApp] Could not determine jupyterlab build status without nodejs
[I 2023-11-08 15:40:29.435 ServerApp] Connecting to kernel 0c9943f3-3d6f-4638-9a45-412a87b2f67e.
[I 2023-11-08 15:40:29.444 ServerApp] Connecting to kernel eb780ec5-cfa5-4b7a-9f59-bd4370f51e8b.
[I 2023-11-08 15:40:29.446 ServerApp] Connecting to kernel b667e96e-306a-4540-9aab-98c57fd5da5c.
[I 2023-11-08 15:40:29.568 ServerApp] Starting buffering for b667e96e-306a-4540-9aab-98c57fd5da5c:2b3cccf0-a6a9-4cbf-bdff-c840f543520c
[I 2023-11-08 15:40:29.568 ServerApp] Starting buffering for eb780ec5-cfa5-4b7a-9f59-bd4370f51e8b:df22ffad-b8ca-4e3b-a7af-44b73b24b58c
[I 2023-11-08 15:40:29.572 ServerApp] Starting buffering for 0c9943f3-3d6f-4638-9a45-412a87b2f67e:575d6e0b-91dd-44c9-9723-a12541aace39
[I 2023-11-08 15:40:30.460 ServerApp] Connecting to kernel 0c9943f3-3d6f-4638-9a45-412a87b2f67e.
[I 2023-11-08 15:40:54.642 ServerApp] Connecting to kernel eb780ec5-cfa5-4b7a-9f59-bd4370f51e8b.
[I 2023-11-08 15:42:30.329 ServerApp] Saving file at /historical_analysis/21_zarr_aviso.ipynb
[I 2023-11-08 15:44:30.608 ServerApp] Saving file at /historical_analysis/21_zarr_aviso.ipynb
[I 2023-11-08 15:56:31.337 ServerApp] Saving file at /historical_analysis/21_zarr_aviso.ipynb
[I 2023-11-08 15:58:03.081 ServerApp] Starting buffering for eb780ec5-cfa5-4b7a-9f59-bd4370f51e8b:e7078a33-078e-4828-9567-8e0ad4539d50
[I 2023-11-08 15:58:03.082 ServerApp] Starting buffering for 0c9943f3-3d6f-4638-9a45-412a87b2f67e:2f343c2c-279e-417e-bb66-721583f9d2a4
[W 2023-11-08 15:58:04.561 LabApp] Could not determine jupyterlab build status without nodejs
[I 2023-11-08 15:58:04.628 ServerApp] Connecting to kernel 0c9943f3-3d6f-4638-9a45-412a87b2f67e.
[I 2023-11-08 15:58:04.636 ServerApp] Connecting to kernel eb780ec5-cfa5-4b7a-9f59-bd4370f51e8b.
[I 2023-11-08 15:58:04.639 ServerApp] Connecting to kernel b667e96e-306a-4540-9aab-98c57fd5da5c.
[I 2023-11-08 15:58:04.822 ServerApp] Starting buffering for 0c9943f3-3d6f-4638-9a45-412a87b2f67e:b5bf7ece-c165-4b96-a606-f3cc561b15e8
[I 2023-11-08 15:58:04.823 ServerApp] Starting buffering for eb780ec5-cfa5-4b7a-9f59-bd4370f51e8b:dfc270f9-3bd7-43da-ab31-7857a4cc88be
[I 2023-11-08 15:58:04.823 ServerApp] Starting buffering for b667e96e-306a-4540-9aab-98c57fd5da5c:d1a4d9bc-3a29-402c-8812-5fa294bf3333
[I 2023-11-08 15:58:06.153 ServerApp] Connecting to kernel 0c9943f3-3d6f-4638-9a45-412a87b2f67e.
[I 2023-11-08 15:58:06.155 ServerApp] Connecting to kernel eb780ec5-cfa5-4b7a-9f59-bd4370f51e8b.
[I 2023-11-08 15:58:15.429 ServerApp] Starting buffering for 0c9943f3-3d6f-4638-9a45-412a87b2f67e:5d1b959c-14e4-430d-9100-b1002bf75ff4
[I 2023-11-08 15:58:15.430 ServerApp] Starting buffering for eb780ec5-cfa5-4b7a-9f59-bd4370f51e8b:6c4b545b-c046-4ffe-b9cf-2feca5d78ac1
[W 2023-11-08 15:58:17.964 LabApp] Could not determine jupyterlab build status without nodejs
[I 2023-11-08 15:58:18.011 ServerApp] Connecting to kernel 0c9943f3-3d6f-4638-9a45-412a87b2f67e.
[I 2023-11-08 15:58:18.019 ServerApp] Connecting to kernel eb780ec5-cfa5-4b7a-9f59-bd4370f51e8b.
[I 2023-11-08 15:58:18.022 ServerApp] Connecting to kernel b667e96e-306a-4540-9aab-98c57fd5da5c.
[I 2023-11-08 15:58:18.109 ServerApp] Starting buffering for 0c9943f3-3d6f-4638-9a45-412a87b2f67e:0d591d19-74ee-4eb3-9746-6fb9366f2526
[I 2023-11-08 15:58:18.110 ServerApp] Starting buffering for eb780ec5-cfa5-4b7a-9f59-bd4370f51e8b:38e6af29-ea51-4699-8c70-db0683ec40a0
[I 2023-11-08 15:58:18.116 ServerApp] Starting buffering for b667e96e-306a-4540-9aab-98c57fd5da5c:93720142-e147-408c-b79e-961712e61ec1
[I 2023-11-08 15:58:19.689 ServerApp] Connecting to kernel 0c9943f3-3d6f-4638-9a45-412a87b2f67e.
[I 2023-11-08 15:58:19.691 ServerApp] Connecting to kernel eb780ec5-cfa5-4b7a-9f59-bd4370f51e8b.
[I 2023-11-08 16:00:19.160 ServerApp] Saving file at /historical_analysis/21_zarr_aviso.ipynb
[I 2023-11-08 16:00:53.296 ServerApp] Kernel interrupted: 0c9943f3-3d6f-4638-9a45-412a87b2f67e
[I 2023-11-08 16:00:53.564 ServerApp] Kernel interrupted: 0c9943f3-3d6f-4638-9a45-412a87b2f67e
[I 2023-11-08 16:02:19.448 ServerApp] Saving file at /historical_analysis/21_zarr_aviso.ipynb
[I 2023-11-08 16:04:19.794 ServerApp] Saving file at /historical_analysis/21_zarr_aviso.ipynb
[I 2023-11-08 16:06:20.071 ServerApp] Saving file at /historical_analysis/21_zarr_aviso.ipynb
[I 2023-11-08 16:08:20.398 ServerApp] Saving file at /historical_analysis/21_zarr_aviso.ipynb
[I 2023-11-08 16:08:54.442 ServerApp] Kernel restarted: 0c9943f3-3d6f-4638-9a45-412a87b2f67e
[I 2023-11-08 16:08:54.449 ServerApp] Starting buffering for 0c9943f3-3d6f-4638-9a45-412a87b2f67e:97f72f23-a1ab-4804-b973-d5a064af9a2c
[I 2023-11-08 16:08:54.458 ServerApp] Connecting to kernel 0c9943f3-3d6f-4638-9a45-412a87b2f67e.
[I 2023-11-08 16:08:54.458 ServerApp] Restoring connection for 0c9943f3-3d6f-4638-9a45-412a87b2f67e:97f72f23-a1ab-4804-b973-d5a064af9a2c
readline: /etc/inputrc: line 19: term: unknown variable name
[I 2023-11-08 16:10:20.690 ServerApp] Saving file at /historical_analysis/21_zarr_aviso.ipynb
[I 2023-11-08 16:12:20.988 ServerApp] Saving file at /historical_analysis/21_zarr_aviso.ipynb
[I 2023-11-08 16:13:40.859 ServerApp] Kernel interrupted: 0c9943f3-3d6f-4638-9a45-412a87b2f67e
[I 2023-11-08 16:13:41.063 ServerApp] Kernel interrupted: 0c9943f3-3d6f-4638-9a45-412a87b2f67e
[I 2023-11-08 16:13:41.277 ServerApp] Kernel interrupted: 0c9943f3-3d6f-4638-9a45-412a87b2f67e
[I 2023-11-08 16:14:18.533 ServerApp] Saving file at /historical_analysis/histlib/aviso.py
[I 2023-11-08 16:14:21.458 ServerApp] Saving file at /historical_analysis/21_zarr_aviso.ipynb
[I 2023-11-08 16:16:18.552 ServerApp] Saving file at /historical_analysis/histlib/aviso.py
[I 2023-11-08 16:16:35.192 ServerApp] Saving file at /historical_analysis/histlib/aviso.py
[I 2023-11-08 16:16:48.264 ServerApp] Kernel restarted: 0c9943f3-3d6f-4638-9a45-412a87b2f67e
[I 2023-11-08 16:16:48.269 ServerApp] Starting buffering for 0c9943f3-3d6f-4638-9a45-412a87b2f67e:97f72f23-a1ab-4804-b973-d5a064af9a2c
[I 2023-11-08 16:16:48.277 ServerApp] Connecting to kernel 0c9943f3-3d6f-4638-9a45-412a87b2f67e.
[I 2023-11-08 16:16:48.277 ServerApp] Restoring connection for 0c9943f3-3d6f-4638-9a45-412a87b2f67e:97f72f23-a1ab-4804-b973-d5a064af9a2c
readline: /etc/inputrc: line 19: term: unknown variable name
[I 2023-11-08 16:17:50.840 ServerApp] Saving file at /historical_analysis/histlib/aviso.py
/home1/datahome/mdemol/.miniconda3/envs/histenv2/lib/python3.9/site-packages/dask/config.py:742: FutureWarning: Dask configuration key 'distributed.scheduler.transition-log-length' has been deprecated; please use 'distributed.admin.low-level-log-length' instead
  warnings.warn(
/home1/datahome/mdemol/.miniconda3/envs/histenv2/lib/python3.9/site-packages/dask/config.py:742: FutureWarning: Dask configuration key 'distributed.comm.recent-messages-log-length' has been deprecated; please use 'distributed.admin.low-level-log-length' instead
  warnings.warn(
/home1/datahome/mdemol/.miniconda3/envs/histenv2/lib/python3.9/site-packages/dask/config.py:742: FutureWarning: Dask configuration key 'distributed.scheduler.transition-log-length' has been deprecated; please use 'distributed.admin.low-level-log-length' instead
  warnings.warn(
/home1/datahome/mdemol/.miniconda3/envs/histenv2/lib/python3.9/site-packages/dask/config.py:742: FutureWarning: Dask configuration key 'distributed.comm.recent-messages-log-length' has been deprecated; please use 'distributed.admin.low-level-log-length' instead
  warnings.warn(
/home1/datahome/mdemol/.miniconda3/envs/histenv2/lib/python3.9/site-packages/dask/config.py:742: FutureWarning: Dask configuration key 'distributed.scheduler.transition-log-length' has been deprecated; please use 'distributed.admin.low-level-log-length' instead
  warnings.warn(
/home1/datahome/mdemol/.miniconda3/envs/histenv2/lib/python3.9/site-packages/dask/config.py:742: FutureWarning: Dask configuration key 'distributed.scheduler.transition-log-length' has been deprecated; please use 'distributed.admin.low-level-log-length' instead
  warnings.warn(
/home1/datahome/mdemol/.miniconda3/envs/histenv2/lib/python3.9/site-packages/dask/config.py:742: FutureWarning: Dask configuration key 'distributed.comm.recent-messages-log-length' has been deprecated; please use 'distributed.admin.low-level-log-length' instead
  warnings.warn(
/home1/datahome/mdemol/.miniconda3/envs/histenv2/lib/python3.9/site-packages/dask/config.py:742: FutureWarning: Dask configuration key 'distributed.comm.recent-messages-log-length' has been deprecated; please use 'distributed.admin.low-level-log-length' instead
  warnings.warn(
/home1/datahome/mdemol/.miniconda3/envs/histenv2/lib/python3.9/site-packages/dask/config.py:742: FutureWarning: Dask configuration key 'distributed.scheduler.transition-log-length' has been deprecated; please use 'distributed.admin.low-level-log-length' instead
  warnings.warn(
/home1/datahome/mdemol/.miniconda3/envs/histenv2/lib/python3.9/site-packages/dask/config.py:742: FutureWarning: Dask configuration key 'distributed.comm.recent-messages-log-length' has been deprecated; please use 'distributed.admin.low-level-log-length' instead
  warnings.warn(
/home1/datahome/mdemol/.miniconda3/envs/histenv2/lib/python3.9/site-packages/dask/config.py:742: FutureWarning: Dask configuration key 'distributed.scheduler.transition-log-length' has been deprecated; please use 'distributed.admin.low-level-log-length' instead
  warnings.warn(
/home1/datahome/mdemol/.miniconda3/envs/histenv2/lib/python3.9/site-packages/dask/config.py:742: FutureWarning: Dask configuration key 'distributed.scheduler.transition-log-length' has been deprecated; please use 'distributed.admin.low-level-log-length' instead
  warnings.warn(
/home1/datahome/mdemol/.miniconda3/envs/histenv2/lib/python3.9/site-packages/dask/config.py:742: FutureWarning: Dask configuration key 'distributed.comm.recent-messages-log-length' has been deprecated; please use 'distributed.admin.low-level-log-length' instead
  warnings.warn(
/home1/datahome/mdemol/.miniconda3/envs/histenv2/lib/python3.9/site-packages/dask/config.py:742: FutureWarning: Dask configuration key 'distributed.comm.recent-messages-log-length' has been deprecated; please use 'distributed.admin.low-level-log-length' instead
  warnings.warn(
/home1/datahome/mdemol/.miniconda3/envs/histenv2/lib/python3.9/site-packages/dask/config.py:742: FutureWarning: Dask configuration key 'distributed.scheduler.transition-log-length' has been deprecated; please use 'distributed.admin.low-level-log-length' instead
  warnings.warn(
/home1/datahome/mdemol/.miniconda3/envs/histenv2/lib/python3.9/site-packages/dask/config.py:742: FutureWarning: Dask configuration key 'distributed.comm.recent-messages-log-length' has been deprecated; please use 'distributed.admin.low-level-log-length' instead
  warnings.warn(
/home1/datahome/mdemol/.miniconda3/envs/histenv2/lib/python3.9/site-packages/dask/config.py:742: FutureWarning: Dask configuration key 'distributed.scheduler.transition-log-length' has been deprecated; please use 'distributed.admin.low-level-log-length' instead
  warnings.warn(
/home1/datahome/mdemol/.miniconda3/envs/histenv2/lib/python3.9/site-packages/dask/config.py:742: FutureWarning: Dask configuration key 'distributed.comm.recent-messages-log-length' has been deprecated; please use 'distributed.admin.low-level-log-length' instead
  warnings.warn(
[I 2023-11-08 16:18:21.787 ServerApp] Saving file at /historical_analysis/21_zarr_aviso.ipynb
[W 2023-11-08 16:18:22.937 ServerApp] /home1/datahome/mdemol/historical_analysis/.~21_zarr_aviso.ipynb doesn't exist
/home1/datahome/mdemol/.miniconda3/envs/histenv2/lib/python3.9/site-packages/xarray/coding/times.py:228: RuntimeWarning: invalid value encountered in cast
  flat_num_dates_ns_int = (flat_num_dates * _NS_PER_TIME_DELTA[delta]).astype(
/home1/datahome/mdemol/.miniconda3/envs/histenv2/lib/python3.9/site-packages/xarray/coding/times.py:228: RuntimeWarning: invalid value encountered in cast
  flat_num_dates_ns_int = (flat_num_dates * _NS_PER_TIME_DELTA[delta]).astype(
/home1/datahome/mdemol/.miniconda3/envs/histenv2/lib/python3.9/site-packages/xarray/coding/times.py:228: RuntimeWarning: invalid value encountered in cast
  flat_num_dates_ns_int = (flat_num_dates * _NS_PER_TIME_DELTA[delta]).astype(
/home1/datahome/mdemol/.miniconda3/envs/histenv2/lib/python3.9/site-packages/xarray/coding/times.py:228: RuntimeWarning: invalid value encountered in cast
  flat_num_dates_ns_int = (flat_num_dates * _NS_PER_TIME_DELTA[delta]).astype(
/home1/datahome/mdemol/.miniconda3/envs/histenv2/lib/python3.9/site-packages/xarray/coding/times.py:228: RuntimeWarning: invalid value encountered in cast
  flat_num_dates_ns_int = (flat_num_dates * _NS_PER_TIME_DELTA[delta]).astype(
/home1/datahome/mdemol/.miniconda3/envs/histenv2/lib/python3.9/site-packages/xarray/coding/times.py:228: RuntimeWarning: invalid value encountered in cast
  flat_num_dates_ns_int = (flat_num_dates * _NS_PER_TIME_DELTA[delta]).astype(
/home1/datahome/mdemol/.miniconda3/envs/histenv2/lib/python3.9/site-packages/xarray/coding/times.py:228: RuntimeWarning: invalid value encountered in cast
  flat_num_dates_ns_int = (flat_num_dates * _NS_PER_TIME_DELTA[delta]).astype(
/home1/datahome/mdemol/.miniconda3/envs/histenv2/lib/python3.9/site-packages/xarray/coding/times.py:228: RuntimeWarning: invalid value encountered in cast
  flat_num_dates_ns_int = (flat_num_dates * _NS_PER_TIME_DELTA[delta]).astype(
/home1/datahome/mdemol/.miniconda3/envs/histenv2/lib/python3.9/site-packages/xarray/coding/times.py:228: RuntimeWarning: invalid value encountered in cast
  flat_num_dates_ns_int = (flat_num_dates * _NS_PER_TIME_DELTA[delta]).astype(
/home1/datahome/mdemol/.miniconda3/envs/histenv2/lib/python3.9/site-packages/xarray/coding/times.py:228: RuntimeWarning: invalid value encountered in cast
  flat_num_dates_ns_int = (flat_num_dates * _NS_PER_TIME_DELTA[delta]).astype(
/home1/datahome/mdemol/.miniconda3/envs/histenv2/lib/python3.9/site-packages/xarray/coding/times.py:228: RuntimeWarning: invalid value encountered in cast
  flat_num_dates_ns_int = (flat_num_dates * _NS_PER_TIME_DELTA[delta]).astype(
/home1/datahome/mdemol/.miniconda3/envs/histenv2/lib/python3.9/site-packages/xarray/coding/times.py:228: RuntimeWarning: invalid value encountered in cast
  flat_num_dates_ns_int = (flat_num_dates * _NS_PER_TIME_DELTA[delta]).astype(
/home1/datahome/mdemol/.miniconda3/envs/histenv2/lib/python3.9/site-packages/xarray/coding/times.py:228: RuntimeWarning: invalid value encountered in cast
  flat_num_dates_ns_int = (flat_num_dates * _NS_PER_TIME_DELTA[delta]).astype(
/home1/datahome/mdemol/.miniconda3/envs/histenv2/lib/python3.9/site-packages/xarray/coding/times.py:228: RuntimeWarning: invalid value encountered in cast
  flat_num_dates_ns_int = (flat_num_dates * _NS_PER_TIME_DELTA[delta]).astype(
/home1/datahome/mdemol/.miniconda3/envs/histenv2/lib/python3.9/site-packages/xarray/coding/times.py:228: RuntimeWarning: invalid value encountered in cast
  flat_num_dates_ns_int = (flat_num_dates * _NS_PER_TIME_DELTA[delta]).astype(
/home1/datahome/mdemol/.miniconda3/envs/histenv2/lib/python3.9/site-packages/xarray/coding/times.py:228: RuntimeWarning: invalid value encountered in cast
  flat_num_dates_ns_int = (flat_num_dates * _NS_PER_TIME_DELTA[delta]).astype(
/home1/datahome/mdemol/.miniconda3/envs/histenv2/lib/python3.9/site-packages/xarray/coding/times.py:228: RuntimeWarning: invalid value encountered in cast
  flat_num_dates_ns_int = (flat_num_dates * _NS_PER_TIME_DELTA[delta]).astype(
/home1/datahome/mdemol/.miniconda3/envs/histenv2/lib/python3.9/site-packages/xarray/coding/times.py:228: RuntimeWarning: invalid value encountered in cast
  flat_num_dates_ns_int = (flat_num_dates * _NS_PER_TIME_DELTA[delta]).astype(
/home1/datahome/mdemol/.miniconda3/envs/histenv2/lib/python3.9/site-packages/xarray/coding/times.py:228: RuntimeWarning: invalid value encountered in cast
  flat_num_dates_ns_int = (flat_num_dates * _NS_PER_TIME_DELTA[delta]).astype(
[I 2023-11-08 16:19:07.659 ServerApp] Kernel interrupted: 0c9943f3-3d6f-4638-9a45-412a87b2f67e
[I 2023-11-08 16:19:07.847 ServerApp] Kernel interrupted: 0c9943f3-3d6f-4638-9a45-412a87b2f67e
distributed.nanny - ERROR - Worker process died unexpectedly
distributed.nanny - ERROR - Worker process died unexpectedly
distributed.nanny - ERROR - Worker process died unexpectedly
Process Dask Worker process (from Nanny):
Process Dask Worker process (from Nanny):
Process Dask Worker process (from Nanny):
Process Dask Worker process (from Nanny):
distributed.nanny - ERROR - Worker process died unexpectedly
distributed.nanny - ERROR - Worker process died unexpectedly
distributed.nanny - ERROR - Worker process died unexpectedly
distributed.nanny - ERROR - Worker process died unexpectedly
Process Dask Worker process (from Nanny):
Process Dask Worker process (from Nanny):
Process Dask Worker process (from Nanny):
distributed.nanny - ERROR - Worker process died unexpectedly
Process Dask Worker process (from Nanny):
Traceback (most recent call last):
Traceback (most recent call last):
  File "/home1/datahome/mdemol/.miniconda3/envs/histenv2/lib/python3.9/site-packages/distributed/compatibility.py", line 236, in asyncio_run
    return loop.run_until_complete(main)
  File "/home1/datahome/mdemol/.miniconda3/envs/histenv2/lib/python3.9/asyncio/base_events.py", line 634, in run_until_complete
    self.run_forever()
  File "/home1/datahome/mdemol/.miniconda3/envs/histenv2/lib/python3.9/asyncio/base_events.py", line 601, in run_forever
    self._run_once()
  File "/home1/datahome/mdemol/.miniconda3/envs/histenv2/lib/python3.9/asyncio/base_events.py", line 1869, in _run_once
    event_list = self._selector.select(timeout)
  File "/home1/datahome/mdemol/.miniconda3/envs/histenv2/lib/python3.9/selectors.py", line 469, in select
    fd_event_list = self._selector.poll(timeout, max_ev)
  File "/home1/datahome/mdemol/.miniconda3/envs/histenv2/lib/python3.9/site-packages/distributed/compatibility.py", line 236, in asyncio_run
    return loop.run_until_complete(main)
  File "/home1/datahome/mdemol/.miniconda3/envs/histenv2/lib/python3.9/asyncio/base_events.py", line 634, in run_until_complete
    self.run_forever()
Traceback (most recent call last):
KeyboardInterrupt
  File "/home1/datahome/mdemol/.miniconda3/envs/histenv2/lib/python3.9/asyncio/base_events.py", line 601, in run_forever
    self._run_once()
  File "/home1/datahome/mdemol/.miniconda3/envs/histenv2/lib/python3.9/asyncio/base_events.py", line 1869, in _run_once
    event_list = self._selector.select(timeout)
  File "/home1/datahome/mdemol/.miniconda3/envs/histenv2/lib/python3.9/selectors.py", line 469, in select
    fd_event_list = self._selector.poll(timeout, max_ev)
Traceback (most recent call last):

During handling of the above exception, another exception occurred:

Traceback (most recent call last):
Traceback (most recent call last):
KeyboardInterrupt
Traceback (most recent call last):

During handling of the above exception, another exception occurred:

  File "/home1/datahome/mdemol/.miniconda3/envs/histenv2/lib/python3.9/site-packages/distributed/compatibility.py", line 236, in asyncio_run
    return loop.run_until_complete(main)
  File "/home1/datahome/mdemol/.miniconda3/envs/histenv2/lib/python3.9/asyncio/base_events.py", line 634, in run_until_complete
    self.run_forever()
Traceback (most recent call last):
  File "/home1/datahome/mdemol/.miniconda3/envs/histenv2/lib/python3.9/site-packages/distributed/compatibility.py", line 236, in asyncio_run
    return loop.run_until_complete(main)
  File "/home1/datahome/mdemol/.miniconda3/envs/histenv2/lib/python3.9/asyncio/base_events.py", line 601, in run_forever
    self._run_once()
  File "/home1/datahome/mdemol/.miniconda3/envs/histenv2/lib/python3.9/site-packages/distributed/compatibility.py", line 236, in asyncio_run
    return loop.run_until_complete(main)
  File "/home1/datahome/mdemol/.miniconda3/envs/histenv2/lib/python3.9/multiprocessing/process.py", line 315, in _bootstrap
    self.run()
  File "/home1/datahome/mdemol/.miniconda3/envs/histenv2/lib/python3.9/asyncio/base_events.py", line 634, in run_until_complete
    self.run_forever()
  File "/home1/datahome/mdemol/.miniconda3/envs/histenv2/lib/python3.9/asyncio/base_events.py", line 634, in run_until_complete
    self.run_forever()
  File "/home1/datahome/mdemol/.miniconda3/envs/histenv2/lib/python3.9/asyncio/base_events.py", line 1869, in _run_once
    event_list = self._selector.select(timeout)
  File "/home1/datahome/mdemol/.miniconda3/envs/histenv2/lib/python3.9/site-packages/distributed/compatibility.py", line 236, in asyncio_run
    return loop.run_until_complete(main)
  File "/home1/datahome/mdemol/.miniconda3/envs/histenv2/lib/python3.9/multiprocessing/process.py", line 108, in run
    self._target(*self._args, **self._kwargs)
  File "/home1/datahome/mdemol/.miniconda3/envs/histenv2/lib/python3.9/asyncio/base_events.py", line 601, in run_forever
    self._run_once()
  File "/home1/datahome/mdemol/.miniconda3/envs/histenv2/lib/python3.9/asyncio/base_events.py", line 601, in run_forever
    self._run_once()
  File "/home1/datahome/mdemol/.miniconda3/envs/histenv2/lib/python3.9/selectors.py", line 469, in select
    fd_event_list = self._selector.poll(timeout, max_ev)
  File "/home1/datahome/mdemol/.miniconda3/envs/histenv2/lib/python3.9/asyncio/base_events.py", line 634, in run_until_complete
    self.run_forever()
  File "/home1/datahome/mdemol/.miniconda3/envs/histenv2/lib/python3.9/site-packages/distributed/process.py", line 202, in _run
    target(*args, **kwargs)
  File "/home1/datahome/mdemol/.miniconda3/envs/histenv2/lib/python3.9/asyncio/base_events.py", line 1869, in _run_once
    event_list = self._selector.select(timeout)
  File "/home1/datahome/mdemol/.miniconda3/envs/histenv2/lib/python3.9/asyncio/base_events.py", line 1869, in _run_once
    event_list = self._selector.select(timeout)
  File "/home1/datahome/mdemol/.miniconda3/envs/histenv2/lib/python3.9/asyncio/base_events.py", line 601, in run_forever
    self._run_once()
  File "/home1/datahome/mdemol/.miniconda3/envs/histenv2/lib/python3.9/site-packages/distributed/nanny.py", line 1014, in _run
    asyncio_run(run(), loop_factory=get_loop_factory())
  File "/home1/datahome/mdemol/.miniconda3/envs/histenv2/lib/python3.9/selectors.py", line 469, in select
    fd_event_list = self._selector.poll(timeout, max_ev)
  File "/home1/datahome/mdemol/.miniconda3/envs/histenv2/lib/python3.9/selectors.py", line 469, in select
    fd_event_list = self._selector.poll(timeout, max_ev)
  File "/home1/datahome/mdemol/.miniconda3/envs/histenv2/lib/python3.9/site-packages/distributed/compatibility.py", line 239, in asyncio_run
    _cancel_all_tasks(loop)
  File "/home1/datahome/mdemol/.miniconda3/envs/histenv2/lib/python3.9/asyncio/base_events.py", line 1869, in _run_once
    event_list = self._selector.select(timeout)
  File "/home1/datahome/mdemol/.miniconda3/envs/histenv2/lib/python3.9/selectors.py", line 469, in select
    fd_event_list = self._selector.poll(timeout, max_ev)
  File "/home1/datahome/mdemol/.miniconda3/envs/histenv2/lib/python3.9/site-packages/distributed/compatibility.py", line 255, in _cancel_all_tasks
    loop.run_until_complete(asyncio.gather(*to_cancel, return_exceptions=True))
KeyboardInterrupt
  File "/home1/datahome/mdemol/.miniconda3/envs/histenv2/lib/python3.9/asyncio/base_events.py", line 634, in run_until_complete
    self.run_forever()
  File "/home1/datahome/mdemol/.miniconda3/envs/histenv2/lib/python3.9/asyncio/base_events.py", line 601, in run_forever
    self._run_once()
  File "/home1/datahome/mdemol/.miniconda3/envs/histenv2/lib/python3.9/asyncio/base_events.py", line 1869, in _run_once
    event_list = self._selector.select(timeout)
KeyboardInterrupt
KeyboardInterrupt
  File "/home1/datahome/mdemol/.miniconda3/envs/histenv2/lib/python3.9/selectors.py", line 469, in select
    fd_event_list = self._selector.poll(timeout, max_ev)
KeyboardInterrupt
  File "/home1/datahome/mdemol/.miniconda3/envs/histenv2/lib/python3.9/multiprocessing/process.py", line 315, in _bootstrap
    self.run()

During handling of the above exception, another exception occurred:

  File "/home1/datahome/mdemol/.miniconda3/envs/histenv2/lib/python3.9/multiprocessing/process.py", line 108, in run
    self._target(*self._args, **self._kwargs)
KeyboardInterrupt
Traceback (most recent call last):
  File "/home1/datahome/mdemol/.miniconda3/envs/histenv2/lib/python3.9/site-packages/distributed/process.py", line 202, in _run
    target(*args, **kwargs)

During handling of the above exception, another exception occurred:


During handling of the above exception, another exception occurred:


During handling of the above exception, another exception occurred:

  File "/home1/datahome/mdemol/.miniconda3/envs/histenv2/lib/python3.9/site-packages/distributed/nanny.py", line 1014, in _run
    asyncio_run(run(), loop_factory=get_loop_factory())
Traceback (most recent call last):
Traceback (most recent call last):
Traceback (most recent call last):
  File "/home1/datahome/mdemol/.miniconda3/envs/histenv2/lib/python3.9/site-packages/distributed/compatibility.py", line 239, in asyncio_run
    _cancel_all_tasks(loop)
  File "/home1/datahome/mdemol/.miniconda3/envs/histenv2/lib/python3.9/site-packages/distributed/compatibility.py", line 255, in _cancel_all_tasks
    loop.run_until_complete(asyncio.gather(*to_cancel, return_exceptions=True))
  File "/home1/datahome/mdemol/.miniconda3/envs/histenv2/lib/python3.9/asyncio/base_events.py", line 634, in run_until_complete
    self.run_forever()
  File "/home1/datahome/mdemol/.miniconda3/envs/histenv2/lib/python3.9/asyncio/base_events.py", line 601, in run_forever
    self._run_once()
  File "/home1/datahome/mdemol/.miniconda3/envs/histenv2/lib/python3.9/asyncio/base_events.py", line 1869, in _run_once
    event_list = self._selector.select(timeout)
  File "/home1/datahome/mdemol/.miniconda3/envs/histenv2/lib/python3.9/selectors.py", line 469, in select
    fd_event_list = self._selector.poll(timeout, max_ev)
KeyboardInterrupt
  File "/home1/datahome/mdemol/.miniconda3/envs/histenv2/lib/python3.9/multiprocessing/process.py", line 315, in _bootstrap
    self.run()
  File "/home1/datahome/mdemol/.miniconda3/envs/histenv2/lib/python3.9/multiprocessing/process.py", line 315, in _bootstrap
    self.run()
  File "/home1/datahome/mdemol/.miniconda3/envs/histenv2/lib/python3.9/multiprocessing/process.py", line 315, in _bootstrap
    self.run()
  File "/home1/datahome/mdemol/.miniconda3/envs/histenv2/lib/python3.9/multiprocessing/process.py", line 315, in _bootstrap
    self.run()
  File "/home1/datahome/mdemol/.miniconda3/envs/histenv2/lib/python3.9/multiprocessing/process.py", line 108, in run
    self._target(*self._args, **self._kwargs)
  File "/home1/datahome/mdemol/.miniconda3/envs/histenv2/lib/python3.9/multiprocessing/process.py", line 108, in run
    self._target(*self._args, **self._kwargs)
  File "/home1/datahome/mdemol/.miniconda3/envs/histenv2/lib/python3.9/multiprocessing/process.py", line 108, in run
    self._target(*self._args, **self._kwargs)
  File "/home1/datahome/mdemol/.miniconda3/envs/histenv2/lib/python3.9/multiprocessing/process.py", line 108, in run
    self._target(*self._args, **self._kwargs)
  File "/home1/datahome/mdemol/.miniconda3/envs/histenv2/lib/python3.9/site-packages/distributed/process.py", line 202, in _run
    target(*args, **kwargs)
  File "/home1/datahome/mdemol/.miniconda3/envs/histenv2/lib/python3.9/site-packages/distributed/process.py", line 202, in _run
    target(*args, **kwargs)
  File "/home1/datahome/mdemol/.miniconda3/envs/histenv2/lib/python3.9/site-packages/distributed/process.py", line 202, in _run
    target(*args, **kwargs)
  File "/home1/datahome/mdemol/.miniconda3/envs/histenv2/lib/python3.9/site-packages/distributed/process.py", line 202, in _run
    target(*args, **kwargs)
  File "/home1/datahome/mdemol/.miniconda3/envs/histenv2/lib/python3.9/site-packages/distributed/nanny.py", line 1014, in _run
    asyncio_run(run(), loop_factory=get_loop_factory())
  File "/home1/datahome/mdemol/.miniconda3/envs/histenv2/lib/python3.9/site-packages/distributed/nanny.py", line 1014, in _run
    asyncio_run(run(), loop_factory=get_loop_factory())
  File "/home1/datahome/mdemol/.miniconda3/envs/histenv2/lib/python3.9/site-packages/distributed/nanny.py", line 1014, in _run
    asyncio_run(run(), loop_factory=get_loop_factory())
  File "/home1/datahome/mdemol/.miniconda3/envs/histenv2/lib/python3.9/site-packages/distributed/nanny.py", line 1014, in _run
    asyncio_run(run(), loop_factory=get_loop_factory())
  File "/home1/datahome/mdemol/.miniconda3/envs/histenv2/lib/python3.9/site-packages/distributed/compatibility.py", line 239, in asyncio_run
    _cancel_all_tasks(loop)
  File "/home1/datahome/mdemol/.miniconda3/envs/histenv2/lib/python3.9/site-packages/distributed/compatibility.py", line 239, in asyncio_run
    _cancel_all_tasks(loop)
  File "/home1/datahome/mdemol/.miniconda3/envs/histenv2/lib/python3.9/site-packages/distributed/compatibility.py", line 239, in asyncio_run
    _cancel_all_tasks(loop)
  File "/home1/datahome/mdemol/.miniconda3/envs/histenv2/lib/python3.9/site-packages/distributed/compatibility.py", line 239, in asyncio_run
    _cancel_all_tasks(loop)
  File "/home1/datahome/mdemol/.miniconda3/envs/histenv2/lib/python3.9/site-packages/distributed/compatibility.py", line 255, in _cancel_all_tasks
    loop.run_until_complete(asyncio.gather(*to_cancel, return_exceptions=True))
  File "/home1/datahome/mdemol/.miniconda3/envs/histenv2/lib/python3.9/site-packages/distributed/compatibility.py", line 255, in _cancel_all_tasks
    loop.run_until_complete(asyncio.gather(*to_cancel, return_exceptions=True))
  File "/home1/datahome/mdemol/.miniconda3/envs/histenv2/lib/python3.9/site-packages/distributed/compatibility.py", line 255, in _cancel_all_tasks
    loop.run_until_complete(asyncio.gather(*to_cancel, return_exceptions=True))
  File "/home1/datahome/mdemol/.miniconda3/envs/histenv2/lib/python3.9/asyncio/base_events.py", line 634, in run_until_complete
    self.run_forever()
  File "/home1/datahome/mdemol/.miniconda3/envs/histenv2/lib/python3.9/site-packages/distributed/compatibility.py", line 255, in _cancel_all_tasks
    loop.run_until_complete(asyncio.gather(*to_cancel, return_exceptions=True))
  File "/home1/datahome/mdemol/.miniconda3/envs/histenv2/lib/python3.9/asyncio/base_events.py", line 634, in run_until_complete
    self.run_forever()
  File "/home1/datahome/mdemol/.miniconda3/envs/histenv2/lib/python3.9/asyncio/base_events.py", line 634, in run_until_complete
    self.run_forever()
  File "/home1/datahome/mdemol/.miniconda3/envs/histenv2/lib/python3.9/asyncio/base_events.py", line 601, in run_forever
    self._run_once()
  File "/home1/datahome/mdemol/.miniconda3/envs/histenv2/lib/python3.9/asyncio/base_events.py", line 634, in run_until_complete
    self.run_forever()
  File "/home1/datahome/mdemol/.miniconda3/envs/histenv2/lib/python3.9/asyncio/base_events.py", line 601, in run_forever
    self._run_once()
  File "/home1/datahome/mdemol/.miniconda3/envs/histenv2/lib/python3.9/asyncio/base_events.py", line 601, in run_forever
    self._run_once()
  File "/home1/datahome/mdemol/.miniconda3/envs/histenv2/lib/python3.9/asyncio/base_events.py", line 1869, in _run_once
    event_list = self._selector.select(timeout)
  File "/home1/datahome/mdemol/.miniconda3/envs/histenv2/lib/python3.9/asyncio/base_events.py", line 601, in run_forever
    self._run_once()
  File "/home1/datahome/mdemol/.miniconda3/envs/histenv2/lib/python3.9/asyncio/base_events.py", line 1869, in _run_once
    event_list = self._selector.select(timeout)
  File "/home1/datahome/mdemol/.miniconda3/envs/histenv2/lib/python3.9/asyncio/base_events.py", line 1869, in _run_once
    event_list = self._selector.select(timeout)
  File "/home1/datahome/mdemol/.miniconda3/envs/histenv2/lib/python3.9/selectors.py", line 469, in select
    fd_event_list = self._selector.poll(timeout, max_ev)
  File "/home1/datahome/mdemol/.miniconda3/envs/histenv2/lib/python3.9/asyncio/base_events.py", line 1869, in _run_once
    event_list = self._selector.select(timeout)
  File "/home1/datahome/mdemol/.miniconda3/envs/histenv2/lib/python3.9/selectors.py", line 469, in select
    fd_event_list = self._selector.poll(timeout, max_ev)
  File "/home1/datahome/mdemol/.miniconda3/envs/histenv2/lib/python3.9/selectors.py", line 469, in select
    fd_event_list = self._selector.poll(timeout, max_ev)
  File "/home1/datahome/mdemol/.miniconda3/envs/histenv2/lib/python3.9/selectors.py", line 469, in select
    fd_event_list = self._selector.poll(timeout, max_ev)
KeyboardInterrupt
KeyboardInterrupt
KeyboardInterrupt
KeyboardInterrupt
Traceback (most recent call last):
  File "/home1/datahome/mdemol/.miniconda3/envs/histenv2/lib/python3.9/site-packages/distributed/compatibility.py", line 236, in asyncio_run
    return loop.run_until_complete(main)
  File "/home1/datahome/mdemol/.miniconda3/envs/histenv2/lib/python3.9/asyncio/base_events.py", line 634, in run_until_complete
    self.run_forever()
  File "/home1/datahome/mdemol/.miniconda3/envs/histenv2/lib/python3.9/asyncio/base_events.py", line 601, in run_forever
    self._run_once()
  File "/home1/datahome/mdemol/.miniconda3/envs/histenv2/lib/python3.9/asyncio/base_events.py", line 1869, in _run_once
    event_list = self._selector.select(timeout)
  File "/home1/datahome/mdemol/.miniconda3/envs/histenv2/lib/python3.9/selectors.py", line 469, in select
    fd_event_list = self._selector.poll(timeout, max_ev)
KeyboardInterrupt

During handling of the above exception, another exception occurred:

Traceback (most recent call last):
  File "/home1/datahome/mdemol/.miniconda3/envs/histenv2/lib/python3.9/multiprocessing/process.py", line 315, in _bootstrap
    self.run()
  File "/home1/datahome/mdemol/.miniconda3/envs/histenv2/lib/python3.9/multiprocessing/process.py", line 108, in run
    self._target(*self._args, **self._kwargs)
  File "/home1/datahome/mdemol/.miniconda3/envs/histenv2/lib/python3.9/site-packages/distributed/process.py", line 202, in _run
    target(*args, **kwargs)
  File "/home1/datahome/mdemol/.miniconda3/envs/histenv2/lib/python3.9/site-packages/distributed/nanny.py", line 1014, in _run
    asyncio_run(run(), loop_factory=get_loop_factory())
  File "/home1/datahome/mdemol/.miniconda3/envs/histenv2/lib/python3.9/site-packages/distributed/compatibility.py", line 239, in asyncio_run
    _cancel_all_tasks(loop)
  File "/home1/datahome/mdemol/.miniconda3/envs/histenv2/lib/python3.9/site-packages/distributed/compatibility.py", line 255, in _cancel_all_tasks
    loop.run_until_complete(asyncio.gather(*to_cancel, return_exceptions=True))
  File "/home1/datahome/mdemol/.miniconda3/envs/histenv2/lib/python3.9/asyncio/base_events.py", line 634, in run_until_complete
    self.run_forever()
  File "/home1/datahome/mdemol/.miniconda3/envs/histenv2/lib/python3.9/asyncio/base_events.py", line 601, in run_forever
    self._run_once()
  File "/home1/datahome/mdemol/.miniconda3/envs/histenv2/lib/python3.9/asyncio/base_events.py", line 1869, in _run_once
    event_list = self._selector.select(timeout)
  File "/home1/datahome/mdemol/.miniconda3/envs/histenv2/lib/python3.9/selectors.py", line 469, in select
    fd_event_list = self._selector.poll(timeout, max_ev)
KeyboardInterrupt
Traceback (most recent call last):
  File "/home1/datahome/mdemol/.miniconda3/envs/histenv2/lib/python3.9/site-packages/distributed/compatibility.py", line 236, in asyncio_run
    return loop.run_until_complete(main)
  File "/home1/datahome/mdemol/.miniconda3/envs/histenv2/lib/python3.9/asyncio/base_events.py", line 634, in run_until_complete
    self.run_forever()
  File "/home1/datahome/mdemol/.miniconda3/envs/histenv2/lib/python3.9/asyncio/base_events.py", line 601, in run_forever
    self._run_once()
  File "/home1/datahome/mdemol/.miniconda3/envs/histenv2/lib/python3.9/asyncio/base_events.py", line 1869, in _run_once
    event_list = self._selector.select(timeout)
  File "/home1/datahome/mdemol/.miniconda3/envs/histenv2/lib/python3.9/selectors.py", line 469, in select
    fd_event_list = self._selector.poll(timeout, max_ev)
KeyboardInterrupt

During handling of the above exception, another exception occurred:

Traceback (most recent call last):
  File "/home1/datahome/mdemol/.miniconda3/envs/histenv2/lib/python3.9/multiprocessing/process.py", line 315, in _bootstrap
    self.run()
  File "/home1/datahome/mdemol/.miniconda3/envs/histenv2/lib/python3.9/multiprocessing/process.py", line 108, in run
    self._target(*self._args, **self._kwargs)
  File "/home1/datahome/mdemol/.miniconda3/envs/histenv2/lib/python3.9/site-packages/distributed/process.py", line 202, in _run
    target(*args, **kwargs)
  File "/home1/datahome/mdemol/.miniconda3/envs/histenv2/lib/python3.9/site-packages/distributed/nanny.py", line 1014, in _run
    asyncio_run(run(), loop_factory=get_loop_factory())
  File "/home1/datahome/mdemol/.miniconda3/envs/histenv2/lib/python3.9/site-packages/distributed/compatibility.py", line 239, in asyncio_run
    _cancel_all_tasks(loop)
  File "/home1/datahome/mdemol/.miniconda3/envs/histenv2/lib/python3.9/site-packages/distributed/compatibility.py", line 255, in _cancel_all_tasks
    loop.run_until_complete(asyncio.gather(*to_cancel, return_exceptions=True))
  File "/home1/datahome/mdemol/.miniconda3/envs/histenv2/lib/python3.9/asyncio/base_events.py", line 634, in run_until_complete
    self.run_forever()
  File "/home1/datahome/mdemol/.miniconda3/envs/histenv2/lib/python3.9/asyncio/base_events.py", line 601, in run_forever
    self._run_once()
  File "/home1/datahome/mdemol/.miniconda3/envs/histenv2/lib/python3.9/asyncio/base_events.py", line 1869, in _run_once
    event_list = self._selector.select(timeout)
  File "/home1/datahome/mdemol/.miniconda3/envs/histenv2/lib/python3.9/selectors.py", line 469, in select
    fd_event_list = self._selector.poll(timeout, max_ev)
KeyboardInterrupt
/home1/datahome/mdemol/.miniconda3/envs/histenv2/lib/python3.9/site-packages/dask/config.py:742: FutureWarning: Dask configuration key 'distributed.scheduler.transition-log-length' has been deprecated; please use 'distributed.admin.low-level-log-length' instead
  warnings.warn(
/home1/datahome/mdemol/.miniconda3/envs/histenv2/lib/python3.9/site-packages/dask/config.py:742: FutureWarning: Dask configuration key 'distributed.comm.recent-messages-log-length' has been deprecated; please use 'distributed.admin.low-level-log-length' instead
  warnings.warn(
/home1/datahome/mdemol/.miniconda3/envs/histenv2/lib/python3.9/site-packages/dask/config.py:742: FutureWarning: Dask configuration key 'distributed.scheduler.transition-log-length' has been deprecated; please use 'distributed.admin.low-level-log-length' instead
  warnings.warn(
/home1/datahome/mdemol/.miniconda3/envs/histenv2/lib/python3.9/site-packages/dask/config.py:742: FutureWarning: Dask configuration key 'distributed.comm.recent-messages-log-length' has been deprecated; please use 'distributed.admin.low-level-log-length' instead
  warnings.warn(
/home1/datahome/mdemol/.miniconda3/envs/histenv2/lib/python3.9/site-packages/dask/config.py:742: FutureWarning: Dask configuration key 'distributed.scheduler.transition-log-length' has been deprecated; please use 'distributed.admin.low-level-log-length' instead
  warnings.warn(
/home1/datahome/mdemol/.miniconda3/envs/histenv2/lib/python3.9/site-packages/dask/config.py:742: FutureWarning: Dask configuration key 'distributed.comm.recent-messages-log-length' has been deprecated; please use 'distributed.admin.low-level-log-length' instead
  warnings.warn(
/home1/datahome/mdemol/.miniconda3/envs/histenv2/lib/python3.9/site-packages/dask/config.py:742: FutureWarning: Dask configuration key 'distributed.scheduler.transition-log-length' has been deprecated; please use 'distributed.admin.low-level-log-length' instead
  warnings.warn(
/home1/datahome/mdemol/.miniconda3/envs/histenv2/lib/python3.9/site-packages/dask/config.py:742: FutureWarning: Dask configuration key 'distributed.scheduler.transition-log-length' has been deprecated; please use 'distributed.admin.low-level-log-length' instead
  warnings.warn(
/home1/datahome/mdemol/.miniconda3/envs/histenv2/lib/python3.9/site-packages/dask/config.py:742: FutureWarning: Dask configuration key 'distributed.comm.recent-messages-log-length' has been deprecated; please use 'distributed.admin.low-level-log-length' instead
  warnings.warn(
/home1/datahome/mdemol/.miniconda3/envs/histenv2/lib/python3.9/site-packages/dask/config.py:742: FutureWarning: Dask configuration key 'distributed.comm.recent-messages-log-length' has been deprecated; please use 'distributed.admin.low-level-log-length' instead
  warnings.warn(
/home1/datahome/mdemol/.miniconda3/envs/histenv2/lib/python3.9/site-packages/dask/config.py:742: FutureWarning: Dask configuration key 'distributed.scheduler.transition-log-length' has been deprecated; please use 'distributed.admin.low-level-log-length' instead
  warnings.warn(
/home1/datahome/mdemol/.miniconda3/envs/histenv2/lib/python3.9/site-packages/dask/config.py:742: FutureWarning: Dask configuration key 'distributed.comm.recent-messages-log-length' has been deprecated; please use 'distributed.admin.low-level-log-length' instead
  warnings.warn(
/home1/datahome/mdemol/.miniconda3/envs/histenv2/lib/python3.9/site-packages/dask/config.py:742: FutureWarning: Dask configuration key 'distributed.scheduler.transition-log-length' has been deprecated; please use 'distributed.admin.low-level-log-length' instead
  warnings.warn(
/home1/datahome/mdemol/.miniconda3/envs/histenv2/lib/python3.9/site-packages/dask/config.py:742: FutureWarning: Dask configuration key 'distributed.comm.recent-messages-log-length' has been deprecated; please use 'distributed.admin.low-level-log-length' instead
  warnings.warn(
/home1/datahome/mdemol/.miniconda3/envs/histenv2/lib/python3.9/site-packages/dask/config.py:742: FutureWarning: Dask configuration key 'distributed.scheduler.transition-log-length' has been deprecated; please use 'distributed.admin.low-level-log-length' instead
  warnings.warn(
/home1/datahome/mdemol/.miniconda3/envs/histenv2/lib/python3.9/site-packages/dask/config.py:742: FutureWarning: Dask configuration key 'distributed.comm.recent-messages-log-length' has been deprecated; please use 'distributed.admin.low-level-log-length' instead
  warnings.warn(
/home1/datahome/mdemol/.miniconda3/envs/histenv2/lib/python3.9/site-packages/xarray/coding/times.py:228: RuntimeWarning: invalid value encountered in cast
  flat_num_dates_ns_int = (flat_num_dates * _NS_PER_TIME_DELTA[delta]).astype(
/home1/datahome/mdemol/.miniconda3/envs/histenv2/lib/python3.9/site-packages/xarray/coding/times.py:228: RuntimeWarning: invalid value encountered in cast
  flat_num_dates_ns_int = (flat_num_dates * _NS_PER_TIME_DELTA[delta]).astype(
/home1/datahome/mdemol/.miniconda3/envs/histenv2/lib/python3.9/site-packages/xarray/coding/times.py:228: RuntimeWarning: invalid value encountered in cast
  flat_num_dates_ns_int = (flat_num_dates * _NS_PER_TIME_DELTA[delta]).astype(
/home1/datahome/mdemol/.miniconda3/envs/histenv2/lib/python3.9/site-packages/xarray/coding/times.py:228: RuntimeWarning: invalid value encountered in cast
  flat_num_dates_ns_int = (flat_num_dates * _NS_PER_TIME_DELTA[delta]).astype(
/home1/datahome/mdemol/.miniconda3/envs/histenv2/lib/python3.9/site-packages/xarray/coding/times.py:228: RuntimeWarning: invalid value encountered in cast
  flat_num_dates_ns_int = (flat_num_dates * _NS_PER_TIME_DELTA[delta]).astype(
/home1/datahome/mdemol/.miniconda3/envs/histenv2/lib/python3.9/site-packages/xarray/coding/times.py:228: RuntimeWarning: invalid value encountered in cast
  flat_num_dates_ns_int = (flat_num_dates * _NS_PER_TIME_DELTA[delta]).astype(
/home1/datahome/mdemol/.miniconda3/envs/histenv2/lib/python3.9/site-packages/xarray/coding/times.py:228: RuntimeWarning: invalid value encountered in cast
  flat_num_dates_ns_int = (flat_num_dates * _NS_PER_TIME_DELTA[delta]).astype(
/home1/datahome/mdemol/.miniconda3/envs/histenv2/lib/python3.9/site-packages/xarray/coding/times.py:228: RuntimeWarning: invalid value encountered in cast
  flat_num_dates_ns_int = (flat_num_dates * _NS_PER_TIME_DELTA[delta]).astype(
/home1/datahome/mdemol/.miniconda3/envs/histenv2/lib/python3.9/site-packages/xarray/coding/times.py:228: RuntimeWarning: invalid value encountered in cast
  flat_num_dates_ns_int = (flat_num_dates * _NS_PER_TIME_DELTA[delta]).astype(
/home1/datahome/mdemol/.miniconda3/envs/histenv2/lib/python3.9/site-packages/xarray/coding/times.py:228: RuntimeWarning: invalid value encountered in cast
  flat_num_dates_ns_int = (flat_num_dates * _NS_PER_TIME_DELTA[delta]).astype(
/home1/datahome/mdemol/.miniconda3/envs/histenv2/lib/python3.9/site-packages/xarray/coding/times.py:228: RuntimeWarning: invalid value encountered in cast
  flat_num_dates_ns_int = (flat_num_dates * _NS_PER_TIME_DELTA[delta]).astype(
/home1/datahome/mdemol/.miniconda3/envs/histenv2/lib/python3.9/site-packages/xarray/coding/times.py:228: RuntimeWarning: invalid value encountered in cast
  flat_num_dates_ns_int = (flat_num_dates * _NS_PER_TIME_DELTA[delta]).astype(
/home1/datahome/mdemol/.miniconda3/envs/histenv2/lib/python3.9/site-packages/xarray/coding/times.py:228: RuntimeWarning: invalid value encountered in cast
  flat_num_dates_ns_int = (flat_num_dates * _NS_PER_TIME_DELTA[delta]).astype(
/home1/datahome/mdemol/.miniconda3/envs/histenv2/lib/python3.9/site-packages/xarray/coding/times.py:228: RuntimeWarning: invalid value encountered in cast
  flat_num_dates_ns_int = (flat_num_dates * _NS_PER_TIME_DELTA[delta]).astype(
/home1/datahome/mdemol/.miniconda3/envs/histenv2/lib/python3.9/site-packages/xarray/coding/times.py:228: RuntimeWarning: invalid value encountered in cast
  flat_num_dates_ns_int = (flat_num_dates * _NS_PER_TIME_DELTA[delta]).astype(
distributed.worker.state_machine - WARNING - Async instruction for <Task cancelled name="execute(('open_dataset-570c837613df69df97fa7d8f8b8eeb0ealti_sla_unfiltered_denoised-05e64269115cc3b164d4c6abaf09cae7', 105, 0))" coro=<Worker.execute() done, defined at /home1/datahome/mdemol/.miniconda3/envs/histenv2/lib/python3.9/site-packages/distributed/worker_state_machine.py:3610>> ended with CancelledError
distributed.worker.state_machine - WARNING - Async instruction for <Task cancelled name="execute(('open_dataset-570c837613df69df97fa7d8f8b8eeb0ebox_lon-297208dbe23cd5e49e42e779656767e7', 6, 0, 0))" coro=<Worker.execute() done, defined at /home1/datahome/mdemol/.miniconda3/envs/histenv2/lib/python3.9/site-packages/distributed/worker_state_machine.py:3610>> ended with CancelledError
distributed.worker.state_machine - WARNING - Async instruction for <Task cancelled name="execute(('open_dataset-570c837613df69df97fa7d8f8b8eeb0edrifter_err_vn-af0ce8c4bde7c91e172149ea464986cb', 105, 0))" coro=<Worker.execute() done, defined at /home1/datahome/mdemol/.miniconda3/envs/histenv2/lib/python3.9/site-packages/distributed/worker_state_machine.py:3610>> ended with CancelledError
distributed.worker.state_machine - WARNING - Async instruction for <Task cancelled name="execute(('open_dataset-570c837613df69df97fa7d8f8b8eeb0ealti_y-52168659e8651f5ac3ffe5acc78abc9b', 212, 0))" coro=<Worker.execute() done, defined at /home1/datahome/mdemol/.miniconda3/envs/histenv2/lib/python3.9/site-packages/distributed/worker_state_machine.py:3610>> ended with CancelledError
distributed.worker.state_machine - WARNING - Async instruction for <Task cancelled name="execute(('open_dataset-570c837613df69df97fa7d8f8b8eeb0ebox_lon-297208dbe23cd5e49e42e779656767e7', 56, 0, 0))" coro=<Worker.execute() done, defined at /home1/datahome/mdemol/.miniconda3/envs/histenv2/lib/python3.9/site-packages/distributed/worker_state_machine.py:3610>> ended with CancelledError
distributed.worker.state_machine - WARNING - Async instruction for <Task cancelled name="execute(('open_dataset-570c837613df69df97fa7d8f8b8eeb0edrifter_err_vn-af0ce8c4bde7c91e172149ea464986cb', 213, 0))" coro=<Worker.execute() done, defined at /home1/datahome/mdemol/.miniconda3/envs/histenv2/lib/python3.9/site-packages/distributed/worker_state_machine.py:3610>> ended with CancelledError
distributed.worker.state_machine - WARNING - Async instruction for <Task cancelled name="execute(('open_dataset-570c837613df69df97fa7d8f8b8eeb0ealti_sla_unfiltered_denoised-05e64269115cc3b164d4c6abaf09cae7', 171, 0))" coro=<Worker.execute() done, defined at /home1/datahome/mdemol/.miniconda3/envs/histenv2/lib/python3.9/site-packages/distributed/worker_state_machine.py:3610>> ended with CancelledError
distributed.worker.state_machine - WARNING - Async instruction for <Task cancelled name="execute(('open_dataset-570c837613df69df97fa7d8f8b8eeb0ealti_y-52168659e8651f5ac3ffe5acc78abc9b', 135, 0))" coro=<Worker.execute() done, defined at /home1/datahome/mdemol/.miniconda3/envs/histenv2/lib/python3.9/site-packages/distributed/worker_state_machine.py:3610>> ended with CancelledError
distributed.worker.state_machine - WARNING - Async instruction for <Task cancelled name="execute(('open_dataset-570c837613df69df97fa7d8f8b8eeb0edrifter_err_vn-af0ce8c4bde7c91e172149ea464986cb', 26, 0))" coro=<Worker.execute() done, defined at /home1/datahome/mdemol/.miniconda3/envs/histenv2/lib/python3.9/site-packages/distributed/worker_state_machine.py:3610>> ended with CancelledError
distributed.worker.state_machine - WARNING - Async instruction for <Task cancelled name="execute(('open_dataset-570c837613df69df97fa7d8f8b8eeb0ealti_ggx_ocean_tide-1fce07467734a1146fdd8fa92fe47659', 99, 0))" coro=<Worker.execute() done, defined at /home1/datahome/mdemol/.miniconda3/envs/histenv2/lib/python3.9/site-packages/distributed/worker_state_machine.py:3610>> ended with CancelledError
distributed.worker.state_machine - WARNING - Async instruction for <Task cancelled name="execute(('open_dataset-570c837613df69df97fa7d8f8b8eeb0ealti_ggx_sla_unfiltered_noise-23b39a65bf981deca14f09b8149c59e5', 92, 0))" coro=<Worker.execute() done, defined at /home1/datahome/mdemol/.miniconda3/envs/histenv2/lib/python3.9/site-packages/distributed/worker_state_machine.py:3610>> ended with CancelledError
distributed.worker.state_machine - WARNING - Async instruction for <Task cancelled name="execute(('open_dataset-570c837613df69df97fa7d8f8b8eeb0ebox_lon-297208dbe23cd5e49e42e779656767e7', 165, 0, 0))" coro=<Worker.execute() done, defined at /home1/datahome/mdemol/.miniconda3/envs/histenv2/lib/python3.9/site-packages/distributed/worker_state_machine.py:3610>> ended with CancelledError
distributed.worker.state_machine - WARNING - Async instruction for <Task cancelled name="execute(('open_dataset-570c837613df69df97fa7d8f8b8eeb0ealti_ggx_ocean_tide-1fce07467734a1146fdd8fa92fe47659', 165, 0))" coro=<Worker.execute() done, defined at /home1/datahome/mdemol/.miniconda3/envs/histenv2/lib/python3.9/site-packages/distributed/worker_state_machine.py:3610>> ended with CancelledError
distributed.worker.state_machine - WARNING - Async instruction for <Task cancelled name="execute(('open_dataset-570c837613df69df97fa7d8f8b8eeb0ealti_ggx_sla_unfiltered_noise-23b39a65bf981deca14f09b8149c59e5', 39, 0))" coro=<Worker.execute() done, defined at /home1/datahome/mdemol/.miniconda3/envs/histenv2/lib/python3.9/site-packages/distributed/worker_state_machine.py:3610>> ended with CancelledError
distributed.worker.state_machine - WARNING - Async instruction for <Task cancelled name="execute(('open_dataset-570c837613df69df97fa7d8f8b8eeb0ealti_sla_unfiltered_denoised-05e64269115cc3b164d4c6abaf09cae7', 184, 0))" coro=<Worker.execute() done, defined at /home1/datahome/mdemol/.miniconda3/envs/histenv2/lib/python3.9/site-packages/distributed/worker_state_machine.py:3610>> ended with CancelledError
distributed.worker.state_machine - WARNING - Async instruction for <Task cancelled name="execute(('open_dataset-570c837613df69df97fa7d8f8b8eeb0ebox_lon-297208dbe23cd5e49e42e779656767e7', 168, 0, 0))" coro=<Worker.execute() done, defined at /home1/datahome/mdemol/.miniconda3/envs/histenv2/lib/python3.9/site-packages/distributed/worker_state_machine.py:3610>> ended with CancelledError
distributed.worker.state_machine - WARNING - Async instruction for <Task cancelled name="execute(('open_dataset-570c837613df69df97fa7d8f8b8eeb0ealti_y-52168659e8651f5ac3ffe5acc78abc9b', 29, 0))" coro=<Worker.execute() done, defined at /home1/datahome/mdemol/.miniconda3/envs/histenv2/lib/python3.9/site-packages/distributed/worker_state_machine.py:3610>> ended with CancelledError
distributed.worker.state_machine - WARNING - Async instruction for <Task cancelled name="execute(('open_dataset-570c837613df69df97fa7d8f8b8eeb0edrifter_err_vn-af0ce8c4bde7c91e172149ea464986cb', 81, 0))" coro=<Worker.execute() done, defined at /home1/datahome/mdemol/.miniconda3/envs/histenv2/lib/python3.9/site-packages/distributed/worker_state_machine.py:3610>> ended with CancelledError
distributed.worker.state_machine - WARNING - Async instruction for <Task cancelled name="execute(('open_dataset-570c837613df69df97fa7d8f8b8eeb0ealti_ggx_ocean_tide-1fce07467734a1146fdd8fa92fe47659', 141, 0))" coro=<Worker.execute() done, defined at /home1/datahome/mdemol/.miniconda3/envs/histenv2/lib/python3.9/site-packages/distributed/worker_state_machine.py:3610>> ended with CancelledError
distributed.worker.state_machine - WARNING - Async instruction for <Task cancelled name="execute(('open_dataset-570c837613df69df97fa7d8f8b8eeb0ealti_ggx_sla_unfiltered_noise-23b39a65bf981deca14f09b8149c59e5', 202, 0))" coro=<Worker.execute() done, defined at /home1/datahome/mdemol/.miniconda3/envs/histenv2/lib/python3.9/site-packages/distributed/worker_state_machine.py:3610>> ended with CancelledError
distributed.worker.state_machine - WARNING - Async instruction for <Task cancelled name="execute(('open_dataset-570c837613df69df97fa7d8f8b8eeb0ebox_lon-297208dbe23cd5e49e42e779656767e7', 46, 0, 0))" coro=<Worker.execute() done, defined at /home1/datahome/mdemol/.miniconda3/envs/histenv2/lib/python3.9/site-packages/distributed/worker_state_machine.py:3610>> ended with CancelledError
distributed.worker.state_machine - WARNING - Async instruction for <Task cancelled name="execute(('open_dataset-570c837613df69df97fa7d8f8b8eeb0ealti_y-52168659e8651f5ac3ffe5acc78abc9b', 190, 0))" coro=<Worker.execute() done, defined at /home1/datahome/mdemol/.miniconda3/envs/histenv2/lib/python3.9/site-packages/distributed/worker_state_machine.py:3610>> ended with CancelledError
distributed.worker.state_machine - WARNING - Async instruction for <Task cancelled name="execute(('open_dataset-570c837613df69df97fa7d8f8b8eeb0ealti_sla_unfiltered_denoised-05e64269115cc3b164d4c6abaf09cae7', 173, 0))" coro=<Worker.execute() done, defined at /home1/datahome/mdemol/.miniconda3/envs/histenv2/lib/python3.9/site-packages/distributed/worker_state_machine.py:3610>> ended with CancelledError
distributed.worker.state_machine - WARNING - Async instruction for <Task cancelled name="execute(('open_dataset-570c837613df69df97fa7d8f8b8eeb0ebox_lon-297208dbe23cd5e49e42e779656767e7', 140, 0, 0))" coro=<Worker.execute() done, defined at /home1/datahome/mdemol/.miniconda3/envs/histenv2/lib/python3.9/site-packages/distributed/worker_state_machine.py:3610>> ended with CancelledError
distributed.worker.state_machine - WARNING - Async instruction for <Task cancelled name="execute(('open_dataset-570c837613df69df97fa7d8f8b8eeb0edrifter_err_vn-af0ce8c4bde7c91e172149ea464986cb', 224, 0))" coro=<Worker.execute() done, defined at /home1/datahome/mdemol/.miniconda3/envs/histenv2/lib/python3.9/site-packages/distributed/worker_state_machine.py:3610>> ended with CancelledError
distributed.worker.state_machine - WARNING - Async instruction for <Task cancelled name="execute(('open_dataset-570c837613df69df97fa7d8f8b8eeb0ealti_y-52168659e8651f5ac3ffe5acc78abc9b', 80, 0))" coro=<Worker.execute() done, defined at /home1/datahome/mdemol/.miniconda3/envs/histenv2/lib/python3.9/site-packages/distributed/worker_state_machine.py:3610>> ended with CancelledError
distributed.worker.state_machine - WARNING - Async instruction for <Task cancelled name="execute(('open_dataset-570c837613df69df97fa7d8f8b8eeb0ealti_ggx_sla_unfiltered_noise-23b39a65bf981deca14f09b8149c59e5', 147, 0))" coro=<Worker.execute() done, defined at /home1/datahome/mdemol/.miniconda3/envs/histenv2/lib/python3.9/site-packages/distributed/worker_state_machine.py:3610>> ended with CancelledError
distributed.worker.state_machine - WARNING - Async instruction for <Task cancelled name="execute(('open_dataset-570c837613df69df97fa7d8f8b8eeb0ealti_ggx_ocean_tide-1fce07467734a1146fdd8fa92fe47659', 231, 0))" coro=<Worker.execute() done, defined at /home1/datahome/mdemol/.miniconda3/envs/histenv2/lib/python3.9/site-packages/distributed/worker_state_machine.py:3610>> ended with CancelledError
distributed.worker.state_machine - WARNING - Async instruction for <Task cancelled name="execute(('open_dataset-570c837613df69df97fa7d8f8b8eeb0ebox_lon-297208dbe23cd5e49e42e779656767e7', 181, 0, 0))" coro=<Worker.execute() done, defined at /home1/datahome/mdemol/.miniconda3/envs/histenv2/lib/python3.9/site-packages/distributed/worker_state_machine.py:3610>> ended with CancelledError
distributed.worker.state_machine - WARNING - Async instruction for <Task cancelled name="execute(('open_dataset-570c837613df69df97fa7d8f8b8eeb0edrifter_err_vn-af0ce8c4bde7c91e172149ea464986cb', 15, 0))" coro=<Worker.execute() done, defined at /home1/datahome/mdemol/.miniconda3/envs/histenv2/lib/python3.9/site-packages/distributed/worker_state_machine.py:3610>> ended with CancelledError
distributed.worker.state_machine - WARNING - Async instruction for <Task cancelled name="execute(('open_dataset-570c837613df69df97fa7d8f8b8eeb0ealti_y-52168659e8651f5ac3ffe5acc78abc9b', 146, 0))" coro=<Worker.execute() done, defined at /home1/datahome/mdemol/.miniconda3/envs/histenv2/lib/python3.9/site-packages/distributed/worker_state_machine.py:3610>> ended with CancelledError
distributed.worker.state_machine - WARNING - Async instruction for <Task cancelled name="execute(('open_dataset-570c837613df69df97fa7d8f8b8eeb0ealti_sla_unfiltered_denoised-05e64269115cc3b164d4c6abaf09cae7', 195, 0))" coro=<Worker.execute() done, defined at /home1/datahome/mdemol/.miniconda3/envs/histenv2/lib/python3.9/site-packages/distributed/worker_state_machine.py:3610>> ended with CancelledError
distributed.worker.state_machine - WARNING - Async instruction for <Task cancelled name="execute(('open_dataset-570c837613df69df97fa7d8f8b8eeb0edrifter_err_vn-af0ce8c4bde7c91e172149ea464986cb', 226, 0))" coro=<Worker.execute() done, defined at /home1/datahome/mdemol/.miniconda3/envs/histenv2/lib/python3.9/site-packages/distributed/worker_state_machine.py:3610>> ended with CancelledError
distributed.worker.state_machine - WARNING - Async instruction for <Task cancelled name="execute(('open_dataset-570c837613df69df97fa7d8f8b8eeb0ealti_y-52168659e8651f5ac3ffe5acc78abc9b', 91, 0))" coro=<Worker.execute() done, defined at /home1/datahome/mdemol/.miniconda3/envs/histenv2/lib/python3.9/site-packages/distributed/worker_state_machine.py:3610>> ended with CancelledError
distributed.worker.state_machine - WARNING - Async instruction for <Task cancelled name="execute(('open_dataset-570c837613df69df97fa7d8f8b8eeb0ealti_ggx_ocean_tide-1fce07467734a1146fdd8fa92fe47659', 176, 0))" coro=<Worker.execute() done, defined at /home1/datahome/mdemol/.miniconda3/envs/histenv2/lib/python3.9/site-packages/distributed/worker_state_machine.py:3610>> ended with CancelledError
distributed.worker.state_machine - WARNING - Async instruction for <Task cancelled name="execute(('open_dataset-570c837613df69df97fa7d8f8b8eeb0ealti_sla_unfiltered_denoised-05e64269115cc3b164d4c6abaf09cae7', 54, 0))" coro=<Worker.execute() done, defined at /home1/datahome/mdemol/.miniconda3/envs/histenv2/lib/python3.9/site-packages/distributed/worker_state_machine.py:3610>> ended with CancelledError
distributed.worker.state_machine - WARNING - Async instruction for <Task cancelled name="execute(('open_dataset-570c837613df69df97fa7d8f8b8eeb0ealti_ggx_ocean_tide-1fce07467734a1146fdd8fa92fe47659', 242, 0))" coro=<Worker.execute() done, defined at /home1/datahome/mdemol/.miniconda3/envs/histenv2/lib/python3.9/site-packages/distributed/worker_state_machine.py:3610>> ended with CancelledError
distributed.worker.state_machine - WARNING - Async instruction for <Task cancelled name="execute(('open_dataset-570c837613df69df97fa7d8f8b8eeb0ealti_ggx_sla_unfiltered_noise-23b39a65bf981deca14f09b8149c59e5', 28, 0))" coro=<Worker.execute() done, defined at /home1/datahome/mdemol/.miniconda3/envs/histenv2/lib/python3.9/site-packages/distributed/worker_state_machine.py:3610>> ended with CancelledError
distributed.worker.state_machine - WARNING - Async instruction for <Task cancelled name="execute(('open_dataset-570c837613df69df97fa7d8f8b8eeb0ealti_ggx_ocean_tide-1fce07467734a1146fdd8fa92fe47659', 121, 0))" coro=<Worker.execute() done, defined at /home1/datahome/mdemol/.miniconda3/envs/histenv2/lib/python3.9/site-packages/distributed/worker_state_machine.py:3610>> ended with CancelledError
distributed.worker.state_machine - WARNING - Async instruction for <Task cancelled name="execute(('open_dataset-570c837613df69df97fa7d8f8b8eeb0ealti_sla_unfiltered_denoised-05e64269115cc3b164d4c6abaf09cae7', 160, 0))" coro=<Worker.execute() done, defined at /home1/datahome/mdemol/.miniconda3/envs/histenv2/lib/python3.9/site-packages/distributed/worker_state_machine.py:3610>> ended with CancelledError
distributed.worker.state_machine - WARNING - Async instruction for <Task cancelled name="execute(('open_dataset-570c837613df69df97fa7d8f8b8eeb0ealti_ggx_sla_unfiltered_noise-23b39a65bf981deca14f09b8149c59e5', 200, 0))" coro=<Worker.execute() done, defined at /home1/datahome/mdemol/.miniconda3/envs/histenv2/lib/python3.9/site-packages/distributed/worker_state_machine.py:3610>> ended with CancelledError
distributed.worker.state_machine - WARNING - Async instruction for <Task cancelled name="execute(('open_dataset-570c837613df69df97fa7d8f8b8eeb0ealti_ggx_sla_unfiltered_noise-23b39a65bf981deca14f09b8149c59e5', 81, 0))" coro=<Worker.execute() done, defined at /home1/datahome/mdemol/.miniconda3/envs/histenv2/lib/python3.9/site-packages/distributed/worker_state_machine.py:3610>> ended with CancelledError
distributed.worker - ERROR - Failed to communicate with scheduler during heartbeat.
Traceback (most recent call last):
  File "/home1/datahome/mdemol/.miniconda3/envs/histenv2/lib/python3.9/site-packages/distributed/comm/tcp.py", line 224, in read
    frames_nbytes = await stream.read_bytes(fmt_size)
tornado.iostream.StreamClosedError: Stream is closed

The above exception was the direct cause of the following exception:

Traceback (most recent call last):
  File "/home1/datahome/mdemol/.miniconda3/envs/histenv2/lib/python3.9/site-packages/distributed/worker.py", line 1255, in heartbeat
    response = await retry_operation(
  File "/home1/datahome/mdemol/.miniconda3/envs/histenv2/lib/python3.9/site-packages/distributed/utils_comm.py", line 455, in retry_operation
    return await retry(
  File "/home1/datahome/mdemol/.miniconda3/envs/histenv2/lib/python3.9/site-packages/distributed/utils_comm.py", line 434, in retry
    return await coro()
  File "/home1/datahome/mdemol/.miniconda3/envs/histenv2/lib/python3.9/site-packages/distributed/core.py", line 1396, in send_recv_from_rpc
    return await send_recv(comm=comm, op=key, **kwargs)
  File "/home1/datahome/mdemol/.miniconda3/envs/histenv2/lib/python3.9/site-packages/distributed/core.py", line 1155, in send_recv
    response = await comm.read(deserializers=deserializers)
  File "/home1/datahome/mdemol/.miniconda3/envs/histenv2/lib/python3.9/site-packages/distributed/comm/tcp.py", line 240, in read
    convert_stream_closed_error(self, e)
  File "/home1/datahome/mdemol/.miniconda3/envs/histenv2/lib/python3.9/site-packages/distributed/comm/tcp.py", line 143, in convert_stream_closed_error
    raise CommClosedError(f"in {obj}: {exc}") from exc
distributed.comm.core.CommClosedError: in <TCP (closed) ConnectionPool.heartbeat_worker local=tcp://127.0.0.1:47439 remote=tcp://127.0.0.1:39593>: Stream is closed
distributed.worker - ERROR - Failed to communicate with scheduler during heartbeat.
Traceback (most recent call last):
  File "/home1/datahome/mdemol/.miniconda3/envs/histenv2/lib/python3.9/site-packages/distributed/comm/tcp.py", line 224, in read
    frames_nbytes = await stream.read_bytes(fmt_size)
tornado.iostream.StreamClosedError: Stream is closed

The above exception was the direct cause of the following exception:

Traceback (most recent call last):
  File "/home1/datahome/mdemol/.miniconda3/envs/histenv2/lib/python3.9/site-packages/distributed/worker.py", line 1255, in heartbeat
    response = await retry_operation(
  File "/home1/datahome/mdemol/.miniconda3/envs/histenv2/lib/python3.9/site-packages/distributed/utils_comm.py", line 455, in retry_operation
    return await retry(
  File "/home1/datahome/mdemol/.miniconda3/envs/histenv2/lib/python3.9/site-packages/distributed/utils_comm.py", line 434, in retry
    return await coro()
  File "/home1/datahome/mdemol/.miniconda3/envs/histenv2/lib/python3.9/site-packages/distributed/core.py", line 1396, in send_recv_from_rpc
    return await send_recv(comm=comm, op=key, **kwargs)
  File "/home1/datahome/mdemol/.miniconda3/envs/histenv2/lib/python3.9/site-packages/distributed/core.py", line 1155, in send_recv
    response = await comm.read(deserializers=deserializers)
  File "/home1/datahome/mdemol/.miniconda3/envs/histenv2/lib/python3.9/site-packages/distributed/comm/tcp.py", line 240, in read
    convert_stream_closed_error(self, e)
  File "/home1/datahome/mdemol/.miniconda3/envs/histenv2/lib/python3.9/site-packages/distributed/comm/tcp.py", line 143, in convert_stream_closed_error
    raise CommClosedError(f"in {obj}: {exc}") from exc
distributed.comm.core.CommClosedError: in <TCP (closed) ConnectionPool.heartbeat_worker local=tcp://127.0.0.1:47438 remote=tcp://127.0.0.1:39593>: Stream is closed
distributed.worker - ERROR - Failed to communicate with scheduler during heartbeat.
Traceback (most recent call last):
  File "/home1/datahome/mdemol/.miniconda3/envs/histenv2/lib/python3.9/site-packages/distributed/comm/tcp.py", line 224, in read
    frames_nbytes = await stream.read_bytes(fmt_size)
tornado.iostream.StreamClosedError: Stream is closed

The above exception was the direct cause of the following exception:

Traceback (most recent call last):
  File "/home1/datahome/mdemol/.miniconda3/envs/histenv2/lib/python3.9/site-packages/distributed/worker.py", line 1255, in heartbeat
    response = await retry_operation(
  File "/home1/datahome/mdemol/.miniconda3/envs/histenv2/lib/python3.9/site-packages/distributed/utils_comm.py", line 455, in retry_operation
    return await retry(
  File "/home1/datahome/mdemol/.miniconda3/envs/histenv2/lib/python3.9/site-packages/distributed/utils_comm.py", line 434, in retry
    return await coro()
  File "/home1/datahome/mdemol/.miniconda3/envs/histenv2/lib/python3.9/site-packages/distributed/core.py", line 1396, in send_recv_from_rpc
    return await send_recv(comm=comm, op=key, **kwargs)
  File "/home1/datahome/mdemol/.miniconda3/envs/histenv2/lib/python3.9/site-packages/distributed/core.py", line 1155, in send_recv
    response = await comm.read(deserializers=deserializers)
  File "/home1/datahome/mdemol/.miniconda3/envs/histenv2/lib/python3.9/site-packages/distributed/comm/tcp.py", line 240, in read
    convert_stream_closed_error(self, e)
  File "/home1/datahome/mdemol/.miniconda3/envs/histenv2/lib/python3.9/site-packages/distributed/comm/tcp.py", line 143, in convert_stream_closed_error
    raise CommClosedError(f"in {obj}: {exc}") from exc
distributed.comm.core.CommClosedError: in <TCP (closed) ConnectionPool.heartbeat_worker local=tcp://127.0.0.1:47440 remote=tcp://127.0.0.1:39593>: Stream is closed
distributed.worker - ERROR - Failed to communicate with scheduler during heartbeat.
Traceback (most recent call last):
  File "/home1/datahome/mdemol/.miniconda3/envs/histenv2/lib/python3.9/site-packages/distributed/comm/tcp.py", line 224, in read
    frames_nbytes = await stream.read_bytes(fmt_size)
tornado.iostream.StreamClosedError: Stream is closed

The above exception was the direct cause of the following exception:

Traceback (most recent call last):
  File "/home1/datahome/mdemol/.miniconda3/envs/histenv2/lib/python3.9/site-packages/distributed/worker.py", line 1255, in heartbeat
    response = await retry_operation(
  File "/home1/datahome/mdemol/.miniconda3/envs/histenv2/lib/python3.9/site-packages/distributed/utils_comm.py", line 455, in retry_operation
    return await retry(
  File "/home1/datahome/mdemol/.miniconda3/envs/histenv2/lib/python3.9/site-packages/distributed/utils_comm.py", line 434, in retry
    return await coro()
  File "/home1/datahome/mdemol/.miniconda3/envs/histenv2/lib/python3.9/site-packages/distributed/core.py", line 1396, in send_recv_from_rpc
    return await send_recv(comm=comm, op=key, **kwargs)
  File "/home1/datahome/mdemol/.miniconda3/envs/histenv2/lib/python3.9/site-packages/distributed/core.py", line 1155, in send_recv
    response = await comm.read(deserializers=deserializers)
  File "/home1/datahome/mdemol/.miniconda3/envs/histenv2/lib/python3.9/site-packages/distributed/comm/tcp.py", line 240, in read
    convert_stream_closed_error(self, e)
  File "/home1/datahome/mdemol/.miniconda3/envs/histenv2/lib/python3.9/site-packages/distributed/comm/tcp.py", line 143, in convert_stream_closed_error
    raise CommClosedError(f"in {obj}: {exc}") from exc
distributed.comm.core.CommClosedError: in <TCP (closed) ConnectionPool.heartbeat_worker local=tcp://127.0.0.1:47436 remote=tcp://127.0.0.1:39593>: Stream is closed
distributed.worker - ERROR - Failed to communicate with scheduler during heartbeat.
Traceback (most recent call last):
  File "/home1/datahome/mdemol/.miniconda3/envs/histenv2/lib/python3.9/site-packages/distributed/comm/tcp.py", line 224, in read
    frames_nbytes = await stream.read_bytes(fmt_size)
tornado.iostream.StreamClosedError: Stream is closed

The above exception was the direct cause of the following exception:

Traceback (most recent call last):
  File "/home1/datahome/mdemol/.miniconda3/envs/histenv2/lib/python3.9/site-packages/distributed/worker.py", line 1255, in heartbeat
    response = await retry_operation(
  File "/home1/datahome/mdemol/.miniconda3/envs/histenv2/lib/python3.9/site-packages/distributed/utils_comm.py", line 455, in retry_operation
    return await retry(
  File "/home1/datahome/mdemol/.miniconda3/envs/histenv2/lib/python3.9/site-packages/distributed/utils_comm.py", line 434, in retry
    return await coro()
  File "/home1/datahome/mdemol/.miniconda3/envs/histenv2/lib/python3.9/site-packages/distributed/core.py", line 1396, in send_recv_from_rpc
    return await send_recv(comm=comm, op=key, **kwargs)
  File "/home1/datahome/mdemol/.miniconda3/envs/histenv2/lib/python3.9/site-packages/distributed/core.py", line 1155, in send_recv
    response = await comm.read(deserializers=deserializers)
  File "/home1/datahome/mdemol/.miniconda3/envs/histenv2/lib/python3.9/site-packages/distributed/comm/tcp.py", line 240, in read
    convert_stream_closed_error(self, e)
  File "/home1/datahome/mdemol/.miniconda3/envs/histenv2/lib/python3.9/site-packages/distributed/comm/tcp.py", line 143, in convert_stream_closed_error
    raise CommClosedError(f"in {obj}: {exc}") from exc
distributed.comm.core.CommClosedError: in <TCP (closed) ConnectionPool.heartbeat_worker local=tcp://127.0.0.1:47437 remote=tcp://127.0.0.1:39593>: Stream is closed
distributed.worker - ERROR - Failed to communicate with scheduler during heartbeat.
Traceback (most recent call last):
  File "/home1/datahome/mdemol/.miniconda3/envs/histenv2/lib/python3.9/site-packages/distributed/comm/tcp.py", line 224, in read
    frames_nbytes = await stream.read_bytes(fmt_size)
tornado.iostream.StreamClosedError: Stream is closed

The above exception was the direct cause of the following exception:

Traceback (most recent call last):
  File "/home1/datahome/mdemol/.miniconda3/envs/histenv2/lib/python3.9/site-packages/distributed/worker.py", line 1255, in heartbeat
    response = await retry_operation(
  File "/home1/datahome/mdemol/.miniconda3/envs/histenv2/lib/python3.9/site-packages/distributed/utils_comm.py", line 455, in retry_operation
    return await retry(
  File "/home1/datahome/mdemol/.miniconda3/envs/histenv2/lib/python3.9/site-packages/distributed/utils_comm.py", line 434, in retry
    return await coro()
  File "/home1/datahome/mdemol/.miniconda3/envs/histenv2/lib/python3.9/site-packages/distributed/core.py", line 1396, in send_recv_from_rpc
    return await send_recv(comm=comm, op=key, **kwargs)
  File "/home1/datahome/mdemol/.miniconda3/envs/histenv2/lib/python3.9/site-packages/distributed/core.py", line 1155, in send_recv
    response = await comm.read(deserializers=deserializers)
  File "/home1/datahome/mdemol/.miniconda3/envs/histenv2/lib/python3.9/site-packages/distributed/comm/tcp.py", line 240, in read
    convert_stream_closed_error(self, e)
  File "/home1/datahome/mdemol/.miniconda3/envs/histenv2/lib/python3.9/site-packages/distributed/comm/tcp.py", line 143, in convert_stream_closed_error
    raise CommClosedError(f"in {obj}: {exc}") from exc
distributed.comm.core.CommClosedError: in <TCP (closed) ConnectionPool.heartbeat_worker local=tcp://127.0.0.1:47442 remote=tcp://127.0.0.1:39593>: Stream is closed
[I 2023-11-08 16:19:26.909 ServerApp] Kernel restarted: 0c9943f3-3d6f-4638-9a45-412a87b2f67e
[I 2023-11-08 16:19:26.913 ServerApp] Starting buffering for 0c9943f3-3d6f-4638-9a45-412a87b2f67e:97f72f23-a1ab-4804-b973-d5a064af9a2c
[I 2023-11-08 16:19:26.922 ServerApp] Connecting to kernel 0c9943f3-3d6f-4638-9a45-412a87b2f67e.
[I 2023-11-08 16:19:26.922 ServerApp] Restoring connection for 0c9943f3-3d6f-4638-9a45-412a87b2f67e:97f72f23-a1ab-4804-b973-d5a064af9a2c
readline: /etc/inputrc: line 19: term: unknown variable name
[I 2023-11-08 16:19:44.422 ServerApp] Kernel restarted: 0c9943f3-3d6f-4638-9a45-412a87b2f67e
[I 2023-11-08 16:19:44.428 ServerApp] Starting buffering for 0c9943f3-3d6f-4638-9a45-412a87b2f67e:97f72f23-a1ab-4804-b973-d5a064af9a2c
[I 2023-11-08 16:19:44.437 ServerApp] Connecting to kernel 0c9943f3-3d6f-4638-9a45-412a87b2f67e.
[I 2023-11-08 16:19:44.437 ServerApp] Restoring connection for 0c9943f3-3d6f-4638-9a45-412a87b2f67e:97f72f23-a1ab-4804-b973-d5a064af9a2c
readline: /etc/inputrc: line 19: term: unknown variable name
/home1/datahome/mdemol/.miniconda3/envs/histenv2/lib/python3.9/site-packages/dask/config.py:742: FutureWarning: Dask configuration key 'distributed.scheduler.transition-log-length' has been deprecated; please use 'distributed.admin.low-level-log-length' instead
  warnings.warn(
/home1/datahome/mdemol/.miniconda3/envs/histenv2/lib/python3.9/site-packages/dask/config.py:742: FutureWarning: Dask configuration key 'distributed.comm.recent-messages-log-length' has been deprecated; please use 'distributed.admin.low-level-log-length' instead
  warnings.warn(
/home1/datahome/mdemol/.miniconda3/envs/histenv2/lib/python3.9/site-packages/dask/config.py:742: FutureWarning: Dask configuration key 'distributed.scheduler.transition-log-length' has been deprecated; please use 'distributed.admin.low-level-log-length' instead
  warnings.warn(
/home1/datahome/mdemol/.miniconda3/envs/histenv2/lib/python3.9/site-packages/dask/config.py:742: FutureWarning: Dask configuration key 'distributed.comm.recent-messages-log-length' has been deprecated; please use 'distributed.admin.low-level-log-length' instead
  warnings.warn(
/home1/datahome/mdemol/.miniconda3/envs/histenv2/lib/python3.9/site-packages/dask/config.py:742: FutureWarning: Dask configuration key 'distributed.scheduler.transition-log-length' has been deprecated; please use 'distributed.admin.low-level-log-length' instead
  warnings.warn(
/home1/datahome/mdemol/.miniconda3/envs/histenv2/lib/python3.9/site-packages/dask/config.py:742: FutureWarning: Dask configuration key 'distributed.comm.recent-messages-log-length' has been deprecated; please use 'distributed.admin.low-level-log-length' instead
  warnings.warn(
/home1/datahome/mdemol/.miniconda3/envs/histenv2/lib/python3.9/site-packages/dask/config.py:742: FutureWarning: Dask configuration key 'distributed.scheduler.transition-log-length' has been deprecated; please use 'distributed.admin.low-level-log-length' instead
  warnings.warn(
/home1/datahome/mdemol/.miniconda3/envs/histenv2/lib/python3.9/site-packages/dask/config.py:742: FutureWarning: Dask configuration key 'distributed.comm.recent-messages-log-length' has been deprecated; please use 'distributed.admin.low-level-log-length' instead
  warnings.warn(
/home1/datahome/mdemol/.miniconda3/envs/histenv2/lib/python3.9/site-packages/dask/config.py:742: FutureWarning: Dask configuration key 'distributed.scheduler.transition-log-length' has been deprecated; please use 'distributed.admin.low-level-log-length' instead
  warnings.warn(
/home1/datahome/mdemol/.miniconda3/envs/histenv2/lib/python3.9/site-packages/dask/config.py:742: FutureWarning: Dask configuration key 'distributed.comm.recent-messages-log-length' has been deprecated; please use 'distributed.admin.low-level-log-length' instead
  warnings.warn(
/home1/datahome/mdemol/.miniconda3/envs/histenv2/lib/python3.9/site-packages/dask/config.py:742: FutureWarning: Dask configuration key 'distributed.scheduler.transition-log-length' has been deprecated; please use 'distributed.admin.low-level-log-length' instead
  warnings.warn(
/home1/datahome/mdemol/.miniconda3/envs/histenv2/lib/python3.9/site-packages/dask/config.py:742: FutureWarning: Dask configuration key 'distributed.scheduler.transition-log-length' has been deprecated; please use 'distributed.admin.low-level-log-length' instead
  warnings.warn(
/home1/datahome/mdemol/.miniconda3/envs/histenv2/lib/python3.9/site-packages/dask/config.py:742: FutureWarning: Dask configuration key 'distributed.comm.recent-messages-log-length' has been deprecated; please use 'distributed.admin.low-level-log-length' instead
  warnings.warn(
/home1/datahome/mdemol/.miniconda3/envs/histenv2/lib/python3.9/site-packages/dask/config.py:742: FutureWarning: Dask configuration key 'distributed.comm.recent-messages-log-length' has been deprecated; please use 'distributed.admin.low-level-log-length' instead
  warnings.warn(
/home1/datahome/mdemol/.miniconda3/envs/histenv2/lib/python3.9/site-packages/dask/config.py:742: FutureWarning: Dask configuration key 'distributed.scheduler.transition-log-length' has been deprecated; please use 'distributed.admin.low-level-log-length' instead
  warnings.warn(
/home1/datahome/mdemol/.miniconda3/envs/histenv2/lib/python3.9/site-packages/dask/config.py:742: FutureWarning: Dask configuration key 'distributed.comm.recent-messages-log-length' has been deprecated; please use 'distributed.admin.low-level-log-length' instead
  warnings.warn(
/home1/datahome/mdemol/.miniconda3/envs/histenv2/lib/python3.9/site-packages/dask/config.py:742: FutureWarning: Dask configuration key 'distributed.scheduler.transition-log-length' has been deprecated; please use 'distributed.admin.low-level-log-length' instead
  warnings.warn(
/home1/datahome/mdemol/.miniconda3/envs/histenv2/lib/python3.9/site-packages/dask/config.py:742: FutureWarning: Dask configuration key 'distributed.comm.recent-messages-log-length' has been deprecated; please use 'distributed.admin.low-level-log-length' instead
  warnings.warn(
/home1/datahome/mdemol/.miniconda3/envs/histenv2/lib/python3.9/site-packages/xarray/coding/times.py:228: RuntimeWarning: invalid value encountered in cast
  flat_num_dates_ns_int = (flat_num_dates * _NS_PER_TIME_DELTA[delta]).astype(
/home1/datahome/mdemol/.miniconda3/envs/histenv2/lib/python3.9/site-packages/xarray/coding/times.py:228: RuntimeWarning: invalid value encountered in cast
  flat_num_dates_ns_int = (flat_num_dates * _NS_PER_TIME_DELTA[delta]).astype(
/home1/datahome/mdemol/.miniconda3/envs/histenv2/lib/python3.9/site-packages/xarray/coding/times.py:228: RuntimeWarning: invalid value encountered in cast
  flat_num_dates_ns_int = (flat_num_dates * _NS_PER_TIME_DELTA[delta]).astype(
/home1/datahome/mdemol/.miniconda3/envs/histenv2/lib/python3.9/site-packages/xarray/coding/times.py:228: RuntimeWarning: invalid value encountered in cast
  flat_num_dates_ns_int = (flat_num_dates * _NS_PER_TIME_DELTA[delta]).astype(
/home1/datahome/mdemol/.miniconda3/envs/histenv2/lib/python3.9/site-packages/xarray/coding/times.py:228: RuntimeWarning: invalid value encountered in cast
  flat_num_dates_ns_int = (flat_num_dates * _NS_PER_TIME_DELTA[delta]).astype(
/home1/datahome/mdemol/.miniconda3/envs/histenv2/lib/python3.9/site-packages/xarray/coding/times.py:228: RuntimeWarning: invalid value encountered in cast
  flat_num_dates_ns_int = (flat_num_dates * _NS_PER_TIME_DELTA[delta]).astype(
/home1/datahome/mdemol/.miniconda3/envs/histenv2/lib/python3.9/site-packages/xarray/coding/times.py:228: RuntimeWarning: invalid value encountered in cast
  flat_num_dates_ns_int = (flat_num_dates * _NS_PER_TIME_DELTA[delta]).astype(
/home1/datahome/mdemol/.miniconda3/envs/histenv2/lib/python3.9/site-packages/xarray/coding/times.py:228: RuntimeWarning: invalid value encountered in cast
  flat_num_dates_ns_int = (flat_num_dates * _NS_PER_TIME_DELTA[delta]).astype(
/home1/datahome/mdemol/.miniconda3/envs/histenv2/lib/python3.9/site-packages/xarray/coding/times.py:228: RuntimeWarning: invalid value encountered in cast
  flat_num_dates_ns_int = (flat_num_dates * _NS_PER_TIME_DELTA[delta]).astype(
/home1/datahome/mdemol/.miniconda3/envs/histenv2/lib/python3.9/site-packages/xarray/coding/times.py:228: RuntimeWarning: invalid value encountered in cast
  flat_num_dates_ns_int = (flat_num_dates * _NS_PER_TIME_DELTA[delta]).astype(
/home1/datahome/mdemol/.miniconda3/envs/histenv2/lib/python3.9/site-packages/xarray/coding/times.py:228: RuntimeWarning: invalid value encountered in cast
  flat_num_dates_ns_int = (flat_num_dates * _NS_PER_TIME_DELTA[delta]).astype(
/home1/datahome/mdemol/.miniconda3/envs/histenv2/lib/python3.9/site-packages/xarray/coding/times.py:228: RuntimeWarning: invalid value encountered in cast
  flat_num_dates_ns_int = (flat_num_dates * _NS_PER_TIME_DELTA[delta]).astype(
/home1/datahome/mdemol/.miniconda3/envs/histenv2/lib/python3.9/site-packages/xarray/coding/times.py:228: RuntimeWarning: invalid value encountered in cast
  flat_num_dates_ns_int = (flat_num_dates * _NS_PER_TIME_DELTA[delta]).astype(
/home1/datahome/mdemol/.miniconda3/envs/histenv2/lib/python3.9/site-packages/xarray/coding/times.py:228: RuntimeWarning: invalid value encountered in cast
  flat_num_dates_ns_int = (flat_num_dates * _NS_PER_TIME_DELTA[delta]).astype(
/home1/datahome/mdemol/.miniconda3/envs/histenv2/lib/python3.9/site-packages/xarray/coding/times.py:228: RuntimeWarning: invalid value encountered in cast
  flat_num_dates_ns_int = (flat_num_dates * _NS_PER_TIME_DELTA[delta]).astype(
/home1/datahome/mdemol/.miniconda3/envs/histenv2/lib/python3.9/site-packages/xarray/coding/times.py:228: RuntimeWarning: invalid value encountered in cast
  flat_num_dates_ns_int = (flat_num_dates * _NS_PER_TIME_DELTA[delta]).astype(
/home1/datahome/mdemol/.miniconda3/envs/histenv2/lib/python3.9/site-packages/xarray/coding/times.py:228: RuntimeWarning: invalid value encountered in cast
  flat_num_dates_ns_int = (flat_num_dates * _NS_PER_TIME_DELTA[delta]).astype(
/home1/datahome/mdemol/.miniconda3/envs/histenv2/lib/python3.9/site-packages/xarray/coding/times.py:228: RuntimeWarning: invalid value encountered in cast
  flat_num_dates_ns_int = (flat_num_dates * _NS_PER_TIME_DELTA[delta]).astype(
/home1/datahome/mdemol/.miniconda3/envs/histenv2/lib/python3.9/site-packages/xarray/coding/times.py:228: RuntimeWarning: invalid value encountered in cast
  flat_num_dates_ns_int = (flat_num_dates * _NS_PER_TIME_DELTA[delta]).astype(
/home1/datahome/mdemol/.miniconda3/envs/histenv2/lib/python3.9/site-packages/xarray/coding/times.py:228: RuntimeWarning: invalid value encountered in cast
  flat_num_dates_ns_int = (flat_num_dates * _NS_PER_TIME_DELTA[delta]).astype(
/home1/datahome/mdemol/.miniconda3/envs/histenv2/lib/python3.9/site-packages/xarray/coding/times.py:228: RuntimeWarning: invalid value encountered in cast
  flat_num_dates_ns_int = (flat_num_dates * _NS_PER_TIME_DELTA[delta]).astype(
/home1/datahome/mdemol/.miniconda3/envs/histenv2/lib/python3.9/site-packages/xarray/coding/times.py:228: RuntimeWarning: invalid value encountered in cast
  flat_num_dates_ns_int = (flat_num_dates * _NS_PER_TIME_DELTA[delta]).astype(
/home1/datahome/mdemol/.miniconda3/envs/histenv2/lib/python3.9/site-packages/xarray/coding/times.py:228: RuntimeWarning: invalid value encountered in cast
  flat_num_dates_ns_int = (flat_num_dates * _NS_PER_TIME_DELTA[delta]).astype(
/home1/datahome/mdemol/.miniconda3/envs/histenv2/lib/python3.9/site-packages/xarray/coding/times.py:228: RuntimeWarning: invalid value encountered in cast
  flat_num_dates_ns_int = (flat_num_dates * _NS_PER_TIME_DELTA[delta]).astype(
/home1/datahome/mdemol/.miniconda3/envs/histenv2/lib/python3.9/site-packages/xarray/coding/times.py:228: RuntimeWarning: invalid value encountered in cast
  flat_num_dates_ns_int = (flat_num_dates * _NS_PER_TIME_DELTA[delta]).astype(
/home1/datahome/mdemol/.miniconda3/envs/histenv2/lib/python3.9/site-packages/xarray/coding/times.py:228: RuntimeWarning: invalid value encountered in cast
  flat_num_dates_ns_int = (flat_num_dates * _NS_PER_TIME_DELTA[delta]).astype(
/home1/datahome/mdemol/.miniconda3/envs/histenv2/lib/python3.9/site-packages/xarray/coding/times.py:228: RuntimeWarning: invalid value encountered in cast
  flat_num_dates_ns_int = (flat_num_dates * _NS_PER_TIME_DELTA[delta]).astype(
/home1/datahome/mdemol/.miniconda3/envs/histenv2/lib/python3.9/site-packages/xarray/coding/times.py:228: RuntimeWarning: invalid value encountered in cast
  flat_num_dates_ns_int = (flat_num_dates * _NS_PER_TIME_DELTA[delta]).astype(
/home1/datahome/mdemol/.miniconda3/envs/histenv2/lib/python3.9/site-packages/xarray/coding/times.py:228: RuntimeWarning: invalid value encountered in cast
  flat_num_dates_ns_int = (flat_num_dates * _NS_PER_TIME_DELTA[delta]).astype(
/home1/datahome/mdemol/.miniconda3/envs/histenv2/lib/python3.9/site-packages/xarray/coding/times.py:228: RuntimeWarning: invalid value encountered in cast
  flat_num_dates_ns_int = (flat_num_dates * _NS_PER_TIME_DELTA[delta]).astype(
/home1/datahome/mdemol/.miniconda3/envs/histenv2/lib/python3.9/site-packages/xarray/coding/times.py:228: RuntimeWarning: invalid value encountered in cast
  flat_num_dates_ns_int = (flat_num_dates * _NS_PER_TIME_DELTA[delta]).astype(
/home1/datahome/mdemol/.miniconda3/envs/histenv2/lib/python3.9/site-packages/xarray/coding/times.py:228: RuntimeWarning: invalid value encountered in cast
  flat_num_dates_ns_int = (flat_num_dates * _NS_PER_TIME_DELTA[delta]).astype(
[I 2023-11-08 16:20:22.903 ServerApp] Saving file at /historical_analysis/21_zarr_aviso.ipynb
[I 2023-11-08 16:20:47.597 ServerApp] Starting buffering for 0c9943f3-3d6f-4638-9a45-412a87b2f67e:97f72f23-a1ab-4804-b973-d5a064af9a2c
[I 2023-11-08 16:20:47.598 ServerApp] Starting buffering for eb780ec5-cfa5-4b7a-9f59-bd4370f51e8b:2bee6008-8591-419e-8b7e-85aa2a5534cf
[W 2023-11-08 16:20:49.069 LabApp] Could not determine jupyterlab build status without nodejs
[I 2023-11-08 16:20:49.151 ServerApp] Connecting to kernel 0c9943f3-3d6f-4638-9a45-412a87b2f67e.
[I 2023-11-08 16:20:49.164 ServerApp] Connecting to kernel eb780ec5-cfa5-4b7a-9f59-bd4370f51e8b.
[I 2023-11-08 16:20:49.166 ServerApp] Connecting to kernel b667e96e-306a-4540-9aab-98c57fd5da5c.
[I 2023-11-08 16:20:49.264 ServerApp] Starting buffering for 0c9943f3-3d6f-4638-9a45-412a87b2f67e:31f73e0b-3552-4f02-aff4-7eb45f2fd679
[I 2023-11-08 16:20:49.265 ServerApp] Starting buffering for b667e96e-306a-4540-9aab-98c57fd5da5c:e2922566-aa42-4565-8596-b57d5ae19307
[I 2023-11-08 16:20:49.265 ServerApp] Starting buffering for eb780ec5-cfa5-4b7a-9f59-bd4370f51e8b:f9286ade-f087-42c4-a4d6-40b388006b6d
[I 2023-11-08 16:20:50.698 ServerApp] Connecting to kernel eb780ec5-cfa5-4b7a-9f59-bd4370f51e8b.
[I 2023-11-08 16:20:50.700 ServerApp] Connecting to kernel 0c9943f3-3d6f-4638-9a45-412a87b2f67e.
[I 2023-11-08 16:20:56.277 ServerApp] Starting buffering for 0c9943f3-3d6f-4638-9a45-412a87b2f67e:4cb5aba1-33a8-49cd-8e45-64595e6ea0f8
[I 2023-11-08 16:20:56.278 ServerApp] Starting buffering for eb780ec5-cfa5-4b7a-9f59-bd4370f51e8b:ed7b04ba-e864-4414-9433-4f1ba6157de4
[W 2023-11-08 16:20:57.599 LabApp] Could not determine jupyterlab build status without nodejs
[I 2023-11-08 16:20:57.656 ServerApp] Connecting to kernel 0c9943f3-3d6f-4638-9a45-412a87b2f67e.
[I 2023-11-08 16:20:57.664 ServerApp] Connecting to kernel eb780ec5-cfa5-4b7a-9f59-bd4370f51e8b.
[I 2023-11-08 16:20:57.666 ServerApp] Connecting to kernel b667e96e-306a-4540-9aab-98c57fd5da5c.
[I 2023-11-08 16:20:57.752 ServerApp] Starting buffering for 0c9943f3-3d6f-4638-9a45-412a87b2f67e:33b57381-1fb9-4c0e-8659-5cc824ef302d
[I 2023-11-08 16:20:57.752 ServerApp] Starting buffering for b667e96e-306a-4540-9aab-98c57fd5da5c:5ceabc9a-bf03-48e8-a3e6-cdfdd46cef4d
[I 2023-11-08 16:20:57.753 ServerApp] Starting buffering for eb780ec5-cfa5-4b7a-9f59-bd4370f51e8b:9d8d6a04-6edf-40de-a51c-0eca621e5866
[I 2023-11-08 16:20:58.734 ServerApp] Connecting to kernel 0c9943f3-3d6f-4638-9a45-412a87b2f67e.
[I 2023-11-08 16:20:58.737 ServerApp] Connecting to kernel eb780ec5-cfa5-4b7a-9f59-bd4370f51e8b.
[I 2023-11-08 16:21:00.776 ServerApp] Starting buffering for eb780ec5-cfa5-4b7a-9f59-bd4370f51e8b:c6cbd015-60b5-4d2a-8c71-a23ba001e0c8
[I 2023-11-08 16:21:00.777 ServerApp] Starting buffering for 0c9943f3-3d6f-4638-9a45-412a87b2f67e:e0e13911-a567-4a3f-ad78-fde7b6ce53e5
[W 2023-11-08 16:21:12.277 LabApp] Could not determine jupyterlab build status without nodejs
[I 2023-11-08 16:21:12.341 ServerApp] Connecting to kernel eb780ec5-cfa5-4b7a-9f59-bd4370f51e8b.
[I 2023-11-08 16:21:12.343 ServerApp] Connecting to kernel 0c9943f3-3d6f-4638-9a45-412a87b2f67e.
[I 2023-11-08 16:21:12.349 ServerApp] Connecting to kernel b667e96e-306a-4540-9aab-98c57fd5da5c.
[I 2023-11-08 16:21:12.495 ServerApp] Starting buffering for 0c9943f3-3d6f-4638-9a45-412a87b2f67e:936cd89f-5894-4dc8-8457-5f55a94311bd
[I 2023-11-08 16:21:12.495 ServerApp] Starting buffering for eb780ec5-cfa5-4b7a-9f59-bd4370f51e8b:e298a6e7-8465-4be3-8853-7d3ce81825d5
[I 2023-11-08 16:21:12.496 ServerApp] Starting buffering for b667e96e-306a-4540-9aab-98c57fd5da5c:8fcd35ef-d2df-425a-87cb-3c0a71305665
[I 2023-11-08 16:21:13.780 ServerApp] Connecting to kernel 0c9943f3-3d6f-4638-9a45-412a87b2f67e.
[I 2023-11-08 16:21:13.782 ServerApp] Connecting to kernel eb780ec5-cfa5-4b7a-9f59-bd4370f51e8b.
[I 2023-11-08 16:21:23.223 ServerApp] Kernel restarted: 0c9943f3-3d6f-4638-9a45-412a87b2f67e
[I 2023-11-08 16:21:23.232 ServerApp] Starting buffering for 0c9943f3-3d6f-4638-9a45-412a87b2f67e:f4fcd24d-5b23-40ed-9eb0-3e41de97cba8
[I 2023-11-08 16:21:23.242 ServerApp] Connecting to kernel 0c9943f3-3d6f-4638-9a45-412a87b2f67e.
[I 2023-11-08 16:21:23.242 ServerApp] Restoring connection for 0c9943f3-3d6f-4638-9a45-412a87b2f67e:f4fcd24d-5b23-40ed-9eb0-3e41de97cba8
readline: /etc/inputrc: line 19: term: unknown variable name
[I 2023-11-08 16:23:13.336 ServerApp] Saving file at /historical_analysis/21_zarr_aviso.ipynb
[I 2023-11-08 16:24:03.047 ServerApp] Starting buffering for 0c9943f3-3d6f-4638-9a45-412a87b2f67e:f4fcd24d-5b23-40ed-9eb0-3e41de97cba8
[I 2023-11-08 16:24:03.048 ServerApp] Starting buffering for eb780ec5-cfa5-4b7a-9f59-bd4370f51e8b:3de20767-1996-48a5-a535-1535b5877a0d
[W 2023-11-08 16:24:04.400 LabApp] Could not determine jupyterlab build status without nodejs
[I 2023-11-08 16:24:04.456 ServerApp] Connecting to kernel 0c9943f3-3d6f-4638-9a45-412a87b2f67e.
[I 2023-11-08 16:24:04.457 ServerApp] Discarding 1 buffered messages for 0c9943f3-3d6f-4638-9a45-412a87b2f67e:f4fcd24d-5b23-40ed-9eb0-3e41de97cba8
[I 2023-11-08 16:24:04.459 ServerApp] Connecting to kernel eb780ec5-cfa5-4b7a-9f59-bd4370f51e8b.
[I 2023-11-08 16:24:04.461 ServerApp] Connecting to kernel b667e96e-306a-4540-9aab-98c57fd5da5c.
[I 2023-11-08 16:24:04.588 ServerApp] Starting buffering for eb780ec5-cfa5-4b7a-9f59-bd4370f51e8b:f3a01179-6f66-434e-a950-eba26db7f33a
[I 2023-11-08 16:24:04.588 ServerApp] Starting buffering for b667e96e-306a-4540-9aab-98c57fd5da5c:be7002da-98f9-49b6-82c3-d1d69edbb0f2
[I 2023-11-08 16:24:05.964 ServerApp] Connecting to kernel 0c9943f3-3d6f-4638-9a45-412a87b2f67e.
[I 2023-11-08 16:24:05.969 ServerApp] Connecting to kernel eb780ec5-cfa5-4b7a-9f59-bd4370f51e8b.
[I 2023-11-08 16:24:10.307 ServerApp] Starting buffering for eb780ec5-cfa5-4b7a-9f59-bd4370f51e8b:c5ed89ce-4776-41f1-883f-2a094738c328
[I 2023-11-08 16:24:10.308 ServerApp] Starting buffering for 0c9943f3-3d6f-4638-9a45-412a87b2f67e:abc86d60-0586-4308-83c3-210cbf52a297
[W 2023-11-08 16:24:15.350 LabApp] Could not determine jupyterlab build status without nodejs
[I 2023-11-08 16:24:15.418 ServerApp] Connecting to kernel eb780ec5-cfa5-4b7a-9f59-bd4370f51e8b.
[I 2023-11-08 16:24:15.421 ServerApp] Connecting to kernel 0c9943f3-3d6f-4638-9a45-412a87b2f67e.
[I 2023-11-08 16:24:15.421 ServerApp] Discarding 1 buffered messages for 0c9943f3-3d6f-4638-9a45-412a87b2f67e:abc86d60-0586-4308-83c3-210cbf52a297
[I 2023-11-08 16:24:15.426 ServerApp] Connecting to kernel b667e96e-306a-4540-9aab-98c57fd5da5c.
[I 2023-11-08 16:24:15.512 ServerApp] Starting buffering for eb780ec5-cfa5-4b7a-9f59-bd4370f51e8b:704d19f6-6fa3-45fa-9c79-88fdfc5d1228
[I 2023-11-08 16:24:15.517 ServerApp] Starting buffering for b667e96e-306a-4540-9aab-98c57fd5da5c:f9c76e8f-f062-4eb1-ab0e-ba01031d0199
[I 2023-11-08 16:24:16.547 ServerApp] Connecting to kernel 0c9943f3-3d6f-4638-9a45-412a87b2f67e.
[I 2023-11-08 16:24:16.549 ServerApp] Connecting to kernel eb780ec5-cfa5-4b7a-9f59-bd4370f51e8b.
[I 2023-11-08 16:24:28.039 ServerApp] Kernel interrupted: 0c9943f3-3d6f-4638-9a45-412a87b2f67e
[I 2023-11-08 16:24:28.217 ServerApp] Kernel interrupted: 0c9943f3-3d6f-4638-9a45-412a87b2f67e
[I 2023-11-08 16:24:28.434 ServerApp] Kernel interrupted: 0c9943f3-3d6f-4638-9a45-412a87b2f67e
[I 2023-11-08 16:24:36.392 ServerApp] Kernel restarted: 0c9943f3-3d6f-4638-9a45-412a87b2f67e
[I 2023-11-08 16:24:36.398 ServerApp] Starting buffering for 0c9943f3-3d6f-4638-9a45-412a87b2f67e:b3fc5bb3-4ddf-4349-81a2-6abd7d2d9af8
[I 2023-11-08 16:24:36.407 ServerApp] Connecting to kernel 0c9943f3-3d6f-4638-9a45-412a87b2f67e.
[I 2023-11-08 16:24:36.407 ServerApp] Restoring connection for 0c9943f3-3d6f-4638-9a45-412a87b2f67e:b3fc5bb3-4ddf-4349-81a2-6abd7d2d9af8
readline: /etc/inputrc: line 19: term: unknown variable name
[I 2023-11-08 16:25:01.545 ServerApp] Starting buffering for 0c9943f3-3d6f-4638-9a45-412a87b2f67e:b3fc5bb3-4ddf-4349-81a2-6abd7d2d9af8
[I 2023-11-08 16:25:01.545 ServerApp] Starting buffering for eb780ec5-cfa5-4b7a-9f59-bd4370f51e8b:c01a0dfe-b6f4-4dfd-afda-ac270bfb0046
[W 2023-11-08 16:25:06.551 LabApp] Could not determine jupyterlab build status without nodejs
[I 2023-11-08 16:25:06.599 ServerApp] Connecting to kernel 0c9943f3-3d6f-4638-9a45-412a87b2f67e.
[I 2023-11-08 16:25:06.607 ServerApp] Connecting to kernel eb780ec5-cfa5-4b7a-9f59-bd4370f51e8b.
[I 2023-11-08 16:25:06.609 ServerApp] Connecting to kernel b667e96e-306a-4540-9aab-98c57fd5da5c.
[I 2023-11-08 16:25:06.707 ServerApp] Starting buffering for 0c9943f3-3d6f-4638-9a45-412a87b2f67e:e8fbe1e7-6421-492b-a151-5ae366e5391c
[I 2023-11-08 16:25:06.708 ServerApp] Starting buffering for eb780ec5-cfa5-4b7a-9f59-bd4370f51e8b:8ca62035-c4d9-43d1-b38d-344553c6ea2d
[I 2023-11-08 16:25:06.712 ServerApp] Starting buffering for b667e96e-306a-4540-9aab-98c57fd5da5c:91e6bd3c-9106-4c14-8753-c593a130708a
[I 2023-11-08 16:25:07.695 ServerApp] Connecting to kernel 0c9943f3-3d6f-4638-9a45-412a87b2f67e.
[I 2023-11-08 16:25:07.698 ServerApp] Connecting to kernel eb780ec5-cfa5-4b7a-9f59-bd4370f51e8b.
[I 2023-11-08 16:27:07.413 ServerApp] Saving file at /historical_analysis/21_zarr_aviso.ipynb
[I 2023-11-08 16:27:58.563 ServerApp] Starting buffering for 0c9943f3-3d6f-4638-9a45-412a87b2f67e:1f03170a-edd2-4b74-a755-757bd09a3b33
[I 2023-11-08 16:27:58.564 ServerApp] Starting buffering for eb780ec5-cfa5-4b7a-9f59-bd4370f51e8b:42c50d71-0cc5-4987-b7a4-215dfdcbb895
[W 2023-11-08 16:27:59.923 LabApp] Could not determine jupyterlab build status without nodejs
[I 2023-11-08 16:27:59.973 ServerApp] Connecting to kernel 0c9943f3-3d6f-4638-9a45-412a87b2f67e.
[I 2023-11-08 16:27:59.981 ServerApp] Connecting to kernel eb780ec5-cfa5-4b7a-9f59-bd4370f51e8b.
[I 2023-11-08 16:27:59.983 ServerApp] Connecting to kernel b667e96e-306a-4540-9aab-98c57fd5da5c.
[I 2023-11-08 16:28:00.142 ServerApp] Starting buffering for 0c9943f3-3d6f-4638-9a45-412a87b2f67e:c16f6c30-33ad-46c7-92af-f1b8c621a5e1
[I 2023-11-08 16:28:00.143 ServerApp] Starting buffering for eb780ec5-cfa5-4b7a-9f59-bd4370f51e8b:55621776-91c8-4ddb-88eb-72e91ca1def3
[I 2023-11-08 16:28:00.143 ServerApp] Starting buffering for b667e96e-306a-4540-9aab-98c57fd5da5c:75b36c6e-6fe9-4a7c-8612-c96487c525d3
[I 2023-11-08 16:28:01.870 ServerApp] Connecting to kernel 0c9943f3-3d6f-4638-9a45-412a87b2f67e.
[I 2023-11-08 16:28:01.872 ServerApp] Connecting to kernel eb780ec5-cfa5-4b7a-9f59-bd4370f51e8b.
[I 2023-11-08 16:28:05.911 ServerApp] Starting buffering for eb780ec5-cfa5-4b7a-9f59-bd4370f51e8b:38ff2d3b-9442-40fd-aaf1-271c6aa57ae7
[I 2023-11-08 16:28:05.912 ServerApp] Starting buffering for 0c9943f3-3d6f-4638-9a45-412a87b2f67e:3b2c05e2-bfc5-4f60-84a2-826cc77e087a
[W 2023-11-08 16:28:11.122 LabApp] Could not determine jupyterlab build status without nodejs
[I 2023-11-08 16:28:11.173 ServerApp] Connecting to kernel 0c9943f3-3d6f-4638-9a45-412a87b2f67e.
[I 2023-11-08 16:28:11.183 ServerApp] Connecting to kernel eb780ec5-cfa5-4b7a-9f59-bd4370f51e8b.
[I 2023-11-08 16:28:11.192 ServerApp] Connecting to kernel b667e96e-306a-4540-9aab-98c57fd5da5c.
[I 2023-11-08 16:28:11.274 ServerApp] Starting buffering for eb780ec5-cfa5-4b7a-9f59-bd4370f51e8b:fe425e91-e216-41b1-9b48-1be09f350627
[I 2023-11-08 16:28:11.277 ServerApp] Starting buffering for 0c9943f3-3d6f-4638-9a45-412a87b2f67e:19eadff4-4338-4bc1-9c7f-1a913cfd074b
[I 2023-11-08 16:28:11.279 ServerApp] Starting buffering for b667e96e-306a-4540-9aab-98c57fd5da5c:e7446f62-d6d0-43b4-9415-8394f88ed297
[I 2023-11-08 16:28:12.860 ServerApp] Connecting to kernel 0c9943f3-3d6f-4638-9a45-412a87b2f67e.
[I 2023-11-08 16:28:12.862 ServerApp] Connecting to kernel eb780ec5-cfa5-4b7a-9f59-bd4370f51e8b.
[I 2023-11-08 16:28:50.791 ServerApp] Kernel restarted: 0c9943f3-3d6f-4638-9a45-412a87b2f67e
[I 2023-11-08 16:28:50.795 ServerApp] Starting buffering for 0c9943f3-3d6f-4638-9a45-412a87b2f67e:a1ac3063-3cf6-44ce-a5b0-35ab622cf684
[I 2023-11-08 16:28:50.801 ServerApp] Connecting to kernel 0c9943f3-3d6f-4638-9a45-412a87b2f67e.
[I 2023-11-08 16:28:50.801 ServerApp] Restoring connection for 0c9943f3-3d6f-4638-9a45-412a87b2f67e:a1ac3063-3cf6-44ce-a5b0-35ab622cf684
readline: /etc/inputrc: line 19: term: unknown variable name
[I 2023-11-08 16:28:55.411 ServerApp] Kernel interrupted: 0c9943f3-3d6f-4638-9a45-412a87b2f67e
[I 2023-11-08 16:28:55.756 ServerApp] Kernel interrupted: 0c9943f3-3d6f-4638-9a45-412a87b2f67e
[I 2023-11-08 16:29:02.949 ServerApp] Kernel restarted: 0c9943f3-3d6f-4638-9a45-412a87b2f67e
[I 2023-11-08 16:29:02.953 ServerApp] Starting buffering for 0c9943f3-3d6f-4638-9a45-412a87b2f67e:a1ac3063-3cf6-44ce-a5b0-35ab622cf684
[I 2023-11-08 16:29:02.959 ServerApp] Connecting to kernel 0c9943f3-3d6f-4638-9a45-412a87b2f67e.
[I 2023-11-08 16:29:02.959 ServerApp] Restoring connection for 0c9943f3-3d6f-4638-9a45-412a87b2f67e:a1ac3063-3cf6-44ce-a5b0-35ab622cf684
readline: /etc/inputrc: line 19: term: unknown variable name
[I 2023-11-08 16:30:12.178 ServerApp] Saving file at /historical_analysis/21_zarr_aviso.ipynb
[I 2023-11-08 16:32:04.880 ServerApp] Starting buffering for eb780ec5-cfa5-4b7a-9f59-bd4370f51e8b:b7645ad1-481e-47d2-bd2f-7d6686f52357
[I 2023-11-08 16:32:04.882 ServerApp] Starting buffering for 0c9943f3-3d6f-4638-9a45-412a87b2f67e:a1ac3063-3cf6-44ce-a5b0-35ab622cf684
[W 2023-11-08 16:32:10.768 LabApp] Could not determine jupyterlab build status without nodejs
[I 2023-11-08 16:32:10.817 ServerApp] Connecting to kernel 0c9943f3-3d6f-4638-9a45-412a87b2f67e.
[I 2023-11-08 16:32:10.825 ServerApp] Connecting to kernel eb780ec5-cfa5-4b7a-9f59-bd4370f51e8b.
[I 2023-11-08 16:32:10.828 ServerApp] Connecting to kernel b667e96e-306a-4540-9aab-98c57fd5da5c.
[I 2023-11-08 16:32:10.943 ServerApp] Starting buffering for 0c9943f3-3d6f-4638-9a45-412a87b2f67e:5ba5b4cc-47a4-4925-804b-4c54596ddebe
[I 2023-11-08 16:32:10.944 ServerApp] Starting buffering for b667e96e-306a-4540-9aab-98c57fd5da5c:64dd7465-9052-48e5-865f-800b696ba37e
[I 2023-11-08 16:32:10.944 ServerApp] Starting buffering for eb780ec5-cfa5-4b7a-9f59-bd4370f51e8b:50376eae-70ab-4780-93e3-c78ed96f22c8
[I 2023-11-08 16:32:12.478 ServerApp] Connecting to kernel 0c9943f3-3d6f-4638-9a45-412a87b2f67e.
[I 2023-11-08 16:32:12.480 ServerApp] Connecting to kernel eb780ec5-cfa5-4b7a-9f59-bd4370f51e8b.
[W 2023-11-08 16:37:42.479 ServerApp] WebSocket ping timeout after 119998 ms.
[W 2023-11-08 16:37:42.481 ServerApp] WebSocket ping timeout after 119999 ms.
[I 2023-11-08 16:37:47.481 ServerApp] Starting buffering for 0c9943f3-3d6f-4638-9a45-412a87b2f67e:021805e2-b65c-4973-a9c9-a666b229a10e
[I 2023-11-08 16:37:47.482 ServerApp] Starting buffering for eb780ec5-cfa5-4b7a-9f59-bd4370f51e8b:dc685dfd-dd46-4c61-b51b-83f473e05b3b
[W 2023-11-08 21:14:25.971 LabApp] Could not determine jupyterlab build status without nodejs
[I 2023-11-08 21:14:26.098 ServerApp] Connecting to kernel 0c9943f3-3d6f-4638-9a45-412a87b2f67e.
[I 2023-11-08 21:14:26.105 ServerApp] Connecting to kernel eb780ec5-cfa5-4b7a-9f59-bd4370f51e8b.
[I 2023-11-08 21:14:26.106 ServerApp] Connecting to kernel b667e96e-306a-4540-9aab-98c57fd5da5c.
[I 2023-11-08 21:14:26.258 ServerApp] Starting buffering for eb780ec5-cfa5-4b7a-9f59-bd4370f51e8b:eaa94a7f-1e5f-49de-b9b6-e839445f6a75
[I 2023-11-08 21:14:26.258 ServerApp] Starting buffering for b667e96e-306a-4540-9aab-98c57fd5da5c:9cbee675-f542-4e94-961e-0e3b5c50219d
[I 2023-11-08 21:14:26.278 ServerApp] Starting buffering for 0c9943f3-3d6f-4638-9a45-412a87b2f67e:de97e5a0-3351-4cb7-b109-9b43271684b7
[I 2023-11-08 21:14:29.650 ServerApp] Connecting to kernel 0c9943f3-3d6f-4638-9a45-412a87b2f67e.
[I 2023-11-08 21:14:31.252 ServerApp] Connecting to kernel eb780ec5-cfa5-4b7a-9f59-bd4370f51e8b.
[I 2023-11-08 21:15:42.108 ServerApp] Saving file at /historical_analysis/job_distributed.py
[I 2023-11-08 21:17:02.283 ServerApp] Saving file at /historical_analysis/job_distributed.py
[I 2023-11-08 21:17:36.735 ServerApp] Kernel started: 194f340f-c9da-490f-8679-e01b8d6a2a6f
readline: /etc/inputrc: line 19: term: unknown variable name
[I 2023-11-08 21:17:38.420 ServerApp] Connecting to kernel 194f340f-c9da-490f-8679-e01b8d6a2a6f.
[I 2023-11-08 21:18:29.685 ServerApp] Saving file at /historical_analysis/job_distributed.py
[I 2023-11-08 21:18:53.137 ServerApp] Saving file at /historical_analysis/job_distributed.py
[I 2023-11-08 21:19:44.706 ServerApp] Starting buffering for 194f340f-c9da-490f-8679-e01b8d6a2a6f:6550c1f3-f6d3-421a-9433-3c7c19da8b50
[I 2023-11-08 21:21:03.819 ServerApp] Starting buffering for 0c9943f3-3d6f-4638-9a45-412a87b2f67e:bbc21969-e3cb-4d4e-b658-11155dd163a6
[I 2023-11-08 21:21:03.820 ServerApp] Starting buffering for eb780ec5-cfa5-4b7a-9f59-bd4370f51e8b:a0d54ac5-47ab-4112-a14a-4805d531f6b9
[I 2023-11-08 21:21:49.961 ServerApp] Connecting to kernel eb780ec5-cfa5-4b7a-9f59-bd4370f51e8b.
[I 2023-11-08 21:21:49.961 ServerApp] Restoring connection for eb780ec5-cfa5-4b7a-9f59-bd4370f51e8b:a0d54ac5-47ab-4112-a14a-4805d531f6b9
[I 2023-11-08 21:22:06.281 ServerApp] Connecting to kernel 0c9943f3-3d6f-4638-9a45-412a87b2f67e.
[I 2023-11-08 21:22:06.281 ServerApp] Restoring connection for 0c9943f3-3d6f-4638-9a45-412a87b2f67e:bbc21969-e3cb-4d4e-b658-11155dd163a6
[I 2023-11-08 21:24:56.006 ServerApp] Saving file at /historical_analysis/job_distributed.py
[I 2023-11-08 21:25:56.389 ServerApp] Saving file at /historical_analysis/job_distributed.py
Terminated
[C 2023-11-08 21:33:23.787 ServerApp] received signal 15, stopping
[I 2023-11-08 21:33:23.914 ServerApp] Shutting down 6 extensions
[I 2023-11-08 21:33:23.915 ServerApp] Shutting down 4 kernels
[I 2023-11-08 21:33:23.915 ServerApp] Kernel shutdown: 194f340f-c9da-490f-8679-e01b8d6a2a6f
[I 2023-11-08 21:33:23.915 ServerApp] Kernel shutdown: eb780ec5-cfa5-4b7a-9f59-bd4370f51e8b
[I 2023-11-08 21:33:23.916 ServerApp] Kernel shutdown: b667e96e-306a-4540-9aab-98c57fd5da5c
[I 2023-11-08 21:33:23.916 ServerApp] Kernel shutdown: 0c9943f3-3d6f-4638-9a45-412a87b2f67e
